Workbook

Sheet ①企画一覧・審査
A1: 企画パイプライン：一覧 → STEP4 チェック → STEP5 採点 → ランキング
A2: 使い方：①黄色セルだけ記入 → ②STEP4の6項目を ○（はい）/△（直せばいける）/×（いいえ）で審査 → ③ステータスが「◎ 候補リスト」になったものだけ STEP5 を採点 → ④「②候補ランキング」シートで優先軸を選ぶと順位が出る → ⑤「最終判断」で制作決定／保留／ボツを決める。 新しい企画は空いている行に追加するだけで自動判定されます。
A3: ステータスの流れ： ① STEP1待ち → ② フォーマット・アングル未記入 → ③ STEP4 審査待ち → （×が1つでも）✕ ボツ候補 ／ （△あり）△ 修正して再審査 ／ （全部○）◎ 候補リスト
A4: 基本 | E4: STEP1 | G4: STEP2-3 | J4: STEP4 | P4: 判定 | Q4: STEP5 | U4: 判断 | W4: 内部
A5: ID | B5: 区分 | C5: 企画名 | D5: トピック | E5: STEP1 検証結果 | F5: STEP1 根拠・メモ | G5: STEP2 フォーマット | H5: STEP3 アングル | I5: タイトル／サムネ案 | J5: ①実現 可能性 | K5: ②新規 視聴者 | L5: ③既存 視聴者 | M5: ④再生 ポテンシャル | N5: ⑤ブランド 親和性 | O5: ⑥パッケー ジ化 | P5: ステータス （自動） | Q5: ワクワク | R5: 労力 (1=楽) | S5: 確信度 | T5: 合計 （自動） | U5: 最終判断 | V5: 審査メモ | W5: 並べ替え キー
A6: =IF(C6="","",ROW()-5) | B6: 本命 | C6: 受講生のスピーキング模試を全部見せる＋フィードバック解説 | D6: IELTS Speaking | E6: 通過 | F6: STEP1通過（Speaking・模試＋フィードバック解説型が繰り返し当たっている）。根拠：ORIENT ACADEMY 58x／76,246再生／登録1,610人 | G6: チュートリアル×インタビュー（模試通し＋解説） | H6: 変身・変化 × 親近感 | I6: 「Band 6.0の受講生が3週間で7.0を取るまで（模試を全公開）」／スコア表のビフォーアフター | P6: =IF(C6="","",IF(OR(E6="",E6="未検証"),"① STEP1待ち",IF(E6="不通過","✕ STEP1不通過",IF(OR(G6="",H6=""),"② STEP2-3 未記入",IF(COUNTIF(J6:O6,"×")>0,"✕ ボツ候補",IF(COUNTA(J6:O6)<6,"③ STEP4 審査待ち",IF(COUNTIF(J6:O6,"△")>0,"△ 修正して再審査","◎ 候補リスト"))))))) | Q6: 8 | R6: 8 | S6: 9 | T6: =IF(COUNT(Q6:S6)<3,"",Q6+(11-R6)+S6) | W6: =IF(AND(P6="◎ 候補リスト",U6<>"ボツ",U6<>"制作済み",T6<>"",OR('②候補ランキング'!$C$5="すべて",B6='②候補ランキング'!$C$5)),IF('②候補ランキング'!$C$4="ワクワク",Q6,IF('②候補ランキング'!$C$4="手軽さ",11-R6,IF('②候補ランキング'!$C$4="確信度",S6,T6)))*1000+T6+(1000-A6)/10000,"")
A7: =IF(C7="","",ROW()-5) | B7: 本命 | C7: Part1〜3 通し模試（ゲスト受験者） | D7: IELTS Speaking | E7: 通過 | F7: STEP1通過。根拠：BBC GLOBAL EDUCATION 6.9x／11,926再生／登録40,400人（21日前） | G7: チャレンジ×インタビュー | H7: 網羅的（コンプリート）× 比較 | I7: 「Part1〜3を最初から最後まで通しで受けてみた」／Band別に並べた比較サムネ | P7: =IF(C7="","",IF(OR(E7="",E7="未検証"),"① STEP1待ち",IF(E7="不通過","✕ STEP1不通過",IF(OR(G7="",H7=""),"② STEP2-3 未記入",IF(COUNTIF(J7:O7,"×")>0,"✕ ボツ候補",IF(COUNTA(J7:O7)<6,"③ STEP4 審査待ち",IF(COUNTIF(J7:O7,"△")>0,"△ 修正して再審査","◎ 候補リスト"))))))) | Q7: 7 | R7: 8 | S7: 9 | T7: =IF(COUNT(Q7:S7)<3,"",Q7+(11-R7)+S7) | W7: =IF(AND(P7="◎ 候補リスト",U7<>"ボツ",U7<>"制作済み",T7<>"",OR('②候補ランキング'!$C$5="すべて",B7='②候補ランキング'!$C$5)),IF('②候補ランキング'!$C$4="ワクワク",Q7,IF('②候補ランキング'!$C$4="手軽さ",11-R7,IF('②候補ランキング'!$C$4="確信度",S7,T7)))*1000+T7+(1000-A7)/10000,"")
A8: =IF(C8="","",ROW()-5) | B8: 本命 | C8: スコアが伸びない回答を1つずつ採点・改善 | D8: IELTS Speaking | E8: 通過 | F8: STEP1通過（フィードバック解説が当たり型の核）。添削700件の実績が参入障壁として機能 | G8: チュートリアル×コメンタリー | H8: 比較（悪い回答 vs 改善回答） | I8: 「この回答、なぜ6.0なのか？」／実際の解答を赤入れして見せる | P8: =IF(C8="","",IF(OR(E8="",E8="未検証"),"① STEP1待ち",IF(E8="不通過","✕ STEP1不通過",IF(OR(G8="",H8=""),"② STEP2-3 未記入",IF(COUNTIF(J8:O8,"×")>0,"✕ ボツ候補",IF(COUNTA(J8:O8)<6,"③ STEP4 審査待ち",IF(COUNTIF(J8:O8,"△")>0,"△ 修正して再審査","◎ 候補リスト"))))))) | Q8: 7 | R8: 5 | S8: 9 | T8: =IF(COUNT(Q8:S8)<3,"",Q8+(11-R8)+S8) | W8: =IF(AND(P8="◎ 候補リスト",U8<>"ボツ",U8<>"制作済み",T8<>"",OR('②候補ランキング'!$C$5="すべて",B8='②候補ランキング'!$C$5)),IF('②候補ランキング'!$C$4="ワクワク",Q8,IF('②候補ランキング'!$C$4="手軽さ",11-R8,IF('②候補ランキング'!$C$4="確信度",S8,T8)))*1000+T8+(1000-A8)/10000,"")
A9: =IF(C9="","",ROW()-5) | B9: 本命 | C9: 言い換え（Paraphrasing）マスター | D9: IELTS Writing | E9: 通過 | F9: STEP1通過。根拠：Paraphrasing Masterclass >100x／117,729再生／登録8,670人（Speaking・Writing共通の最大アウトライアー） | G9: チュートリアル（×リスト） | H9: 明確なリスト（数字）× 網羅的 | I9: 「IELTS言い換え術：Band 7+のための5つの戦略」／Before-Afterの文比較 | P9: =IF(C9="","",IF(OR(E9="",E9="未検証"),"① STEP1待ち",IF(E9="不通過","✕ STEP1不通過",IF(OR(G9="",H9=""),"② STEP2-3 未記入",IF(COUNTIF(J9:O9,"×")>0,"✕ ボツ候補",IF(COUNTA(J9:O9)<6,"③ STEP4 審査待ち",IF(COUNTIF(J9:O9,"△")>0,"△ 修正して再審査","◎ 候補リスト"))))))) | Q9: 8 | R9: 4 | S9: 9 | T9: =IF(COUNT(Q9:S9)<3,"",Q9+(11-R9)+S9) | W9: =IF(AND(P9="◎ 候補リスト",U9<>"ボツ",U9<>"制作済み",T9<>"",OR('②候補ランキング'!$C$5="すべて",B9='②候補ランキング'!$C$5)),IF('②候補ランキング'!$C$4="ワクワク",Q9,IF('②候補ランキング'!$C$4="手軽さ",11-R9,IF('②候補ランキング'!$C$4="確信度",S9,T9)))*1000+T9+(1000-A9)/10000,"")
A10: =IF(C10="","",ROW()-5) | B10: 本命 | C10: ライティングの「設計図」（Cohesion & Coherence） | D10: IELTS Writing | E10: 通過 | F10: STEP1通過。根拠：Writing Flow 9.6x／30,860再生、What Makes Writing Good 8.8x／28,279再生（いずれも設計図型レッスン） | G10: チュートリアル | H10: 明確なリスト（数字）× 変身・変化 | I10: 「文章のつながりを設計する」／構成図で示すBefore-After | P10: =IF(C10="","",IF(OR(E10="",E10="未検証"),"① STEP1待ち",IF(E10="不通過","✕ STEP1不通過",IF(OR(G10="",H10=""),"② STEP2-3 未記入",IF(COUNTIF(J10:O10,"×")>0,"✕ ボツ候補",IF(COUNTA(J10:O10)<6,"③ STEP4 審査待ち",IF(COUNTIF(J10:O10,"△")>0,"△ 修正して再審査","◎ 候補リスト"))))))) | Q10: 7 | R10: 5 | S10: 9 | T10: =IF(COUNT(Q10:S10)<3,"",Q10+(11-R10)+S10) | W10: =IF(AND(P10="◎ 候補リスト",U10<>"ボツ",U10<>"制作済み",T10<>"",OR('②候補ランキング'!$C$5="すべて",B10='②候補ランキング'!$C$5)),IF('②候補ランキング'!$C$4="ワクワク",Q10,IF('②候補ランキング'!$C$4="手軽さ",11-R10,IF('②候補ランキング'!$C$4="確信度",S10,T10)))*1000+T10+(1000-A10)/10000,"")
A11: =IF(C11="","",ROW()-5) | B11: 本命 | C11: Task1 地図問題はこの1つの公式だけ | D11: IELTS Writing Task1 | E11: 通過 | F11: STEP1通過。根拠：IELTS Writing Task 1 Academic: One Simple Formula for Maps 2.3x／11,155再生 | G11: チュートリアル | H11: 明確なリスト（数字）× トピック＋ひねり | I11: 「地図問題はこの1つの公式で書ける」／図解サムネ | P11: =IF(C11="","",IF(OR(E11="",E11="未検証"),"① STEP1待ち",IF(E11="不通過","✕ STEP1不通過",IF(OR(G11="",H11=""),"② STEP2-3 未記入",IF(COUNTIF(J11:O11,"×")>0,"✕ ボツ候補",IF(COUNTA(J11:O11)<6,"③ STEP4 審査待ち",IF(COUNTIF(J11:O11,"△")>0,"△ 修正して再審査","◎ 候補リスト"))))))) | Q11: 6 | R11: 4 | S11: 8 | T11: =IF(COUNT(Q11:S11)<3,"",Q11+(11-R11)+S11) | W11: =IF(AND(P11="◎ 候補リスト",U11<>"ボツ",U11<>"制作済み",T11<>"",OR('②候補ランキング'!$C$5="すべて",B11='②候補ランキング'!$C$5)),IF('②候補ランキング'!$C$4="ワクワク",Q11,IF('②候補ランキング'!$C$4="手軽さ",11-R11,IF('②候補ランキング'!$C$4="確信度",S11,T11)))*1000+T11+(1000-A11)/10000,"")
A12: =IF(C12="","",ROW()-5) | B12: 本命 | C12: 30日でBand 4→8.5の変化ストーリー | D12: IELTS全体 | E12: 通過 | F12: STEP1通過。根拠：Simran IELTS 112.65倍／登録3,860人＝『知名度なしでも伸びる』の直接証拠 | G12: チャレンジ×Vlog | H12: 長期コミット（時間）× 変身・変化 | I12: 「30日でBand 4→8.5を取った全記録」／Day別のスコア推移 | P12: =IF(C12="","",IF(OR(E12="",E12="未検証"),"① STEP1待ち",IF(E12="不通過","✕ STEP1不通過",IF(OR(G12="",H12=""),"② STEP2-3 未記入",IF(COUNTIF(J12:O12,"×")>0,"✕ ボツ候補",IF(COUNTA(J12:O12)<6,"③ STEP4 審査待ち",IF(COUNTIF(J12:O12,"△")>0,"△ 修正して再審査","◎ 候補リスト"))))))) | Q12: 9 | R12: 9 | S12: 8 | T12: =IF(COUNT(Q12:S12)<3,"",Q12+(11-R12)+S12) | W12: =IF(AND(P12="◎ 候補リスト",U12<>"ボツ",U12<>"制作済み",T12<>"",OR('②候補ランキング'!$C$5="すべて",B12='②候補ランキング'!$C$5)),IF('②候補ランキング'!$C$4="ワクワク",Q12,IF('②候補ランキング'!$C$4="手軽さ",11-R12,IF('②候補ランキング'!$C$4="確信度",S12,T12)))*1000+T12+(1000-A12)/10000,"")
A13: =IF(C13="","",ROW()-5) | B13: 実験 | C13: 日本語「IELTS勉強法」の実験1本 | D13: IELTS 勉強法（日本語） | E13: 実験枠 | F13: STEP1は実績ゼロ（アウトライヤー索引に関連結果なし）。英語クエリで再検索が必要。フレームワーク通り実験枠として1本だけキープ | G13: チュートリアル×Vlog | H13: 親近感 | I13: 「英語環境ゼロの私が実際にやったIELTS勉強法」／手元の教材を並べる | P13: =IF(C13="","",IF(OR(E13="",E13="未検証"),"① STEP1待ち",IF(E13="不通過","✕ STEP1不通過",IF(OR(G13="",H13=""),"② STEP2-3 未記入",IF(COUNTIF(J13:O13,"×")>0,"✕ ボツ候補",IF(COUNTA(J13:O13)<6,"③ STEP4 審査待ち",IF(COUNTIF(J13:O13,"△")>0,"△ 修正して再審査","◎ 候補リスト"))))))) | Q13: 6 | R13: 3 | S13: 4 | T13: =IF(COUNT(Q13:S13)<3,"",Q13+(11-R13)+S13) | W13: =IF(AND(P13="◎ 候補リスト",U13<>"ボツ",U13<>"制作済み",T13<>"",OR('②候補ランキング'!$C$5="すべて",B13='②候補ランキング'!$C$5)),IF('②候補ランキング'!$C$4="ワクワク",Q13,IF('②候補ランキング'!$C$4="手軽さ",11-R13,IF('②候補ランキング'!$C$4="確信度",S13,T13)))*1000+T13+(1000-A13)/10000,"")
A14: =IF(C14="","",ROW()-5) | B14: 実験 | C14: 30代・アラサーの年齢不安 | D14: 社会人の大学院留学 | E14: 実験枠 | F14: 自チャンネル最大アウトライアー1,942回（中央値の約6倍）だが、今回のSTEP1では外部検証が未実施。次回は英語クエリでの検証が必要 | G14: 解説×Vlog | H14: 親近感 × 比較 | I14: 「30代で大学院留学して後悔しなかった理由」／20代との比較 | P14: =IF(C14="","",IF(OR(E14="",E14="未検証"),"① STEP1待ち",IF(E14="不通過","✕ STEP1不通過",IF(OR(G14="",H14=""),"② STEP2-3 未記入",IF(COUNTIF(J14:O14,"×")>0,"✕ ボツ候補",IF(COUNTA(J14:O14)<6,"③ STEP4 審査待ち",IF(COUNTIF(J14:O14,"△")>0,"△ 修正して再審査","◎ 候補リスト"))))))) | Q14: 8 | R14: 3 | S14: 7 | T14: =IF(COUNT(Q14:S14)<3,"",Q14+(11-R14)+S14) | W14: =IF(AND(P14="◎ 候補リスト",U14<>"ボツ",U14<>"制作済み",T14<>"",OR('②候補ランキング'!$C$5="すべて",B14='②候補ランキング'!$C$5)),IF('②候補ランキング'!$C$4="ワクワク",Q14,IF('②候補ランキング'!$C$4="手軽さ",11-R14,IF('②候補ランキング'!$C$4="確信度",S14,T14)))*1000+T14+(1000-A14)/10000,"")
A15: =IF(C15="","",ROW()-5) | B15: 転換 | C15: 条件付きオファーの逆算スケジュール | D15: 条件付き合格 | E15: 転換枠 | F15: STEP1でキラー失格（大学院準備は目標超えが少なく、未知チャンネルが跳ねた例がない）。キラー枠ではなく相談・コーチングへのコンバージョン枠として維持 | G15: チュートリアル×解説 | H15: ステークス：時間制限 | I15: 「条件付きオファーの期限に間に合わなかったら？」／逆算カレンダー | P15: =IF(C15="","",IF(OR(E15="",E15="未検証"),"① STEP1待ち",IF(E15="不通過","✕ STEP1不通過",IF(OR(G15="",H15=""),"② STEP2-3 未記入",IF(COUNTIF(J15:O15,"×")>0,"✕ ボツ候補",IF(COUNTA(J15:O15)<6,"③ STEP4 審査待ち",IF(COUNTIF(J15:O15,"△")>0,"△ 修正して再審査","◎ 候補リスト"))))))) | Q15: 6 | R15: 4 | S15: 5 | T15: =IF(COUNT(Q15:S15)<3,"",Q15+(11-R15)+S15) | W15: =IF(AND(P15="◎ 候補リスト",U15<>"ボツ",U15<>"制作済み",T15<>"",OR('②候補ランキング'!$C$5="すべて",B15='②候補ランキング'!$C$5)),IF('②候補ランキング'!$C$4="ワクワク",Q15,IF('②候補ランキング'!$C$4="手軽さ",11-R15,IF('②候補ランキング'!$C$4="確信度",S15,T15)))*1000+T15+(1000-A15)/10000,"")
A16: =IF(C16="","",ROW()-5) | B16: 転換 | C16: 留学費用を全部公開 | D16: 留学費用・資金計画 | E16: 転換枠 | F16: 転換枠。STEP1のD判定に従いキラーにはしない（転換・信頼構築用） | G16: 解説×Vlog | H16: ステークス：お金 × 網羅的 | I16: 「ロンドンで大学院に通った実際の総額を全部出す」／内訳の一覧 | P16: =IF(C16="","",IF(OR(E16="",E16="未検証"),"① STEP1待ち",IF(E16="不通過","✕ STEP1不通過",IF(OR(G16="",H16=""),"② STEP2-3 未記入",IF(COUNTIF(J16:O16,"×")>0,"✕ ボツ候補",IF(COUNTA(J16:O16)<6,"③ STEP4 審査待ち",IF(COUNTIF(J16:O16,"△")>0,"△ 修正して再審査","◎ 候補リスト"))))))) | Q16: 7 | R16: 4 | S16: 5 | T16: =IF(COUNT(Q16:S16)<3,"",Q16+(11-R16)+S16) | W16: =IF(AND(P16="◎ 候補リスト",U16<>"ボツ",U16<>"制作済み",T16<>"",OR('②候補ランキング'!$C$5="すべて",B16='②候補ランキング'!$C$5)),IF('②候補ランキング'!$C$4="ワクワク",Q16,IF('②候補ランキング'!$C$4="手軽さ",11-R16,IF('②候補ランキング'!$C$4="確信度",S16,T16)))*1000+T16+(1000-A16)/10000,"")
A17: =IF(C17="","",ROW()-5) | B17: 転換 | C17: 出願書類を全部見せる | D17: 大学院出願 | E17: 転換枠 | F17: 転換枠。同上。志望動機書系は反応があるため転換導線として残す | G17: チュートリアル×解説 | H17: 網羅的（コンプリート） | I17: 「イギリス大学院の出願書類、ゼロから完成まで全部見せる」 | P17: =IF(C17="","",IF(OR(E17="",E17="未検証"),"① STEP1待ち",IF(E17="不通過","✕ STEP1不通過",IF(OR(G17="",H17=""),"② STEP2-3 未記入",IF(COUNTIF(J17:O17,"×")>0,"✕ ボツ候補",IF(COUNTA(J17:O17)<6,"③ STEP4 審査待ち",IF(COUNTIF(J17:O17,"△")>0,"△ 修正して再審査","◎ 候補リスト"))))))) | Q17: 6 | R17: 6 | S17: 5 | T17: =IF(COUNT(Q17:S17)<3,"",Q17+(11-R17)+S17) | W17: =IF(AND(P17="◎ 候補リスト",U17<>"ボツ",U17<>"制作済み",T17<>"",OR('②候補ランキング'!$C$5="すべて",B17='②候補ランキング'!$C$5)),IF('②候補ランキング'!$C$4="ワクワク",Q17,IF('②候補ランキング'!$C$4="手軽さ",11-R17,IF('②候補ランキング'!$C$4="確信度",S17,T17)))*1000+T17+(1000-A17)/10000,"")
... A37: =IF(C37="","",ROW()-5) | B37: 転換 | C37: 受講生の合格体験談 | D37: 大学院進学 | E37: 転換枠 | F37: 転換枠。STEP1のD判定に従いキラーにはしないが、コーチング導線として最も強い | G37: インタビュー | H37: 親近感 × 変身・変化 | I37: 「英語環境ゼロから大学院に合格した受講生の話」 | P37: =IF(C37="","",IF(OR(E37="",E37="未検証"),"① STEP1待ち",IF(E37="不通過","✕ STEP1不通過",IF(OR(G37="",H37=""),"② STEP2-3 未記入",IF(COUNTIF(J37:O37,"×")>0,"✕ ボツ候補",IF(COUNTA(J37:O37)<6,"③ STEP4 審査待ち",IF(COUNTIF(J37:O37,"△")>0,"△ 修正して再審査","◎ 候補リスト"))))))) | Q37: 6 | R37: 4 | S37: 5 | T37: =IF(COUNT(Q37:S37)<3,"",Q37+(11-R37)+S37) | W37: =IF(AND(P37="◎ 候補リスト",U37<>"ボツ",U37<>"制作済み",T37<>"",OR('②候補ランキング'!$C$5="すべて",B37='②候補ランキング'!$C$5)),IF('②候補ランキング'!$C$4="ワクワク",Q37,IF('②候補ランキング'!$C$4="手軽さ",11-R37,IF('②候補ランキング'!$C$4="確信度",S37,T37)))*1000+T37+(1000-A37)/10000,"")
A38: =IF(C38="","",ROW()-5) | P38: =IF(C38="","",IF(OR(E38="",E38="未検証"),"① STEP1待ち",IF(E38="不通過","✕ STEP1不通過",IF(OR(G38="",H38=""),"② STEP2-3 未記入",IF(COUNTIF(J38:O38,"×")>0,"✕ ボツ候補",IF(COUNTA(J38:O38)<6,"③ STEP4 審査待ち",IF(COUNTIF(J38:O38,"△")>0,"△ 修正して再審査","◎ 候補リスト"))))))) | T38: =IF(COUNT(Q38:S38)<3,"",Q38+(11-R38)+S38) | W38: =IF(AND(P38="◎ 候補リスト",U38<>"ボツ",U38<>"制作済み",T38<>"",OR('②候補ランキング'!$C$5="すべて",B38='②候補ランキング'!$C$5)),IF('②候補ランキング'!$C$4="ワクワク",Q38,IF('②候補ランキング'!$C$4="手軽さ",11-R38,IF('②候補ランキング'!$C$4="確信度",S38,T38)))*1000+T38+(1000-A38)/10000,"")
A39: =IF(C39="","",ROW()-5) | P39: =IF(C39="","",IF(OR(E39="",E39="未検証"),"① STEP1待ち",IF(E39="不通過","✕ STEP1不通過",IF(OR(G39="",H39=""),"② STEP2-3 未記入",IF(COUNTIF(J39:O39,"×")>0,"✕ ボツ候補",IF(COUNTA(J39:O39)<6,"③ STEP4 審査待ち",IF(COUNTIF(J39:O39,"△")>0,"△ 修正して再審査","◎ 候補リスト"))))))) | T39: =IF(COUNT(Q39:S39)<3,"",Q39+(11-R39)+S39) | W39: =IF(AND(P39="◎ 候補リスト",U39<>"ボツ",U39<>"制作済み",T39<>"",OR('②候補ランキング'!$C$5="すべて",B39='②候補ランキング'!$C$5)),IF('②候補ランキング'!$C$4="ワクワク",Q39,IF('②候補ランキング'!$C$4="手軽さ",11-R39,IF('②候補ランキング'!$C$4="確信度",S39,T39)))*1000+T39+(1000-A39)/10000,"")
A40: =IF(C40="","",ROW()-5) | P40: =IF(C40="","",IF(OR(E40="",E40="未検証"),"① STEP1待ち",IF(E40="不通過","✕ STEP1不通過",IF(OR(G40="",H40=""),"② STEP2-3 未記入",IF(COUNTIF(J40:O40,"×")>0,"✕ ボツ候補",IF(COUNTA(J40:O40)<6,"③ STEP4 審査待ち",IF(COUNTIF(J40:O40,"△")>0,"△ 修正して再審査","◎ 候補リスト"))))))) | T40: =IF(COUNT(Q40:S40)<3,"",Q40+(11-R40)+S40) | W40: =IF(AND(P40="◎ 候補リスト",U40<>"ボツ",U40<>"制作済み",T40<>"",OR('②候補ランキング'!$C$5="すべて",B40='②候補ランキング'!$C$5)),IF('②候補ランキング'!$C$4="ワクワク",Q40,IF('②候補ランキング'!$C$4="手軽さ",11-R40,IF('②候補ランキング'!$C$4="確信度",S40,T40)))*1000+T40+(1000-A40)/10000,"")
A41: =IF(C41="","",ROW()-5) | P41: =IF(C41="","",IF(OR(E41="",E41="未検証"),"① STEP1待ち",IF(E41="不通過","✕ STEP1不通過",IF(OR(G41="",H41=""),"② STEP2-3 未記入",IF(COUNTIF(J41:O41,"×")>0,"✕ ボツ候補",IF(COUNTA(J41:O41)<6,"③ STEP4 審査待ち",IF(COUNTIF(J41:O41,"△")>0,"△ 修正して再審査","◎ 候補リスト"))))))) | T41: =IF(COUNT(Q41:S41)<3,"",Q41+(11-R41)+S41) | W41: =IF(AND(P41="◎ 候補リスト",U41<>"ボツ",U41<>"制作済み",T41<>"",OR('②候補ランキング'!$C$5="すべて",B41='②候補ランキング'!$C$5)),IF('②候補ランキング'!$C$4="ワクワク",Q41,IF('②候補ランキング'!$C$4="手軽さ",11-R41,IF('②候補ランキング'!$C$4="確信度",S41,T41)))*1000+T41+(1000-A41)/10000,"")
A42: =IF(C42="","",ROW()-5) | P42: =IF(C42="","",IF(OR(E42="",E42="未検証"),"① STEP1待ち",IF(E42="不通過","✕ STEP1不通過",IF(OR(G42="",H42=""),"② STEP2-3 未記入",IF(COUNTIF(J42:O42,"×")>0,"✕ ボツ候補",IF(COUNTA(J42:O42)<6,"③ STEP4 審査待ち",IF(COUNTIF(J42:O42,"△")>0,"△ 修正して再審査","◎ 候補リスト"))))))) | T42: =IF(COUNT(Q42:S42)<3,"",Q42+(11-R42)+S42) | W42: =IF(AND(P42="◎ 候補リスト",U42<>"ボツ",U42<>"制作済み",T42<>"",OR('②候補ランキング'!$C$5="すべて",B42='②候補ランキング'!$C$5)),IF('②候補ランキング'!$C$4="ワクワク",Q42,IF('②候補ランキング'!$C$4="手軽さ",11-R42,IF('②候補ランキング'!$C$4="確信度",S42,T42)))*1000+T42+(1000-A42)/10000,"")
A43: =IF(C43="","",ROW()-5) | P43: =IF(C43="","",IF(OR(E43="",E43="未検証"),"① STEP1待ち",IF(E43="不通過","✕ STEP1不通過",IF(OR(G43="",H43=""),"② STEP2-3 未記入",IF(COUNTIF(J43:O43,"×")>0,"✕ ボツ候補",IF(COUNTA(J43:O43)<6,"③ STEP4 審査待ち",IF(COUNTIF(J43:O43,"△")>0,"△ 修正して再審査","◎ 候補リスト"))))))) | T43: =IF(COUNT(Q43:S43)<3,"",Q43+(11-R43)+S43) | W43: =IF(AND(P43="◎ 候補リスト",U43<>"ボツ",U43<>"制作済み",T43<>"",OR('②候補ランキング'!$C$5="すべて",B43='②候補ランキング'!$C$5)),IF('②候補ランキング'!$C$4="ワクワク",Q43,IF('②候補ランキング'!$C$4="手軽さ",11-R43,IF('②候補ランキング'!$C$4="確信度",S43,T43)))*1000+T43+(1000-A43)/10000,"")
A44: =IF(C44="","",ROW()-5) | P44: =IF(C44="","",IF(OR(E44="",E44="未検証"),"① STEP1待ち",IF(E44="不通過","✕ STEP1不通過",IF(OR(G44="",H44=""),"② STEP2-3 未記入",IF(COUNTIF(J44:O44,"×")>0,"✕ ボツ候補",IF(COUNTA(J44:O44)<6,"③ STEP4 審査待ち",IF(COUNTIF(J44:O44,"△")>0,"△ 修正して再審査","◎ 候補リスト"))))))) | T44: =IF(COUNT(Q44:S44)<3,"",Q44+(11-R44)+S44) | W44: =IF(AND(P44="◎ 候補リスト",U44<>"ボツ",U44<>"制作済み",T44<>"",OR('②候補ランキング'!$C$5="すべて",B44='②候補ランキング'!$C$5)),IF('②候補ランキング'!$C$4="ワクワク",Q44,IF('②候補ランキング'!$C$4="手軽さ",11-R44,IF('②候補ランキング'!$C$4="確信度",S44,T44)))*1000+T44+(1000-A44)/10000,"")
A45: =IF(C45="","",ROW()-5) | P45: =IF(C45="","",IF(OR(E45="",E45="未検証"),"① STEP1待ち",IF(E45="不通過","✕ STEP1不通過",IF(OR(G45="",H45=""),"② STEP2-3 未記入",IF(COUNTIF(J45:O45,"×")>0,"✕ ボツ候補",IF(COUNTA(J45:O45)<6,"③ STEP4 審査待ち",IF(COUNTIF(J45:O45,"△")>0,"△ 修正して再審査","◎ 候補リスト"))))))) | T45: =IF(COUNT(Q45:S45)<3,"",Q45+(11-R45)+S45) | W45: =IF(AND(P45="◎ 候補リスト",U45<>"ボツ",U45<>"制作済み",T45<>"",OR('②候補ランキング'!$C$5="すべて",B45='②候補ランキング'!$C$5)),IF('②候補ランキング'!$C$4="ワクワク",Q45,IF('②候補ランキング'!$C$4="手軽さ",11-R45,IF('②候補ランキング'!$C$4="確信度",S45,T45)))*1000+T45+(1000-A45)/10000,"")
A46: =IF(C46="","",ROW()-5) | P46: =IF(C46="","",IF(OR(E46="",E46="未検証"),"① STEP1待ち",IF(E46="不通過","✕ STEP1不通過",IF(OR(G46="",H46=""),"② STEP2-3 未記入",IF(COUNTIF(J46:O46,"×")>0,"✕ ボツ候補",IF(COUNTA(J46:O46)<6,"③ STEP4 審査待ち",IF(COUNTIF(J46:O46,"△")>0,"△ 修正して再審査","◎ 候補リスト"))))))) | T46: =IF(COUNT(Q46:S46)<3,"",Q46+(11-R46)+S46) | W46: =IF(AND(P46="◎ 候補リスト",U46<>"ボツ",U46<>"制作済み",T46<>"",OR('②候補ランキング'!$C$5="すべて",B46='②候補ランキング'!$C$5)),IF('②候補ランキング'!$C$4="ワクワク",Q46,IF('②候補ランキング'!$C$4="手軽さ",11-R46,IF('②候補ランキング'!$C$4="確信度",S46,T46)))*1000+T46+(1000-A46)/10000,"")
A47: =IF(C47="","",ROW()-5) | P47: =IF(C47="","",IF(OR(E47="",E47="未検証"),"① STEP1待ち",IF(E47="不通過","✕ STEP1不通過",IF(OR(G47="",H47=""),"② STEP2-3 未記入",IF(COUNTIF(J47:O47,"×")>0,"✕ ボツ候補",IF(COUNTA(J47:O47)<6,"③ STEP4 審査待ち",IF(COUNTIF(J47:O47,"△")>0,"△ 修正して再審査","◎ 候補リスト"))))))) | T47: =IF(COUNT(Q47:S47)<3,"",Q47+(11-R47)+S47) | W47: =IF(AND(P47="◎ 候補リスト",U47<>"ボツ",U47<>"制作済み",T47<>"",OR('②候補ランキング'!$C$5="すべて",B47='②候補ランキング'!$C$5)),IF('②候補ランキング'!$C$4="ワクワク",Q47,IF('②候補ランキング'!$C$4="手軽さ",11-R47,IF('②候補ランキング'!$C$4="確信度",S47,T47)))*1000+T47+(1000-A47)/10000,"")
A48: =IF(C48="","",ROW()-5) | P48: =IF(C48="","",IF(OR(E48="",E48="未検証"),"① STEP1待ち",IF(E48="不通過","✕ STEP1不通過",IF(OR(G48="",H48=""),"② STEP2-3 未記入",IF(COUNTIF(J48:O48,"×")>0,"✕ ボツ候補",IF(COUNTA(J48:O48)<6,"③ STEP4 審査待ち",IF(COUNTIF(J48:O48,"△")>0,"△ 修正して再審査","◎ 候補リスト"))))))) | T48: =IF(COUNT(Q48:S48)<3,"",Q48+(11-R48)+S48) | W48: =IF(AND(P48="◎ 候補リスト",U48<>"ボツ",U48<>"制作済み",T48<>"",OR('②候補ランキング'!$C$5="すべて",B48='②候補ランキング'!$C$5)),IF('②候補ランキング'!$C$4="ワクワク",Q48,IF('②候補ランキング'!$C$4="手軽さ",11-R48,IF('②候補ランキング'!$C$4="確信度",S48,T48)))*1000+T48+(1000-A48)/10000,"")
A49: =IF(C49="","",ROW()-5) | P49: =IF(C49="","",IF(OR(E49="",E49="未検証"),"① STEP1待ち",IF(E49="不通過","✕ STEP1不通過",IF(OR(G49="",H49=""),"② STEP2-3 未記入",IF(COUNTIF(J49:O49,"×")>0,"✕ ボツ候補",IF(COUNTA(J49:O49)<6,"③ STEP4 審査待ち",IF(COUNTIF(J49:O49,"△")>0,"△ 修正して再審査","◎ 候補リスト"))))))) | T49: =IF(COUNT(Q49:S49)<3,"",Q49+(11-R49)+S49) | W49: =IF(AND(P49="◎ 候補リスト",U49<>"ボツ",U49<>"制作済み",T49<>"",OR('②候補ランキング'!$C$5="すべて",B49='②候補ランキング'!$C$5)),IF('②候補ランキング'!$C$4="ワクワク",Q49,IF('②候補ランキング'!$C$4="手軽さ",11-R49,IF('②候補ランキング'!$C$4="確信度",S49,T49)))*1000+T49+(1000-A49)/10000,"")
... A205: =IF(C205="","",ROW()-5) | P205: =IF(C205="","",IF(OR(E205="",E205="未検証"),"① STEP1待ち",IF(E205="不通過","✕ STEP1不通過",IF(OR(G205="",H205=""),"② STEP2-3 未記入",IF(COUNTIF(J205:O205,"×")>0,"✕ ボツ候補",IF(COUNTA(J205:O205)<6,"③ STEP4 審査待ち",IF(COUNTIF(J205:O205,"△")>0,"△ 修正して再審査","◎ 候補リスト"))))))) | T205: =IF(COUNT(Q205:S205)<3,"",Q205+(11-R205)+S205) | W205: =IF(AND(P205="◎ 候補リスト",U205<>"ボツ",U205<>"制作済み",T205<>"",OR('②候補ランキング'!$C$5="すべて",B205='②候補ランキング'!$C$5)),IF('②候補ランキング'!$C$4="ワクワク",Q205,IF('②候補ランキング'!$C$4="手軽さ",11-R205,IF('②候補ランキング'!$C$4="確信度",S205,T205)))*1000+T205+(1000-A205)/10000,"")

Sheet ②候補ランキング
A1: 候補ランキング（STEP5：今の自分に大切な軸で選ぶ）
A2: 「◎ 候補リスト」かつ最終判断がボツ／制作済みでない企画だけが並びます。黄色の3セルを切り替えてください。同点は合計点→ID順。
A4: 優先する軸 | C4: 総合 | D4: 総合＝バランス／ワクワク＝インスピレーションが欲しい時／手軽さ＝息抜きしたい時（労力が低い順）／確信度＝どうしてもヒットが必要な時
A5: 区分で絞る | C5: すべて | D5: 本命＝キラー狙い／実験＝実験枠／転換＝相談・コーチング導線
A6: 今回つくる本数 | C6: 3 | D6: 上位この本数を紫で強調
A8: ■ 審査の進み具合 | F8: ■ 最終判断
A9: ① STEP1待ち | D9: =COUNTIF('①企画一覧・審査'!$P$6:$P$205,"① STEP1待ち")&" 件" | F9: 制作決定 | I9: =COUNTIF('①企画一覧・審査'!$U$6:$U$205,"制作決定")&" 件"
A10: ② STEP2-3 未記入 | D10: =COUNTIF('①企画一覧・審査'!$P$6:$P$205,"② STEP2-3 未記入")&" 件" | F10: 保留 | I10: =COUNTIF('①企画一覧・審査'!$U$6:$U$205,"保留")&" 件"
A11: ③ STEP4 審査待ち | D11: =COUNTIF('①企画一覧・審査'!$P$6:$P$205,"③ STEP4 審査待ち")&" 件" | F11: ボツ | I11: =COUNTIF('①企画一覧・審査'!$U$6:$U$205,"ボツ")&" 件"
A12: △ 修正して再審査 | D12: =COUNTIF('①企画一覧・審査'!$P$6:$P$205,"△ 修正して再審査")&" 件" | F12: 制作済み | I12: =COUNTIF('①企画一覧・審査'!$U$6:$U$205,"制作済み")&" 件"
A13: ✕ ボツ候補 | D13: =COUNTIF('①企画一覧・審査'!$P$6:$P$205,"✕ ボツ候補")&" 件"
A14: ✕ STEP1不通過 | D14: =COUNTIF('①企画一覧・審査'!$P$6:$P$205,"✕ STEP1不通過")&" 件"
A15: ◎ 候補リスト | D15: =COUNTIF('①企画一覧・審査'!$P$6:$P$205,"◎ 候補リスト")&" 件"
A16: ■ ランキング
A17: 順位 | B17: 区分 | C17: 企画名 | D17: タイトル／サムネ案 | E17: ワクワク | F17: 労力 | G17: 確信度 | H17: 合計 | I17: 最終判断 | J17: STEP1 根拠・メモ
A18: =IF(COUNT('①企画一覧・審査'!$W$6:$W$205)<1,"",1) | B18: =IF($L18="","",INDEX('①企画一覧・審査'!$B$6:$B$205,$L18)&"") | C18: =IF($L18="","",INDEX('①企画一覧・審査'!$C$6:$C$205,$L18)&"") | D18: =IF($L18="","",INDEX('①企画一覧・審査'!$I$6:$I$205,$L18)&"") | E18: =IF($L18="","",INDEX('①企画一覧・審査'!$Q$6:$Q$205,$L18)) | F18: =IF($L18="","",INDEX('①企画一覧・審査'!$R$6:$R$205,$L18)) | G18: =IF($L18="","",INDEX('①企画一覧・審査'!$S$6:$S$205,$L18)) | H18: =IF($L18="","",INDEX('①企画一覧・審査'!$T$6:$T$205,$L18)) | I18: =IF($L18="","",INDEX('①企画一覧・審査'!$U$6:$U$205,$L18)&"") | J18: =IF($L18="","",INDEX('①企画一覧・審査'!$F$6:$F$205,$L18)&"") | L18: =IF(A18="","",MATCH(LARGE('①企画一覧・審査'!$W$6:$W$205,1),'①企画一覧・審査'!$W$6:$W$205,0))
A19: =IF(COUNT('①企画一覧・審査'!$W$6:$W$205)<2,"",2) | B19: =IF($L19="","",INDEX('①企画一覧・審査'!$B$6:$B$205,$L19)&"") | C19: =IF($L19="","",INDEX('①企画一覧・審査'!$C$6:$C$205,$L19)&"") | D19: =IF($L19="","",INDEX('①企画一覧・審査'!$I$6:$I$205,$L19)&"") | E19: =IF($L19="","",INDEX('①企画一覧・審査'!$Q$6:$Q$205,$L19)) | F19: =IF($L19="","",INDEX('①企画一覧・審査'!$R$6:$R$205,$L19)) | G19: =IF($L19="","",INDEX('①企画一覧・審査'!$S$6:$S$205,$L19)) | H19: =IF($L19="","",INDEX('①企画一覧・審査'!$T$6:$T$205,$L19)) | I19: =IF($L19="","",INDEX('①企画一覧・審査'!$U$6:$U$205,$L19)&"") | J19: =IF($L19="","",INDEX('①企画一覧・審査'!$F$6:$F$205,$L19)&"") | L19: =IF(A19="","",MATCH(LARGE('①企画一覧・審査'!$W$6:$W$205,2),'①企画一覧・審査'!$W$6:$W$205,0))
A20: =IF(COUNT('①企画一覧・審査'!$W$6:$W$205)<3,"",3) | B20: =IF($L20="","",INDEX('①企画一覧・審査'!$B$6:$B$205,$L20)&"") | C20: =IF($L20="","",INDEX('①企画一覧・審査'!$C$6:$C$205,$L20)&"") | D20: =IF($L20="","",INDEX('①企画一覧・審査'!$I$6:$I$205,$L20)&"") | E20: =IF($L20="","",INDEX('①企画一覧・審査'!$Q$6:$Q$205,$L20)) | F20: =IF($L20="","",INDEX('①企画一覧・審査'!$R$6:$R$205,$L20)) | G20: =IF($L20="","",INDEX('①企画一覧・審査'!$S$6:$S$205,$L20)) | H20: =IF($L20="","",INDEX('①企画一覧・審査'!$T$6:$T$205,$L20)) | I20: =IF($L20="","",INDEX('①企画一覧・審査'!$U$6:$U$205,$L20)&"") | J20: =IF($L20="","",INDEX('①企画一覧・審査'!$F$6:$F$205,$L20)&"") | L20: =IF(A20="","",MATCH(LARGE('①企画一覧・審査'!$W$6:$W$205,3),'①企画一覧・審査'!$W$6:$W$205,0))
A21: =IF(COUNT('①企画一覧・審査'!$W$6:$W$205)<4,"",4) | B21: =IF($L21="","",INDEX('①企画一覧・審査'!$B$6:$B$205,$L21)&"") | C21: =IF($L21="","",INDEX('①企画一覧・審査'!$C$6:$C$205,$L21)&"") | D21: =IF($L21="","",INDEX('①企画一覧・審査'!$I$6:$I$205,$L21)&"") | E21: =IF($L21="","",INDEX('①企画一覧・審査'!$Q$6:$Q$205,$L21)) | F21: =IF($L21="","",INDEX('①企画一覧・審査'!$R$6:$R$205,$L21)) | G21: =IF($L21="","",INDEX('①企画一覧・審査'!$S$6:$S$205,$L21)) | H21: =IF($L21="","",INDEX('①企画一覧・審査'!$T$6:$T$205,$L21)) | I21: =IF($L21="","",INDEX('①企画一覧・審査'!$U$6:$U$205,$L21)&"") | J21: =IF($L21="","",INDEX('①企画一覧・審査'!$F$6:$F$205,$L21)&"") | L21: =IF(A21="","",MATCH(LARGE('①企画一覧・審査'!$W$6:$W$205,4),'①企画一覧・審査'!$W$6:$W$205,0))
A22: =IF(COUNT('①企画一覧・審査'!$W$6:$W$205)<5,"",5) | B22: =IF($L22="","",INDEX('①企画一覧・審査'!$B$6:$B$205,$L22)&"") | C22: =IF($L22="","",INDEX('①企画一覧・審査'!$C$6:$C$205,$L22)&"") | D22: =IF($L22="","",INDEX('①企画一覧・審査'!$I$6:$I$205,$L22)&"") | E22: =IF($L22="","",INDEX('①企画一覧・審査'!$Q$6:$Q$205,$L22)) | F22: =IF($L22="","",INDEX('①企画一覧・審査'!$R$6:$R$205,$L22)) | G22: =IF($L22="","",INDEX('①企画一覧・審査'!$S$6:$S$205,$L22)) | H22: =IF($L22="","",INDEX('①企画一覧・審査'!$T$6:$T$205,$L22)) | I22: =IF($L22="","",INDEX('①企画一覧・審査'!$U$6:$U$205,$L22)&"") | J22: =IF($L22="","",INDEX('①企画一覧・審査'!$F$6:$F$205,$L22)&"") | L22: =IF(A22="","",MATCH(LARGE('①企画一覧・審査'!$W$6:$W$205,5),'①企画一覧・審査'!$W$6:$W$205,0))
A23: =IF(COUNT('①企画一覧・審査'!$W$6:$W$205)<6,"",6) | B23: =IF($L23="","",INDEX('①企画一覧・審査'!$B$6:$B$205,$L23)&"") | C23: =IF($L23="","",INDEX('①企画一覧・審査'!$C$6:$C$205,$L23)&"") | D23: =IF($L23="","",INDEX('①企画一覧・審査'!$I$6:$I$205,$L23)&"") | E23: =IF($L23="","",INDEX('①企画一覧・審査'!$Q$6:$Q$205,$L23)) | F23: =IF($L23="","",INDEX('①企画一覧・審査'!$R$6:$R$205,$L23)) | G23: =IF($L23="","",INDEX('①企画一覧・審査'!$S$6:$S$205,$L23)) | H23: =IF($L23="","",INDEX('①企画一覧・審査'!$T$6:$T$205,$L23)) | I23: =IF($L23="","",INDEX('①企画一覧・審査'!$U$6:$U$205,$L23)&"") | J23: =IF($L23="","",INDEX('①企画一覧・審査'!$F$6:$F$205,$L23)&"") | L23: =IF(A23="","",MATCH(LARGE('①企画一覧・審査'!$W$6:$W$205,6),'①企画一覧・審査'!$W$6:$W$205,0))
A24: =IF(COUNT('①企画一覧・審査'!$W$6:$W$205)<7,"",7) | B24: =IF($L24="","",INDEX('①企画一覧・審査'!$B$6:$B$205,$L24)&"") | C24: =IF($L24="","",INDEX('①企画一覧・審査'!$C$6:$C$205,$L24)&"") | D24: =IF($L24="","",INDEX('①企画一覧・審査'!$I$6:$I$205,$L24)&"") | E24: =IF($L24="","",INDEX('①企画一覧・審査'!$Q$6:$Q$205,$L24)) | F24: =IF($L24="","",INDEX('①企画一覧・審査'!$R$6:$R$205,$L24)) | G24: =IF($L24="","",INDEX('①企画一覧・審査'!$S$6:$S$205,$L24)) | H24: =IF($L24="","",INDEX('①企画一覧・審査'!$T$6:$T$205,$L24)) | I24: =IF($L24="","",INDEX('①企画一覧・審査'!$U$6:$U$205,$L24)&"") | J24: =IF($L24="","",INDEX('①企画一覧・審査'!$F$6:$F$205,$L24)&"") | L24: =IF(A24="","",MATCH(LARGE('①企画一覧・審査'!$W$6:$W$205,7),'①企画一覧・審査'!$W$6:$W$205,0))
A25: =IF(COUNT('①企画一覧・審査'!$W$6:$W$205)<8,"",8) | B25: =IF($L25="","",INDEX('①企画一覧・審査'!$B$6:$B$205,$L25)&"") | C25: =IF($L25="","",INDEX('①企画一覧・審査'!$C$6:$C$205,$L25)&"") | D25: =IF($L25="","",INDEX('①企画一覧・審査'!$I$6:$I$205,$L25)&"") | E25: =IF($L25="","",INDEX('①企画一覧・審査'!$Q$6:$Q$205,$L25)) | F25: =IF($L25="","",INDEX('①企画一覧・審査'!$R$6:$R$205,$L25)) | G25: =IF($L25="","",INDEX('①企画一覧・審査'!$S$6:$S$205,$L25)) | H25: =IF($L25="","",INDEX('①企画一覧・審査'!$T$6:$T$205,$L25)) | I25: =IF($L25="","",INDEX('①企画一覧・審査'!$U$6:$U$205,$L25)&"") | J25: =IF($L25="","",INDEX('①企画一覧・審査'!$F$6:$F$205,$L25)&"") | L25: =IF(A25="","",MATCH(LARGE('①企画一覧・審査'!$W$6:$W$205,8),'①企画一覧・審査'!$W$6:$W$205,0))
A26: =IF(COUNT('①企画一覧・審査'!$W$6:$W$205)<9,"",9) | B26: =IF($L26="","",INDEX('①企画一覧・審査'!$B$6:$B$205,$L26)&"") | C26: =IF($L26="","",INDEX('①企画一覧・審査'!$C$6:$C$205,$L26)&"") | D26: =IF($L26="","",INDEX('①企画一覧・審査'!$I$6:$I$205,$L26)&"") | E26: =IF($L26="","",INDEX('①企画一覧・審査'!$Q$6:$Q$205,$L26)) | F26: =IF($L26="","",INDEX('①企画一覧・審査'!$R$6:$R$205,$L26)) | G26: =IF($L26="","",INDEX('①企画一覧・審査'!$S$6:$S$205,$L26)) | H26: =IF($L26="","",INDEX('①企画一覧・審査'!$T$6:$T$205,$L26)) | I26: =IF($L26="","",INDEX('①企画一覧・審査'!$U$6:$U$205,$L26)&"") | J26: =IF($L26="","",INDEX('①企画一覧・審査'!$F$6:$F$205,$L26)&"") | L26: =IF(A26="","",MATCH(LARGE('①企画一覧・審査'!$W$6:$W$205,9),'①企画一覧・審査'!$W$6:$W$205,0))
A27: =IF(COUNT('①企画一覧・審査'!$W$6:$W$205)<10,"",10) | B27: =IF($L27="","",INDEX('①企画一覧・審査'!$B$6:$B$205,$L27)&"") | C27: =IF($L27="","",INDEX('①企画一覧・審査'!$C$6:$C$205,$L27)&"") | D27: =IF($L27="","",INDEX('①企画一覧・審査'!$I$6:$I$205,$L27)&"") | E27: =IF($L27="","",INDEX('①企画一覧・審査'!$Q$6:$Q$205,$L27)) | F27: =IF($L27="","",INDEX('①企画一覧・審査'!$R$6:$R$205,$L27)) | G27: =IF($L27="","",INDEX('①企画一覧・審査'!$S$6:$S$205,$L27)) | H27: =IF($L27="","",INDEX('①企画一覧・審査'!$T$6:$T$205,$L27)) | I27: =IF($L27="","",INDEX('①企画一覧・審査'!$U$6:$U$205,$L27)&"") | J27: =IF($L27="","",INDEX('①企画一覧・審査'!$F$6:$F$205,$L27)&"") | L27: =IF(A27="","",MATCH(LARGE('①企画一覧・審査'!$W$6:$W$205,10),'①企画一覧・審査'!$W$6:$W$205,0))
A28: =IF(COUNT('①企画一覧・審査'!$W$6:$W$205)<11,"",11) | B28: =IF($L28="","",INDEX('①企画一覧・審査'!$B$6:$B$205,$L28)&"") | C28: =IF($L28="","",INDEX('①企画一覧・審査'!$C$6:$C$205,$L28)&"") | D28: =IF($L28="","",INDEX('①企画一覧・審査'!$I$6:$I$205,$L28)&"") | E28: =IF($L28="","",INDEX('①企画一覧・審査'!$Q$6:$Q$205,$L28)) | F28: =IF($L28="","",INDEX('①企画一覧・審査'!$R$6:$R$205,$L28)) | G28: =IF($L28="","",INDEX('①企画一覧・審査'!$S$6:$S$205,$L28)) | H28: =IF($L28="","",INDEX('①企画一覧・審査'!$T$6:$T$205,$L28)) | I28: =IF($L28="","",INDEX('①企画一覧・審査'!$U$6:$U$205,$L28)&"") | J28: =IF($L28="","",INDEX('①企画一覧・審査'!$F$6:$F$205,$L28)&"") | L28: =IF(A28="","",MATCH(LARGE('①企画一覧・審査'!$W$6:$W$205,11),'①企画一覧・審査'!$W$6:$W$205,0))
A29: =IF(COUNT('①企画一覧・審査'!$W$6:$W$205)<12,"",12) | B29: =IF($L29="","",INDEX('①企画一覧・審査'!$B$6:$B$205,$L29)&"") | C29: =IF($L29="","",INDEX('①企画一覧・審査'!$C$6:$C$205,$L29)&"") | D29: =IF($L29="","",INDEX('①企画一覧・審査'!$I$6:$I$205,$L29)&"") | E29: =IF($L29="","",INDEX('①企画一覧・審査'!$Q$6:$Q$205,$L29)) | F29: =IF($L29="","",INDEX('①企画一覧・審査'!$R$6:$R$205,$L29)) | G29: =IF($L29="","",INDEX('①企画一覧・審査'!$S$6:$S$205,$L29)) | H29: =IF($L29="","",INDEX('①企画一覧・審査'!$T$6:$T$205,$L29)) | I29: =IF($L29="","",INDEX('①企画一覧・審査'!$U$6:$U$205,$L29)&"") | J29: =IF($L29="","",INDEX('①企画一覧・審査'!$F$6:$F$205,$L29)&"") | L29: =IF(A29="","",MATCH(LARGE('①企画一覧・審査'!$W$6:$W$205,12),'①企画一覧・審査'!$W$6:$W$205,0))
A30: =IF(COUNT('①企画一覧・審査'!$W$6:$W$205)<13,"",13) | B30: =IF($L30="","",INDEX('①企画一覧・審査'!$B$6:$B$205,$L30)&"") | C30: =IF($L30="","",INDEX('①企画一覧・審査'!$C$6:$C$205,$L30)&"") | D30: =IF($L30="","",INDEX('①企画一覧・審査'!$I$6:$I$205,$L30)&"") | E30: =IF($L30="","",INDEX('①企画一覧・審査'!$Q$6:$Q$205,$L30)) | F30: =IF($L30="","",INDEX('①企画一覧・審査'!$R$6:$R$205,$L30)) | G30: =IF($L30="","",INDEX('①企画一覧・審査'!$S$6:$S$205,$L30)) | H30: =IF($L30="","",INDEX('①企画一覧・審査'!$T$6:$T$205,$L30)) | I30: =IF($L30="","",INDEX('①企画一覧・審査'!$U$6:$U$205,$L30)&"") | J30: =IF($L30="","",INDEX('①企画一覧・審査'!$F$6:$F$205,$L30)&"") | L30: =IF(A30="","",MATCH(LARGE('①企画一覧・審査'!$W$6:$W$205,13),'①企画一覧・審査'!$W$6:$W$205,0))
A31: =IF(COUNT('①企画一覧・審査'!$W$6:$W$205)<14,"",14) | B31: =IF($L31="","",INDEX('①企画一覧・審査'!$B$6:$B$205,$L31)&"") | C31: =IF($L31="","",INDEX('①企画一覧・審査'!$C$6:$C$205,$L31)&"") | D31: =IF($L31="","",INDEX('①企画一覧・審査'!$I$6:$I$205,$L31)&"") | E31: =IF($L31="","",INDEX('①企画一覧・審査'!$Q$6:$Q$205,$L31)) | F31: =IF($L31="","",INDEX('①企画一覧・審査'!$R$6:$R$205,$L31)) | G31: =IF($L31="","",INDEX('①企画一覧・審査'!$S$6:$S$205,$L31)) | H31: =IF($L31="","",INDEX('①企画一覧・審査'!$T$6:$T$205,$L31)) | I31: =IF($L31="","",INDEX('①企画一覧・審査'!$U$6:$U$205,$L31)&"") | J31: =IF($L31="","",INDEX('①企画一覧・審査'!$F$6:$F$205,$L31)&"") | L31: =IF(A31="","",MATCH(LARGE('①企画一覧・審査'!$W$6:$W$205,14),'①企画一覧・審査'!$W$6:$W$205,0))
A32: =IF(COUNT('①企画一覧・審査'!$W$6:$W$205)<15,"",15) | B32: =IF($L32="","",INDEX('①企画一覧・審査'!$B$6:$B$205,$L32)&"") | C32: =IF($L32="","",INDEX('①企画一覧・審査'!$C$6:$C$205,$L32)&"") | D32: =IF($L32="","",INDEX('①企画一覧・審査'!$I$6:$I$205,$L32)&"") | E32: =IF($L32="","",INDEX('①企画一覧・審査'!$Q$6:$Q$205,$L32)) | F32: =IF($L32="","",INDEX('①企画一覧・審査'!$R$6:$R$205,$L32)) | G32: =IF($L32="","",INDEX('①企画一覧・審査'!$S$6:$S$205,$L32)) | H32: =IF($L32="","",INDEX('①企画一覧・審査'!$T$6:$T$205,$L32)) | I32: =IF($L32="","",INDEX('①企画一覧・審査'!$U$6:$U$205,$L32)&"") | J32: =IF($L32="","",INDEX('①企画一覧・審査'!$F$6:$F$205,$L32)&"") | L32: =IF(A32="","",MATCH(LARGE('①企画一覧・審査'!$W$6:$W$205,15),'①企画一覧・審査'!$W$6:$W$205,0))
A33: =IF(COUNT('①企画一覧・審査'!$W$6:$W$205)<16,"",16) | B33: =IF($L33="","",INDEX('①企画一覧・審査'!$B$6:$B$205,$L33)&"") | C33: =IF($L33="","",INDEX('①企画一覧・審査'!$C$6:$C$205,$L33)&"") | D33: =IF($L33="","",INDEX('①企画一覧・審査'!$I$6:$I$205,$L33)&"") | E33: =IF($L33="","",INDEX('①企画一覧・審査'!$Q$6:$Q$205,$L33)) | F33: =IF($L33="","",INDEX('①企画一覧・審査'!$R$6:$R$205,$L33)) | G33: =IF($L33="","",INDEX('①企画一覧・審査'!$S$6:$S$205,$L33)) | H33: =IF($L33="","",INDEX('①企画一覧・審査'!$T$6:$T$205,$L33)) | I33: =IF($L33="","",INDEX('①企画一覧・審査'!$U$6:$U$205,$L33)&"") | J33: =IF($L33="","",INDEX('①企画一覧・審査'!$F$6:$F$205,$L33)&"") | L33: =IF(A33="","",MATCH(LARGE('①企画一覧・審査'!$W$6:$W$205,16),'①企画一覧・審査'!$W$6:$W$205,0))
A34: =IF(COUNT('①企画一覧・審査'!$W$6:$W$205)<17,"",17) | B34: =IF($L34="","",INDEX('①企画一覧・審査'!$B$6:$B$205,$L34)&"") | C34: =IF($L34="","",INDEX('①企画一覧・審査'!$C$6:$C$205,$L34)&"") | D34: =IF($L34="","",INDEX('①企画一覧・審査'!$I$6:$I$205,$L34)&"") | E34: =IF($L34="","",INDEX('①企画一覧・審査'!$Q$6:$Q$205,$L34)) | F34: =IF($L34="","",INDEX('①企画一覧・審査'!$R$6:$R$205,$L34)) | G34: =IF($L34="","",INDEX('①企画一覧・審査'!$S$6:$S$205,$L34)) | H34: =IF($L34="","",INDEX('①企画一覧・審査'!$T$6:$T$205,$L34)) | I34: =IF($L34="","",INDEX('①企画一覧・審査'!$U$6:$U$205,$L34)&"") | J34: =IF($L34="","",INDEX('①企画一覧・審査'!$F$6:$F$205,$L34)&"") | L34: =IF(A34="","",MATCH(LARGE('①企画一覧・審査'!$W$6:$W$205,17),'①企画一覧・審査'!$W$6:$W$205,0))
A35: =IF(COUNT('①企画一覧・審査'!$W$6:$W$205)<18,"",18) | B35: =IF($L35="","",INDEX('①企画一覧・審査'!$B$6:$B$205,$L35)&"") | C35: =IF($L35="","",INDEX('①企画一覧・審査'!$C$6:$C$205,$L35)&"") | D35: =IF($L35="","",INDEX('①企画一覧・審査'!$I$6:$I$205,$L35)&"") | E35: =IF($L35="","",INDEX('①企画一覧・審査'!$Q$6:$Q$205,$L35)) | F35: =IF($L35="","",INDEX('①企画一覧・審査'!$R$6:$R$205,$L35)) | G35: =IF($L35="","",INDEX('①企画一覧・審査'!$S$6:$S$205,$L35)) | H35: =IF($L35="","",INDEX('①企画一覧・審査'!$T$6:$T$205,$L35)) | I35: =IF($L35="","",INDEX('①企画一覧・審査'!$U$6:$U$205,$L35)&"") | J35: =IF($L35="","",INDEX('①企画一覧・審査'!$F$6:$F$205,$L35)&"") | L35: =IF(A35="","",MATCH(LARGE('①企画一覧・審査'!$W$6:$W$205,18),'①企画一覧・審査'!$W$6:$W$205,0))
A36: =IF(COUNT('①企画一覧・審査'!$W$6:$W$205)<19,"",19) | B36: =IF($L36="","",INDEX('①企画一覧・審査'!$B$6:$B$205,$L36)&"") | C36: =IF($L36="","",INDEX('①企画一覧・審査'!$C$6:$C$205,$L36)&"") | D36: =IF($L36="","",INDEX('①企画一覧・審査'!$I$6:$I$205,$L36)&"") | E36: =IF($L36="","",INDEX('①企画一覧・審査'!$Q$6:$Q$205,$L36)) | F36: =IF($L36="","",INDEX('①企画一覧・審査'!$R$6:$R$205,$L36)) | G36: =IF($L36="","",INDEX('①企画一覧・審査'!$S$6:$S$205,$L36)) | H36: =IF($L36="","",INDEX('①企画一覧・審査'!$T$6:$T$205,$L36)) | I36: =IF($L36="","",INDEX('①企画一覧・審査'!$U$6:$U$205,$L36)&"") | J36: =IF($L36="","",INDEX('①企画一覧・審査'!$F$6:$F$205,$L36)&"") | L36: =IF(A36="","",MATCH(LARGE('①企画一覧・審査'!$W$6:$W$205,19),'①企画一覧・審査'!$W$6:$W$205,0))
A37: =IF(COUNT('①企画一覧・審査'!$W$6:$W$205)<20,"",20) | B37: =IF($L37="","",INDEX('①企画一覧・審査'!$B$6:$B$205,$L37)&"") | C37: =IF($L37="","",INDEX('①企画一覧・審査'!$C$6:$C$205,$L37)&"") | D37: =IF($L37="","",INDEX('①企画一覧・審査'!$I$6:$I$205,$L37)&"") | E37: =IF($L37="","",INDEX('①企画一覧・審査'!$Q$6:$Q$205,$L37)) | F37: =IF($L37="","",INDEX('①企画一覧・審査'!$R$6:$R$205,$L37)) | G37: =IF($L37="","",INDEX('①企画一覧・審査'!$S$6:$S$205,$L37)) | H37: =IF($L37="","",INDEX('①企画一覧・審査'!$T$6:$T$205,$L37)) | I37: =IF($L37="","",INDEX('①企画一覧・審査'!$U$6:$U$205,$L37)&"") | J37: =IF($L37="","",INDEX('①企画一覧・審査'!$F$6:$F$205,$L37)&"") | L37: =IF(A37="","",MATCH(LARGE('①企画一覧・審査'!$W$6:$W$205,20),'①企画一覧・審査'!$W$6:$W$205,0))
A38: =IF(COUNT('①企画一覧・審査'!$W$6:$W$205)<21,"",21) | B38: =IF($L38="","",INDEX('①企画一覧・審査'!$B$6:$B$205,$L38)&"") | C38: =IF($L38="","",INDEX('①企画一覧・審査'!$C$6:$C$205,$L38)&"") | D38: =IF($L38="","",INDEX('①企画一覧・審査'!$I$6:$I$205,$L38)&"") | E38: =IF($L38="","",INDEX('①企画一覧・審査'!$Q$6:$Q$205,$L38)) | F38: =IF($L38="","",INDEX('①企画一覧・審査'!$R$6:$R$205,$L38)) | G38: =IF($L38="","",INDEX('①企画一覧・審査'!$S$6:$S$205,$L38)) | H38: =IF($L38="","",INDEX('①企画一覧・審査'!$T$6:$T$205,$L38)) | I38: =IF($L38="","",INDEX('①企画一覧・審査'!$U$6:$U$205,$L38)&"") | J38: =IF($L38="","",INDEX('①企画一覧・審査'!$F$6:$F$205,$L38)&"") | L38: =IF(A38="","",MATCH(LARGE('①企画一覧・審査'!$W$6:$W$205,21),'①企画一覧・審査'!$W$6:$W$205,0))
A39: =IF(COUNT('①企画一覧・審査'!$W$6:$W$205)<22,"",22) | B39: =IF($L39="","",INDEX('①企画一覧・審査'!$B$6:$B$205,$L39)&"") | C39: =IF($L39="","",INDEX('①企画一覧・審査'!$C$6:$C$205,$L39)&"") | D39: =IF($L39="","",INDEX('①企画一覧・審査'!$I$6:$I$205,$L39)&"") | E39: =IF($L39="","",INDEX('①企画一覧・審査'!$Q$6:$Q$205,$L39)) | F39: =IF($L39="","",INDEX('①企画一覧・審査'!$R$6:$R$205,$L39)) | G39: =IF($L39="","",INDEX('①企画一覧・審査'!$S$6:$S$205,$L39)) | H39: =IF($L39="","",INDEX('①企画一覧・審査'!$T$6:$T$205,$L39)) | I39: =IF($L39="","",INDEX('①企画一覧・審査'!$U$6:$U$205,$L39)&"") | J39: =IF($L39="","",INDEX('①企画一覧・審査'!$F$6:$F$205,$L39)&"") | L39: =IF(A39="","",MATCH(LARGE('①企画一覧・審査'!$W$6:$W$205,22),'①企画一覧・審査'!$W$6:$W$205,0))
A40: =IF(COUNT('①企画一覧・審査'!$W$6:$W$205)<23,"",23) | B40: =IF($L40="","",INDEX('①企画一覧・審査'!$B$6:$B$205,$L40)&"") | C40: =IF($L40="","",INDEX('①企画一覧・審査'!$C$6:$C$205,$L40)&"") | D40: =IF($L40="","",INDEX('①企画一覧・審査'!$I$6:$I$205,$L40)&"") | E40: =IF($L40="","",INDEX('①企画一覧・審査'!$Q$6:$Q$205,$L40)) | F40: =IF($L40="","",INDEX('①企画一覧・審査'!$R$6:$R$205,$L40)) | G40: =IF($L40="","",INDEX('①企画一覧・審査'!$S$6:$S$205,$L40)) | H40: =IF($L40="","",INDEX('①企画一覧・審査'!$T$6:$T$205,$L40)) | I40: =IF($L40="","",INDEX('①企画一覧・審査'!$U$6:$U$205,$L40)&"") | J40: =IF($L40="","",INDEX('①企画一覧・審査'!$F$6:$F$205,$L40)&"") | L40: =IF(A40="","",MATCH(LARGE('①企画一覧・審査'!$W$6:$W$205,23),'①企画一覧・審査'!$W$6:$W$205,0))
A41: =IF(COUNT('①企画一覧・審査'!$W$6:$W$205)<24,"",24) | B41: =IF($L41="","",INDEX('①企画一覧・審査'!$B$6:$B$205,$L41)&"") | C41: =IF($L41="","",INDEX('①企画一覧・審査'!$C$6:$C$205,$L41)&"") | D41: =IF($L41="","",INDEX('①企画一覧・審査'!$I$6:$I$205,$L41)&"") | E41: =IF($L41="","",INDEX('①企画一覧・審査'!$Q$6:$Q$205,$L41)) | F41: =IF($L41="","",INDEX('①企画一覧・審査'!$R$6:$R$205,$L41)) | G41: =IF($L41="","",INDEX('①企画一覧・審査'!$S$6:$S$205,$L41)) | H41: =IF($L41="","",INDEX('①企画一覧・審査'!$T$6:$T$205,$L41)) | I41: =IF($L41="","",INDEX('①企画一覧・審査'!$U$6:$U$205,$L41)&"") | J41: =IF($L41="","",INDEX('①企画一覧・審査'!$F$6:$F$205,$L41)&"") | L41: =IF(A41="","",MATCH(LARGE('①企画一覧・審査'!$W$6:$W$205,24),'①企画一覧・審査'!$W$6:$W$205,0))
A42: =IF(COUNT('①企画一覧・審査'!$W$6:$W$205)<25,"",25) | B42: =IF($L42="","",INDEX('①企画一覧・審査'!$B$6:$B$205,$L42)&"") | C42: =IF($L42="","",INDEX('①企画一覧・審査'!$C$6:$C$205,$L42)&"") | D42: =IF($L42="","",INDEX('①企画一覧・審査'!$I$6:$I$205,$L42)&"") | E42: =IF($L42="","",INDEX('①企画一覧・審査'!$Q$6:$Q$205,$L42)) | F42: =IF($L42="","",INDEX('①企画一覧・審査'!$R$6:$R$205,$L42)) | G42: =IF($L42="","",INDEX('①企画一覧・審査'!$S$6:$S$205,$L42)) | H42: =IF($L42="","",INDEX('①企画一覧・審査'!$T$6:$T$205,$L42)) | I42: =IF($L42="","",INDEX('①企画一覧・審査'!$U$6:$U$205,$L42)&"") | J42: =IF($L42="","",INDEX('①企画一覧・審査'!$F$6:$F$205,$L42)&"") | L42: =IF(A42="","",MATCH(LARGE('①企画一覧・審査'!$W$6:$W$205,25),'①企画一覧・審査'!$W$6:$W$205,0))
...

Sheet 審査ガイド
A1: STEP4 審査ガイド（○△×の付け方）
A2: コツ：1本ずつ「なぜ○と言えるか」を一言で説明できない項目は○にしない。迷ったら△にして、審査メモに「何を直せば○になるか」を書く。全部○の企画ばかりになったら、基準が甘いサイン。
A4: チェック | B4: ○にしてよい条件（このチャンネル用の具体基準） | C4: △／× の目安
A5: ①実現可能性 | B5: 撮影・編集の時間、出演者（受講生・ゲスト）の許可、素材（答案・模試音源）が今すでに手元にある or 2週間以内に揃う | C5: △：協力者の許可待ち ／ ×：素材や協力者のあてがない
A6: ②新規視聴者 | B6: チャンネル名と顔を隠し、タイトルとサムネだけでもIELTS学習者がクリックすると言い切れる（STEP1のアウトライアーと同じ“型”がある） | C6: △：内輪ネタ・前提知識が必要 ／ ×：自分を知っている人しか興味を持たない
A7: ③既存視聴者 | B7: 今の視聴者（IELTS学習者・大学院留学検討者）の8割以上が見たいと思う | C7: △：一部の層（例：Task1だけ）向け ／ ×：今の視聴者と関係が薄い
A8: ④再生ポテンシャル | B8: Long 3,000再生／Shorts 10,000再生（STEP1のキラー定義）に届くと本気で信じられる。※転換枠は「相談・申込への導線になるか」で判定 | C8: △：根拠が自チャンネル内だけ ／ ×：自分でも届くと思えない
A9: ⑤ブランド親和性 | B9: 「英語環境ゼロからIELTS・大学院へ」「添削700件の実績」というチャンネルの軸を強める | C9: △：軸から少しずれる ／ ×：バズ狙いだけで軸と無関係
A10: ⑥パッケージ化 | B10: クリックしたくなるタイトルとサムネ案が一覧に書けていて、1秒で内容が伝わる | C10: △：タイトルはあるがサムネが浮かばない ／ ×：どちらも浮かばない → 企画ごと見直し
A12: STEP5 採点の目安
A13: ワクワク | B13: 1＝義務感で作る ／ 10＝今すぐ撮りたい
A14: 労力 | B14: 1＝撮って出しで半日 ／ 10＝数週間・協力者多数（低いほど楽）
A15: 確信度 | B15: 1＝根拠なし ／ 5＝自チャンネル内で当たり ／ 8以上＝外部の小規模チャンネルでアウトライアーあり
A16: 合計 | B16: ワクワク＋(11−労力)＋確信度（最大30点）

Sheet 企画の作り方
A1: 最強のYouTube企画の作り方 ── 4ステップ方程式
A2: 核心：動画が伸びるかを決める最大の要因は、タイトルでもサムネでもクオリティでもなく「企画の根底にあるアイデア」。 方程式： ① トピック（何を） × ② フォーマット（どのように） ＝ ベースアイデア ＋ ③ アングル（切り口） → ④ 6つの基準で選別 → 企画候補リスト → 優先順位を付けて制作
A4: STEP 1 キラー・トピック（この動画は何についてのものか？）
A5: 手順 | B5: やること | E5: ポイント・基準
A6: 1. 目標を決める | B6: 目標再生回数を決める（例：「100万回再生されるか？されないなら作る意味は？」） | E6: トピック選びを間違えると、台本を書く前から失敗が決まる
A7: 2. 実績を検索 | B7: そのトピックで最も人気の動画を検索し、目標以上の再生数の動画が何本あるか確認 | E7: 過去の成功例ゼロ＝絶対ダメではない。実験枠は一定数キープしてOK
A8: 3. アウトライアーを探す | B8: チャンネル平均を大きく上回った動画（例：普段1万回→1本だけ10万回）を探す | E8: 大物は「親近感バイアス」で数字が盛られる。小規模チャンネルの当たり動画こそ「知名度なしでも伸びる」証拠
A9: 4-A. 手動で探す | B9: 検索→チャンネルページで前後の動画と再生数を比較、を繰り返す | E9: ・無料Chrome拡張「1of10」で倍率を表示 ・公開2週間未満の動画は除外 ・認証マークなし（登録者10万人未満）を優先
A10: 4-B. ツールで探す | B10: 1of10でフィルター検索 | E10: フィルター例：再生倍率3倍以上／再生10万回以上／登録者50万人未満
A11: 5. 判定 | B11: 関連アウトライアーが見つかり、目標超えの動画も十分ある → STEP2へ | E11: アウトライアーが皆無 or 目標超えが少ない → 別トピックを検討。「90%伸びる確信」が持てたら次へ
A13: STEP 2 キラー・フォーマット（どのように見せるか？） トピック × フォーマット ＝ ベースアイデア
A14: フォーマット | B14: 視聴者がクリックする理由 | F14: 例（トピック：ハンバーガー）
A15: チュートリアル | B15: 望む結果・スキルを自分で身につけたい | F15: ハンバーガーの作り方
A16: チャレンジ | B16: 見たことのない体験を疑似体験したい。結果・苦闘・サプライズを見届けたい | F16: ○○縛りでバーガーを作ってみた
A17: 解説・考察 | B17: 答えのわからない疑問＝「好奇心の空白」を埋めたい | F17: なぜアメリカのバーガーは美味いのか？
A18: コメンタリー | B18: 特定の人の意見・視点が欲しい／ドラマ（論争・ゴシップ）が見たい | F18: 話題のバーガー店を本音レビュー
A19: Vlog | B19: 他人の生活を覗き、個人的につながりたい／別の人生を疑似体験したい | F19: バーガー屋で働く1日
A20: インタビュー | B20: 他では聞けない深い・限定的な話を聞きたい | F20: ミシュランシェフに理想のバーガーを聞く
A21: ■ フォーマット選びの問い：「なぜ視聴者はこの動画をクリックしたくなるのか？」「どんな価値を届けたいか？」＋自分のスキル＋YouTube上の既存動画の飽和度
A22: ■ 埋もれないための方法は2つだけ： ① 圧倒的に優れる（タイトル・サムネ・実行クオリティで上回る。例：MrBeastはゲーム内の電車衝突ネタを“本物”で実行） ② 圧倒的に違う ← 一般人はこちらが現実的。最有力手段＝「フォーマットの組み合わせ」
A23: ■ 組み合わせ例：Ryan Trahan ペニーシリーズ（チャレンジ×デイリーVlog → 計3.1億回再生）／Life of Riza（チュートリアル×映画風Vlog）／Hot Ones（インタビュー×激辛チャレンジ）／Mark Rober（チャレンジ×解説×コメンタリー）／Cleo Abram（解説×Vlog×インタビュー） ■ 迷ったら：教育したい → チュートリアル・解説を混ぜる／個人的につながりたい → Vlog・コメンタリーを混ぜる
A25: STEP 3 キラー・アングル（切り口＝ベースアイデアを面白くするスパイス）
A26: 例：ベースアイデア「ハンバーガーを作る×チャレンジ」（退屈）→「世界最大のバーガーを作ってみた」「100年分の歴代バーガーを作ってみた」「素人vsプロ、違いが分かる？」
A27: # | B27: アングル | C27: 効く理由（心理） | F27: 例
A28: 1 | B28: 最上級 | C28: 最大・最安・最高額など。新奇なものに本能的に惹かれる | F28: 世界最大のバーガー
A29: 2 | B29: ステークス：お金 | C29: 失う/得る可能性がサスペンスを生む。お金は誰にとっても重要 | F29: 1万円 vs 10万円のバーガー
A30: 3 | B30: ステークス：時間制限 | C30: 厳しい制限時間で緊張感が生まれる | F30: 10分でバーガーを作れるか？
A31: 4 | B31: 長期コミット（時間） | C31: 投入努力バイアス：努力が多いほど価値が高く見える | F31: 100日かけて究極のバーガーを作る
A32: 5 | B32: 網羅的（コンプリート） | C32: 全バリエーション・必要情報すべてを約束し好奇心を刺激 | F32: 全チェーン店のバーガーを食べ比べ
A33: 6 | B33: 明確なリスト（数字） | C33: 整理された馴染みの構造で、価値を効率よく約束 | F33: 失敗しないバーガーのコツ7選
A34: 7 | B34: 親近感 | C34: 著名人・人気ブランド・トレンド・人気作品に脳が惹かれる | F34: マクドナルドの再現バーガー
A35: 8 | B35: トピック＋ひねり | C35: 馴染み×意外性のコントラストで新鮮さが生まれる | F35: 給食の材料だけでバーガー
A36: 9 | B36: 比較 | C36: 並べることでコントラストが生まれる。検討中のもの・未体験のものが強い | F36: 素人 vs プロのバーガー
A37: 10 | B37: 変身・変化 | C37: ビフォーアフターとA→Bの過程を見たい欲求 | F37: 0円から最高級バーガーへ
A38: ■ アングルは組み合わせOK（MrBeast：比較×お金／Safiya Nygaard：網羅×親近感／Jordan Welch：時間×変化）。ただし詰め込みすぎ注意。ブランドとストーリーを引き立てる1〜2個に絞る。 ■ 新しいアングルは1of10でアウトライアーを眺め、自分のニッチ内外で何が効いているかを見て探す。
A40: STEP 4 キラー・基準（6つのチェック）── 1つでも「いいえ」なら修正 or ボツ
A41: # | B41: チェック項目 | D41: 問い
A42: 1 | B42: 実現可能性 | D42: このアイデアを実際に実行できるか？（予算・時間・スキル）
A43: 2 | B43: 新規視聴者の関心 | D43: あなたを全く知らない人でも興味を持つか？（持たないなら伸びる可能性は極めて低い）
A44: 3 | B44: 既存視聴者の関心 | D44: 既存視聴者の80%以上が興味を持つか？（コアなコミュニティを忘れない）
...

Sheet STEP1検証（ゆうこさん調べ）
A1: STEP1 アウトライアーリサーチ結果（キラー・トピック判定）
A2: 実施：2026-09-25／出典：ゆうこさんによる外部アウトライアーリサーチ
A4: ■ 自チャンネル基準値
A5: 登録者数 | B5: 720
A6: Long 平均再生 | B6: 331
A7: Shorts 平均再生 | B7: 1,572
A8: 直近90日 Long TOP | B8: 625再生（82.8再生／日）
A10: ■ キラー定義
A11: Long：3,000再生超え（平均の約9倍）／Shorts：10,000再生超え（平均の約6倍）
A13: ■ アウトライアー一覧
A14: トピック | B14: 動画 | C14: 倍率（原文表記） | D14: 累計再生 | E14: 登録者 | F14: 公開 | G14: 採用区分
A15: Speaking | B15: IELTS Speaking Band 7.5 ｜ ORIENT ACADEMY | C15: 58x ／ 58.09倍 | D15: 76246 | E15: 1610 | F15: 95日前 | G15: 本命（小規模で58倍）
A16: Speaking | B16: IELTS Paraphrasing Masterclass ｜ 5 Powerful Strategies for Band 7+ Writing & Speaking | C16: >100x ／ 806.27倍 | D16: 117729 | E16: 8670 | F16: 62日前 | G16: ★最優先（Speaking/Writing共通）
A17: Speaking | B17: IELTS SPEAKING TEST IN NEPAL ｜ BAND 7.5 ｜ BBC GLOBAL EDUCATION | C17: 6.9x ／ 6.92倍 | D17: 11926 | E17: 40400 | F17: 21日前 | G17: 本命
A18: Speaking | B18: IELTS Speaking Test - Band 6.5 ｜ IELTS Advantage | C18: 5.6x | D18: 311462 | E18: 5060000 | F18: — | G18: 除外（大物・親近感バイアス／実績カウントのみ）
A19: Speaking | B19: IELTS SPEAKING TEST IN NEPAL ｜ BAND 6.0 ｜ BBC GLOBAL EDUCATION | C19: 11x ／ 11.33倍 | D19: — | E19: — | F19: 9日前 | G19: 保留（公開2週間未満）
A20: Writing | B20: IELTS Paraphrasing Masterclass ｜ 5 Powerful Strategies for Band 7+ Writing & Speaking | C20: >100x ／ 806.27倍 | D20: 117729 | E20: 8670 | F20: 62日前 | G20: ★最優先（上と同一動画）
A21: Writing | B21: How I Cleared IELTS in 30 Days 🔥 4 Band to 8.5 Band ｜ My IELTS Journey (Simran IELTS) | C21: >100x ／ 112.65倍 | D21: 15795 | E21: 3860 | F21: 24日前 | G21: 本命（知名度なしでも112倍）
A22: Writing | B22: IELTS Writing Task 1 Academic: One Simple Formula for Maps | C22: 2.3x ／ 2.29倍 | D22: 11155 | E22: 153000 | F22: 21日前 | G22: 参考
A23: Writing | B23: What Makes Writing Good?（Writing Course Module 1 Part 1） | C23: 8.8x ／ 8.77倍 | D23: 28279 | E23: — | F23: 17日前 | G23: 参考（設計図型レッスン）
A24: Writing | B24: Writing Flow: What Is Cohesion and Coherence?（Writing Course Module 01 Part 2） | C24: 9.6x ／ 9.56倍 | D24: 30860 | E24: — | F24: 15日前 | G24: 参考（設計図型レッスン）
A25: Writing | B25: Prepare for IELTS Writing in 1 Hour: Step-by-Step Course | C25: 2.1x | D25: 210259 | E25: 5060000 | F25: — | G25: 除外（大物・実績カウントのみ）
A27: ※ 倍率はゆうこさんのリサーチ表記をそのまま転記（索引の表示倍率と実測倍率の2種）。大物チャンネルは親近感バイアスで数字が盛られるため証拠から除外し、実績カウントのみ。
A29: ■ トピック判定表
A30: 検証トピック | B30: 関連アウトライアー | C30: 目標超え | D30: 判定
A31: A. ielts speaking 対策 | B31: あり（小規模で58倍・806倍） | C31: 10件中 全件 | D31: STEP2へ（90%の確信あり）
A32: B. ielts writing 対策 | B32: あり（小規模で112倍・806倍） | C32: 10件中 全件 | D32: STEP2へ（90%の確信あり）
A33: C. ielts 勉強法（日本語） | B33: 皆無（索引に関連結果ゼロ） | C33: 0件 | D33: キラーにしない（別クエリで再検討・実験枠）
A34: D. イギリス 大学院 留学 準備 | B34: ほぼなし（最大6,933再生） | C34: 少ない | D34: キラーにしない（相談・コーチングへの転換枠）
A36: ■ 形式の共通点（当たっている構成）
A37: Speaking：Part1〜3を通しで見せ、最後に改善点を解説する『模試通し＋フィードバック解説型』が繰り返し当たっている。
A38: Writing：文章のつながり・設計図を示す『構成解説型レッスン』の需要が強い。
A40: ■ 優先する2本（STEP2へ）
A41: ① IELTS Paraphrasing Masterclass 型（言い換え・構成解説） ② IELTS Speaking Band 7.5 / ORIENT ACADEMY 型（模試＋フィードバック）
A42: どちらも登録1万人未満で5万〜11万再生、倍率50倍超え＝4-B条件（再生倍率3倍以上／登録者50万人未満）を大幅に超えている。
A44: ■ STEP2で分解する項目
A45: 上記2本の | B45: 分解ポイント
A46: タイトル構造 | B46: どういう語順・語彙でクリックを作っているか
A47: 冒頭30秒 | B47: 視聴者を離さない導入の作り
A48: サムネ要素 | B48: 視覚的に何で止めているか（文字数・顔・ビフォーアフター等）
