Workbook

Sheet 決定一覧
A1: タイトル・サムネ 決定一覧（各企画シートから自動）
A2: 各企画シートの組み合わせ表で「公開用」を選ぶと、ここに反映されます。
A4: 企画 | B4: 公開するタイトル | C4: 公開するサムネ | D4: 差し替え用
A5: ① 添削700件で見えた「伸びる答案」の共通点 | B5: ='① 添削700件で見えた「伸びる答案」の共通点'!C11 | C5: ='① 添削700件で見えた「伸びる答案」の共通点'!C12 | D5: ='① 添削700件で見えた「伸びる答案」の共通点'!C13
A6: ② 30代・アラサーの年齢不安 | B6: ='② 30代・アラサーの年齢不安'!C11 | C6: ='② 30代・アラサーの年齢不安'!C12 | D6: ='② 30代・アラサーの年齢不安'!C13
A7: ③ 3週間で伸びる人と伸びない人の練習の違い | B7: ='③ 3週間で伸びる人と伸びない人の練習の違い'!C11 | C7: ='③ 3週間で伸びる人と伸びない人の練習の違い'!C12 | D7: ='③ 3週間で伸びる人と伸びない人の練習の違い'!C13

Sheet ① 添削700件で見えた「伸びる答案」の共通点
A1: タイトル・サムネ決定シート｜① 添削700件で見えた「伸びる答案」の共通点
A2: 手順：❶タイトル足切り（○/×）→ ❷タイトル採点（1〜5）→ ❸サムネ足切り → ❹サムネ採点 → ❺上位からA/B/Cの組み合わせを作る → ❻1組だけ「公開用」にする。黄色セルだけ入力、他は自動。
A4: 動画のテーマ | C4: IELTSライティング｜添削700件で見えた伸びる答案の共通点
A5: 好奇心の型 | C5: 結果型（＋変身型の要素）
A6: 伏せる情報（答え） | C6: 「共通点5つ」の中身＝答案のどこを直すと伸びたのか
A7: 借りる要素（アウトライヤー） | C7: Paraphrasing Masterclass（>100x/806.27倍）の『構成と言い換えの解説』＋ Simran『30日で4→8.5』（112.65倍）の変化提示 → 借りるのは1つ：ビフォーアフターの答案を主役にする構図
A8: ストッパー（1〜2個） | C8: 大きな数字（700件）／赤ペン（見慣れたもの）／感情（驚き）
A10: ■ 決定（自動）：下の組み合わせで「公開用」を選んだものが表示されます
A11: 公開するタイトル | C11: =IFERROR(INDEX($B$56:$B$58,MATCH("公開用",$L$56:$L$58,0)),"未決定（組み合わせ表で「公開用」を選んでください）")
A12: 公開するサムネ | C12: =IFERROR(INDEX($D$56:$D$58,MATCH("公開用",$L$56:$L$58,0)),"未決定")
A13: 差し替え用 | C13: =COUNTIF($L$56:$L$58,"差し替え用")&" 組"
A14: ■ タイトル案（20案） 足切り：1つでも×なら除外 ／ 採点：1〜5（5が最高）
A15: No | B15: タイトル案 | C15: 字数 | D15: スマホで見える前半30字 | E15: ①中身と 一致 | F15: ②答えを 伏せる | G15: ③30字で 伝わる | H15: 好奇心 | I15: 強い言葉 | J15: 分かり やすさ | K15: サムネと 重複しない | L15: 合計 /20 | M15: 判定 | N15: 順位 | O15: 最終判断 | P15: メモ
A16: 1 | B16: 添削700件で見えた、IELTSライティングが伸びる答案の共通点5つ | C16: =IF(B16="","",LEN(B16)) | D16: =IF(B16="","",LEFT(B16,30)) | H16: 5 | I16: 4 | J16: 5 | K16: 5 | L16: =IF(COUNT(H16:K16)<4,"",SUM(H16:K16)) | M16: =IF(B16="","",IF(COUNTIF(E16:G16,"×")>0,"✕ 足切り",IF(COUNTA(E16:G16)<3,"未チェック","◎ 通過"))) | N16: =IF(OR(L16="",M16="✕ 足切り"),"",COUNTIFS($M$16:$M$35,"<>✕ 足切り",$L$16:$L$35,">"&L16)+1)
A17: 2 | B17: 添削700件で分かった「伸びる人」の答案はここが違う | C17: =IF(B17="","",LEN(B17)) | D17: =IF(B17="","",LEFT(B17,30)) | H17: 5 | I17: 4 | J17: 4 | K17: 5 | L17: =IF(COUNT(H17:K17)<4,"",SUM(H17:K17)) | M17: =IF(B17="","",IF(COUNTIF(E17:G17,"×")>0,"✕ 足切り",IF(COUNTA(E17:G17)<3,"未チェック","◎ 通過"))) | N17: =IF(OR(L17="",M17="✕ 足切り"),"",COUNTIFS($M$16:$M$35,"<>✕ 足切り",$L$16:$L$35,">"&L17)+1)
A18: 3 | B18: 700件の答案を見て分かった、6.5で止まる人と7.0を取る人の差 | C18: =IF(B18="","",LEN(B18)) | D18: =IF(B18="","",LEFT(B18,30)) | H18: 5 | I18: 5 | J18: 4 | K18: 4 | L18: =IF(COUNT(H18:K18)<4,"",SUM(H18:K18)) | M18: =IF(B18="","",IF(COUNTIF(E18:G18,"×")>0,"✕ 足切り",IF(COUNTA(E18:G18)<3,"未チェック","◎ 通過"))) | N18: =IF(OR(L18="",M18="✕ 足切り"),"",COUNTIFS($M$16:$M$35,"<>✕ 足切り",$L$16:$L$35,">"&L18)+1)
A19: 4 | B19: IELTSライティング、伸びる答案には共通点があった【添削700件】 | C19: =IF(B19="","",LEN(B19)) | D19: =IF(B19="","",LEFT(B19,30)) | H19: 4 | I19: 3 | J19: 5 | K19: 4 | L19: =IF(COUNT(H19:K19)<4,"",SUM(H19:K19)) | M19: =IF(B19="","",IF(COUNTIF(E19:G19,"×")>0,"✕ 足切り",IF(COUNTA(E19:G19)<3,"未チェック","◎ 通過"))) | N19: =IF(OR(L19="",M19="✕ 足切り"),"",COUNTIFS($M$16:$M$35,"<>✕ 足切り",$L$16:$L$35,">"&L19)+1)
A20: 5 | B20: なぜあの人は7.0を取れたのか。700件の答案から答えを出しました | C20: =IF(B20="","",LEN(B20)) | D20: =IF(B20="","",LEFT(B20,30)) | H20: 5 | I20: 3 | J20: 4 | K20: 4 | L20: =IF(COUNT(H20:K20)<4,"",SUM(H20:K20)) | M20: =IF(B20="","",IF(COUNTIF(E20:G20,"×")>0,"✕ 足切り",IF(COUNTA(E20:G20)<3,"未チェック","◎ 通過"))) | N20: =IF(OR(L20="",M20="✕ 足切り"),"",COUNTIFS($M$16:$M$35,"<>✕ 足切り",$L$16:$L$35,">"&L20)+1)
A21: 6 | B21: 添削700件の結論：スコアが伸びる答案は最初の1文が違う | C21: =IF(B21="","",LEN(B21)) | D21: =IF(B21="","",LEFT(B21,30)) | H21: 5 | I21: 4 | J21: 5 | K21: 4 | L21: =IF(COUNT(H21:K21)<4,"",SUM(H21:K21)) | M21: =IF(B21="","",IF(COUNTIF(E21:G21,"×")>0,"✕ 足切り",IF(COUNTA(E21:G21)<3,"未チェック","◎ 通過"))) | N21: =IF(OR(L21="",M21="✕ 足切り"),"",COUNTIFS($M$16:$M$35,"<>✕ 足切り",$L$16:$L$35,">"&L21)+1)
A22: 7 | B22: 6.5から7.0へ。答案のどこを直せば伸びるのか全部話します | C22: =IF(B22="","",LEN(B22)) | D22: =IF(B22="","",LEFT(B22,30)) | H22: 4 | I22: 3 | J22: 5 | K22: 4 | L22: =IF(COUNT(H22:K22)<4,"",SUM(H22:K22)) | M22: =IF(B22="","",IF(COUNTIF(E22:G22,"×")>0,"✕ 足切り",IF(COUNTA(E22:G22)<3,"未チェック","◎ 通過"))) | N22: =IF(OR(L22="",M22="✕ 足切り"),"",COUNTIFS($M$16:$M$35,"<>✕ 足切り",$L$16:$L$35,">"&L22)+1)
A23: 8 | B23: 700件添削して分かった、減点される答案の共通点 | C23: =IF(B23="","",LEN(B23)) | D23: =IF(B23="","",LEFT(B23,30)) | H23: 4 | I23: 4 | J23: 5 | K23: 5 | L23: =IF(COUNT(H23:K23)<4,"",SUM(H23:K23)) | M23: =IF(B23="","",IF(COUNTIF(E23:G23,"×")>0,"✕ 足切り",IF(COUNTA(E23:G23)<3,"未チェック","◎ 通過"))) | N23: =IF(OR(L23="",M23="✕ 足切り"),"",COUNTIFS($M$16:$M$35,"<>✕ 足切り",$L$16:$L$35,">"&L23)+1)
A24: 9 | B24: IELTSライティングで7.0を取った人だけがやっていたこと | C24: =IF(B24="","",LEN(B24)) | D24: =IF(B24="","",LEFT(B24,30)) | H24: 4 | I24: 3 | J24: 4 | K24: 5 | L24: =IF(COUNT(H24:K24)<4,"",SUM(H24:K24)) | M24: =IF(B24="","",IF(COUNTIF(E24:G24,"×")>0,"✕ 足切り",IF(COUNTA(E24:G24)<3,"未チェック","◎ 通過"))) | N24: =IF(OR(L24="",M24="✕ 足切り"),"",COUNTIFS($M$16:$M$35,"<>✕ 足切り",$L$16:$L$35,">"&L24)+1)
A25: 10 | B25: 添削700件で見えた「受かる答案」と「落ちる答案」の分かれ目 | C25: =IF(B25="","",LEN(B25)) | D25: =IF(B25="","",LEFT(B25,30)) | H25: 5 | I25: 4 | J25: 4 | K25: 4 | L25: =IF(COUNT(H25:K25)<4,"",SUM(H25:K25)) | M25: =IF(B25="","",IF(COUNTIF(E25:G25,"×")>0,"✕ 足切り",IF(COUNTA(E25:G25)<3,"未チェック","◎ 通過"))) | N25: =IF(OR(L25="",M25="✕ 足切り"),"",COUNTIFS($M$16:$M$35,"<>✕ 足切り",$L$16:$L$35,">"&L25)+1)
A26: 11 | B26: スコアが伸びない人の答案、全員に共通していた3つの癖 | C26: =IF(B26="","",LEN(B26)) | D26: =IF(B26="","",LEFT(B26,30)) | H26: 5 | I26: 5 | J26: 5 | K26: 5 | L26: =IF(COUNT(H26:K26)<4,"",SUM(H26:K26)) | M26: =IF(B26="","",IF(COUNTIF(E26:G26,"×")>0,"✕ 足切り",IF(COUNTA(E26:G26)<3,"未チェック","◎ 通過"))) | N26: =IF(OR(L26="",M26="✕ 足切り"),"",COUNTIFS($M$16:$M$35,"<>✕ 足切り",$L$16:$L$35,">"&L26)+1)
A27: 12 | B27: 700件の答案を並べて分かった、たった1つの差 | C27: =IF(B27="","",LEN(B27)) | D27: =IF(B27="","",LEFT(B27,30)) | H27: 5 | I27: 4 | J27: 4 | K27: 3 | L27: =IF(COUNT(H27:K27)<4,"",SUM(H27:K27)) | M27: =IF(B27="","",IF(COUNTIF(E27:G27,"×")>0,"✕ 足切り",IF(COUNTA(E27:G27)<3,"未チェック","◎ 通過"))) | N27: =IF(OR(L27="",M27="✕ 足切り"),"",COUNTIFS($M$16:$M$35,"<>✕ 足切り",$L$16:$L$35,">"&L27)+1)
... A35: 20 | B35: 伸びる答案には理由があった。700件の添削から見えた結論 | C35: =IF(B35="","",LEN(B35)) | D35: =IF(B35="","",LEFT(B35,30)) | H35: 4 | I35: 3 | J35: 4 | K35: 4 | L35: =IF(COUNT(H35:K35)<4,"",SUM(H35:K35)) | M35: =IF(B35="","",IF(COUNTIF(E35:G35,"×")>0,"✕ 足切り",IF(COUNTA(E35:G35)<3,"未チェック","◎ 通過"))) | N35: =IF(OR(L35="",M35="✕ 足切り"),"",COUNTIFS($M$16:$M$35,"<>✕ 足切り",$L$16:$L$35,">"&L35)+1)
A36: ※字数が40字を超えると赤字（長すぎの目安）。順位は足切りされていない案の中での順位（同点は同順位）。上位3位は紫。
A38: ■ サムネ下書き（12案） 足切り：1つでも×なら除外 ／ 採点：1〜5
A39: No | B39: コンセプト（何が映っている？） | C39: 型 | D39: 主役／ストッパー | E39: 文字 | F39: 字数 | G39: ①縮小でも 読める | H39: ②主役は 1つ | I39: ③制作 できる | J39: 好奇心 | K39: 2秒で 伝わる | L39: 目立つ | M39: 合計 /15 | N39: 判定 | O39: 順位 | P39: 最終判断
A40: 1 | B40: 左に赤ペンだらけの6.5答案、右にすっきりした7.0の答案 | C40: 変身型 | D40: 答案2枚／赤ペン | E40: 700件 | F40: =IF(OR(E40="",E40="なし"),0,LEN(E40)) | J40: 5 | K40: 5 | L40: 4 | M40: =IF(COUNT(J40:L40)<3,"",SUM(J40:L40)) | N40: =IF(B40="","",IF(COUNTIF(G40:I40,"×")>0,"✕ 足切り",IF(COUNTA(G40:I40)<3,"未チェック","◎ 通過"))) | O40: =IF(OR(M40="",N40="✕ 足切り"),"",COUNTIFS($N$40:$N$51,"<>✕ 足切り",$M$40:$M$51,">"&M40)+1)
A41: 2 | B41: 赤ペンを持つ手と、積み上がった答案の山 | C41: 新奇性型 | D41: 答案の山／手 | E41: 700件 | F41: =IF(OR(E41="",E41="なし"),0,LEN(E41)) | J41: 4 | K41: 5 | L41: 4 | M41: =IF(COUNT(J41:L41)<3,"",SUM(J41:L41)) | N41: =IF(B41="","",IF(COUNTIF(G41:I41,"×")>0,"✕ 足切り",IF(COUNTA(G41:I41)<3,"未チェック","◎ 通過"))) | O41: =IF(OR(M41="",N41="✕ 足切り"),"",COUNTIFS($N$40:$N$51,"<>✕ 足切り",$M$40:$M$51,">"&M41)+1)
A42: 3 | B42: 6.5の答案と7.0の答案を並べ、間に大きく対比の矢印 | C42: 変身型 | D42: 答案／矢印 | E42: ここが違う | F42: =IF(OR(E42="",E42="なし"),0,LEN(E42)) | J42: 5 | K42: 4 | L42: 4 | M42: =IF(COUNT(J42:L42)<3,"",SUM(J42:L42)) | N42: =IF(B42="","",IF(COUNTIF(G42:I42,"×")>0,"✕ 足切り",IF(COUNTA(G42:I42)<3,"未チェック","◎ 通過"))) | O42: =IF(OR(M42="",N42="✕ 足切り"),"",COUNTIFS($N$40:$N$51,"<>✕ 足切り",$M$40:$M$51,">"&M42)+1)
A43: 4 | B43: 答案を見て驚いている本人の表情、背景に答案 | C43: 瞬間型 | D43: 顔（感情）／答案 | E43: 全員同じ | F43: =IF(OR(E43="",E43="なし"),0,LEN(E43)) | J43: 5 | K43: 4 | L43: 4 | M43: =IF(COUNT(J43:L43)<3,"",SUM(J43:L43)) | N43: =IF(B43="","",IF(COUNTIF(G43:I43,"×")>0,"✕ 足切り",IF(COUNTA(G43:I43)<3,"未チェック","◎ 通過"))) | O43: =IF(OR(M43="",N43="✕ 足切り"),"",COUNTIFS($N$40:$N$51,"<>✕ 足切り",$M$40:$M$51,">"&M43)+1)
A44: 5 | B44: 答案の中の1文だけを拡大、赤で線が引かれている | C44: ストーリー型 | D44: 1文／赤線 | E44: この1文 | F44: =IF(OR(E44="",E44="なし"),0,LEN(E44)) | J44: 4 | K44: 4 | L44: 4 | M44: =IF(COUNT(J44:L44)<3,"",SUM(J44:L44)) | N44: =IF(B44="","",IF(COUNTIF(G44:I44,"×")>0,"✕ 足切り",IF(COUNTA(G44:I44)<3,"未チェック","◎ 通過"))) | O44: =IF(OR(M44="",N44="✕ 足切り"),"",COUNTIFS($N$40:$N$51,"<>✕ 足切り",$M$40:$M$51,">"&M44)+1)
A45: 6 | B45: 積み上がった答案の山と、その上に置かれたスコア表 | C45: 結果型 | D45: スコア表／答案の山 | E45: 共通点5つ | F45: =IF(OR(E45="",E45="なし"),0,LEN(E45)) | J45: 5 | K45: 5 | L45: 4 | M45: =IF(COUNT(J45:L45)<3,"",SUM(J45:L45)) | N45: =IF(B45="","",IF(COUNTIF(G45:I45,"×")>0,"✕ 足切り",IF(COUNTA(G45:I45)<3,"未チェック","◎ 通過"))) | O45: =IF(OR(M45="",N45="✕ 足切り"),"",COUNTIFS($N$40:$N$51,"<>✕ 足切り",$M$40:$M$51,">"&M45)+1)
A46: 7 | B46: 上下分割：上の答案は薄くぼやけ、下の答案は鮮明 | C46: 変身型 | D46: 答案2枚 | E46: 伸びる答案 | F46: =IF(OR(E46="",E46="なし"),0,LEN(E46)) | J46: 5 | K46: 4 | L46: 4 | M46: =IF(COUNT(J46:L46)<3,"",SUM(J46:L46)) | N46: =IF(B46="","",IF(COUNTIF(G46:I46,"×")>0,"✕ 足切り",IF(COUNTA(G46:I46)<3,"未チェック","◎ 通過"))) | O46: =IF(OR(M46="",N46="✕ 足切り"),"",COUNTIFS($N$40:$N$51,"<>✕ 足切り",$M$40:$M$51,">"&M46)+1)
A47: 8 | B47: 「6.5」と「7.0」の大きな数字だけ、背景に答案を薄く | C47: 結果型 | D47: 大きな数字 | E47: なし | F47: =IF(OR(E47="",E47="なし"),0,LEN(E47)) | J47: 4 | K47: 5 | L47: 4 | M47: =IF(COUNT(J47:L47)<3,"",SUM(J47:L47)) | N47: =IF(B47="","",IF(COUNTIF(G47:I47,"×")>0,"✕ 足切り",IF(COUNTA(G47:I47)<3,"未チェック","◎ 通過"))) | O47: =IF(OR(M47="",N47="✕ 足切り"),"",COUNTIFS($N$40:$N$51,"<>✕ 足切り",$M$40:$M$51,">"&M47)+1)
A48: 9 | B48: 答案をめくっている手元のアップ | C48: 瞬間型 | D48: 手／答案 | E48: ビフォー | F48: =IF(OR(E48="",E48="なし"),0,LEN(E48)) | J48: 4 | K48: 4 | L48: 3 | M48: =IF(COUNT(J48:L48)<3,"",SUM(J48:L48)) | N48: =IF(B48="","",IF(COUNTIF(G48:I48,"×")>0,"✕ 足切り",IF(COUNTA(G48:I48)<3,"未チェック","◎ 通過"))) | O48: =IF(OR(M48="",N48="✕ 足切り"),"",COUNTIFS($N$40:$N$51,"<>✕ 足切り",$M$40:$M$51,">"&M48)+1)
A49: 10 | B49: 共通点5つをチェックリスト風に並べる | C49: 結果型 | D49: チェックリスト | E49: 5つ | F49: =IF(OR(E49="",E49="なし"),0,LEN(E49)) | J49: 4 | K49: 5 | L49: 4 | M49: =IF(COUNT(J49:L49)<3,"",SUM(J49:L49)) | N49: =IF(B49="","",IF(COUNTIF(G49:I49,"×")>0,"✕ 足切り",IF(COUNTA(G49:I49)<3,"未チェック","◎ 通過"))) | O49: =IF(OR(M49="",N49="✕ 足切り"),"",COUNTIFS($N$40:$N$51,"<>✕ 足切り",$M$40:$M$51,">"&M49)+1)
A50: 11 | B50: 本人のデスクに答案が積まれ、赤ペンが置かれている | C50: ストーリー型 | D50: デスク／赤ペン | E50: 700件 | F50: =IF(OR(E50="",E50="なし"),0,LEN(E50)) | J50: 4 | K50: 4 | L50: 3 | M50: =IF(COUNT(J50:L50)<3,"",SUM(J50:L50)) | N50: =IF(B50="","",IF(COUNTIF(G50:I50,"×")>0,"✕ 足切り",IF(COUNTA(G50:I50)<3,"未チェック","◎ 通過"))) | O50: =IF(OR(M50="",N50="✕ 足切り"),"",COUNTIFS($N$40:$N$51,"<>✕ 足切り",$M$40:$M$51,">"&M50)+1)
...

Sheet ② 30代・アラサーの年齢不安
A1: タイトル・サムネ決定シート｜② 30代・アラサーの年齢不安
A2: 手順：❶タイトル足切り（○/×）→ ❷タイトル採点（1〜5）→ ❸サムネ足切り → ❹サムネ採点 → ❺上位からA/B/Cの組み合わせを作る → ❻1組だけ「公開用」にする。黄色セルだけ入力、他は自動。
A4: 動画のテーマ | C4: 社会人の大学院留学｜30代・アラサーの年齢不安
A5: 好奇心の型 | C5: ストーリー型（緊張・問い）
A6: 伏せる情報（答え） | C6: 30代でも間に合った理由／実際どうだったかの中身
A7: 借りる要素（アウトライヤー） | C7: 自チャンネル最大アウトライアー「アラサー留学はもう遅い？」1,942回の構図 → 借りるのは1つ：『問いを立てて、顔で感情を見せる構図』
A8: ストッパー（1〜2個） | C8: 顔（感情）／大きな数字（30代）／問いの吹き出し
A10: ■ 決定（自動）：下の組み合わせで「公開用」を選んだものが表示されます
A11: 公開するタイトル | C11: =IFERROR(INDEX($B$56:$B$58,MATCH("公開用",$L$56:$L$58,0)),"未決定（組み合わせ表で「公開用」を選んでください）")
A12: 公開するサムネ | C12: =IFERROR(INDEX($D$56:$D$58,MATCH("公開用",$L$56:$L$58,0)),"未決定")
A13: 差し替え用 | C13: =COUNTIF($L$56:$L$58,"差し替え用")&" 組"
A14: ■ タイトル案（20案） 足切り：1つでも×なら除外 ／ 採点：1〜5（5が最高）
A15: No | B15: タイトル案 | C15: 字数 | D15: スマホで見える前半30字 | E15: ①中身と 一致 | F15: ②答えを 伏せる | G15: ③30字で 伝わる | H15: 好奇心 | I15: 強い言葉 | J15: 分かり やすさ | K15: サムネと 重複しない | L15: 合計 /20 | M15: 判定 | N15: 順位 | O15: 最終判断 | P15: メモ
A16: 1 | B16: 30代で大学院留学して、後悔したこととしなかったこと | C16: =IF(B16="","",LEN(B16)) | D16: =IF(B16="","",LEFT(B16,30)) | H16: 5 | I16: 4 | J16: 5 | K16: 4 | L16: =IF(COUNT(H16:K16)<4,"",SUM(H16:K16)) | M16: =IF(B16="","",IF(COUNTIF(E16:G16,"×")>0,"✕ 足切り",IF(COUNTA(E16:G16)<3,"未チェック","◎ 通過"))) | N16: =IF(OR(L16="",M16="✕ 足切り"),"",COUNTIFS($M$16:$M$35,"<>✕ 足切り",$L$16:$L$35,">"&L16)+1)
A17: 2 | B17: アラサー留学はもう遅い？実際に行った私の答え | C17: =IF(B17="","",LEN(B17)) | D17: =IF(B17="","",LEFT(B17,30)) | H17: 5 | I17: 5 | J17: 5 | K17: 3 | L17: =IF(COUNT(H17:K17)<4,"",SUM(H17:K17)) | M17: =IF(B17="","",IF(COUNTIF(E17:G17,"×")>0,"✕ 足切り",IF(COUNTA(E17:G17)<3,"未チェック","◎ 通過"))) | N17: =IF(OR(L17="",M17="✕ 足切り"),"",COUNTIFS($M$16:$M$35,"<>✕ 足切り",$L$16:$L$35,">"&L17)+1)
A18: 3 | B18: 30代でイギリス大学院に行って分かった、年齢の本当の壁 | C18: =IF(B18="","",LEN(B18)) | D18: =IF(B18="","",LEFT(B18,30)) | H18: 5 | I18: 4 | J18: 4 | K18: 4 | L18: =IF(COUNT(H18:K18)<4,"",SUM(H18:K18)) | M18: =IF(B18="","",IF(COUNTIF(E18:G18,"×")>0,"✕ 足切り",IF(COUNTA(E18:G18)<3,"未チェック","◎ 通過"))) | N18: =IF(OR(L18="",M18="✕ 足切り"),"",COUNTIFS($M$16:$M$35,"<>✕ 足切り",$L$16:$L$35,">"&L18)+1)
A19: 4 | B19: 「今からでも間に合う？」30代留学の現実を全部話します | C19: =IF(B19="","",LEN(B19)) | D19: =IF(B19="","",LEFT(B19,30)) | H19: 4 | I19: 3 | J19: 5 | K19: 4 | L19: =IF(COUNT(H19:K19)<4,"",SUM(H19:K19)) | M19: =IF(B19="","",IF(COUNTIF(E19:G19,"×")>0,"✕ 足切り",IF(COUNTA(E19:G19)<3,"未チェック","◎ 通過"))) | N19: =IF(OR(L19="",M19="✕ 足切り"),"",COUNTIFS($M$16:$M$35,"<>✕ 足切り",$L$16:$L$35,">"&L19)+1)
A20: 5 | B20: 30代・社会人から大学院留学した私が、一番怖かったこと | C20: =IF(B20="","",LEN(B20)) | D20: =IF(B20="","",LEFT(B20,30)) | H20: 5 | I20: 4 | J20: 4 | K20: 4 | L20: =IF(COUNT(H20:K20)<4,"",SUM(H20:K20)) | M20: =IF(B20="","",IF(COUNTIF(E20:G20,"×")>0,"✕ 足切り",IF(COUNTA(E20:G20)<3,"未チェック","◎ 通過"))) | N20: =IF(OR(L20="",M20="✕ 足切り"),"",COUNTIFS($M$16:$M$35,"<>✕ 足切り",$L$16:$L$35,">"&L20)+1)
A21: 6 | B21: 20代と30代、大学院留学で何が違ったか正直に比べます | C21: =IF(B21="","",LEN(B21)) | D21: =IF(B21="","",LEFT(B21,30)) | H21: 5 | I21: 4 | J21: 5 | K21: 3 | L21: =IF(COUNT(H21:K21)<4,"",SUM(H21:K21)) | M21: =IF(B21="","",IF(COUNTIF(E21:G21,"×")>0,"✕ 足切り",IF(COUNTA(E21:G21)<3,"未チェック","◎ 通過"))) | N21: =IF(OR(L21="",M21="✕ 足切り"),"",COUNTIFS($M$16:$M$35,"<>✕ 足切り",$L$16:$L$35,">"&L21)+1)
A22: 7 | B22: 30代で大学院に行くのは遅いのか。結論から話します | C22: =IF(B22="","",LEN(B22)) | D22: =IF(B22="","",LEFT(B22,30)) | H22: 5 | I22: 4 | J22: 5 | K22: 4 | L22: =IF(COUNT(H22:K22)<4,"",SUM(H22:K22)) | M22: =IF(B22="","",IF(COUNTIF(E22:G22,"×")>0,"✕ 足切り",IF(COUNTA(E22:G22)<3,"未チェック","◎ 通過"))) | N22: =IF(OR(L22="",M22="✕ 足切り"),"",COUNTIFS($M$16:$M$35,"<>✕ 足切り",$L$16:$L$35,">"&L22)+1)
A23: 8 | B23: 年齢を理由に留学を諦める前に、知っておいてほしいこと | C23: =IF(B23="","",LEN(B23)) | D23: =IF(B23="","",LEFT(B23,30)) | H23: 4 | I23: 4 | J23: 5 | K23: 5 | L23: =IF(COUNT(H23:K23)<4,"",SUM(H23:K23)) | M23: =IF(B23="","",IF(COUNTIF(E23:G23,"×")>0,"✕ 足切り",IF(COUNTA(E23:G23)<3,"未チェック","◎ 通過"))) | N23: =IF(OR(L23="",M23="✕ 足切り"),"",COUNTIFS($M$16:$M$35,"<>✕ 足切り",$L$16:$L$35,">"&L23)+1)
A24: 9 | B24: 30代で留学した私が「もっと早く」と思わなかった理由 | C24: =IF(B24="","",LEN(B24)) | D24: =IF(B24="","",LEFT(B24,30)) | H24: 5 | I24: 4 | J24: 4 | K24: 4 | L24: =IF(COUNT(H24:K24)<4,"",SUM(H24:K24)) | M24: =IF(B24="","",IF(COUNTIF(E24:G24,"×")>0,"✕ 足切り",IF(COUNTA(E24:G24)<3,"未チェック","◎ 通過"))) | N24: =IF(OR(L24="",M24="✕ 足切り"),"",COUNTIFS($M$16:$M$35,"<>✕ 足切り",$L$16:$L$35,">"&L24)+1)
A25: 10 | B25: アラサーから大学院留学、周りと比べて焦った話 | C25: =IF(B25="","",LEN(B25)) | D25: =IF(B25="","",LEFT(B25,30)) | H25: 5 | I25: 4 | J25: 5 | K25: 4 | L25: =IF(COUNT(H25:K25)<4,"",SUM(H25:K25)) | M25: =IF(B25="","",IF(COUNTIF(E25:G25,"×")>0,"✕ 足切り",IF(COUNTA(E25:G25)<3,"未チェック","◎ 通過"))) | N25: =IF(OR(L25="",M25="✕ 足切り"),"",COUNTIFS($M$16:$M$35,"<>✕ 足切り",$L$16:$L$35,">"&L25)+1)
A26: 11 | B26: 30代の留学は「遅い」ではなく「有利」だった3つの理由 | C26: =IF(B26="","",LEN(B26)) | D26: =IF(B26="","",LEFT(B26,30)) | H26: 5 | I26: 5 | J26: 5 | K26: 4 | L26: =IF(COUNT(H26:K26)<4,"",SUM(H26:K26)) | M26: =IF(B26="","",IF(COUNTIF(E26:G26,"×")>0,"✕ 足切り",IF(COUNTA(E26:G26)<3,"未チェック","◎ 通過"))) | N26: =IF(OR(L26="",M26="✕ 足切り"),"",COUNTIFS($M$16:$M$35,"<>✕ 足切り",$L$16:$L$35,">"&L26)+1)
A27: 12 | B27: 社会人6年目で大学院へ。30代の挑戦がどう見えたか | C27: =IF(B27="","",LEN(B27)) | D27: =IF(B27="","",LEFT(B27,30)) | H27: 4 | I27: 3 | J27: 4 | K27: 4 | L27: =IF(COUNT(H27:K27)<4,"",SUM(H27:K27)) | M27: =IF(B27="","",IF(COUNTIF(E27:G27,"×")>0,"✕ 足切り",IF(COUNTA(E27:G27)<3,"未チェック","◎ 通過"))) | N27: =IF(OR(L27="",M27="✕ 足切り"),"",COUNTIFS($M$16:$M$35,"<>✕ 足切り",$L$16:$L$35,">"&L27)+1)
... A35: 20 | B35: 30代の大学院留学、始める前に知っておきたかったこと | C35: =IF(B35="","",LEN(B35)) | D35: =IF(B35="","",LEFT(B35,30)) | H35: 4 | I35: 3 | J35: 5 | K35: 5 | L35: =IF(COUNT(H35:K35)<4,"",SUM(H35:K35)) | M35: =IF(B35="","",IF(COUNTIF(E35:G35,"×")>0,"✕ 足切り",IF(COUNTA(E35:G35)<3,"未チェック","◎ 通過"))) | N35: =IF(OR(L35="",M35="✕ 足切り"),"",COUNTIFS($M$16:$M$35,"<>✕ 足切り",$L$16:$L$35,">"&L35)+1)
A36: ※字数が40字を超えると赤字（長すぎの目安）。順位は足切りされていない案の中での順位（同点は同順位）。上位3位は紫。
A38: ■ サムネ下書き（12案） 足切り：1つでも×なら除外 ／ 採点：1〜5
A39: No | B39: コンセプト（何が映っている？） | C39: 型 | D39: 主役／ストッパー | E39: 文字 | F39: 字数 | G39: ①縮小でも 読める | H39: ②主役は 1つ | I39: ③制作 できる | J39: 好奇心 | K39: 2秒で 伝わる | L39: 目立つ | M39: 合計 /15 | N39: 判定 | O39: 順位 | P39: 最終判断
A40: 1 | B40: 本人が窓の外を見て考え込む横顔、薄暗い部屋 | C40: ストーリー型 | D40: 顔（表情） | E40: 遅い？ | F40: =IF(OR(E40="",E40="なし"),0,LEN(E40)) | J40: 5 | K40: 4 | L40: 4 | M40: =IF(COUNT(J40:L40)<3,"",SUM(J40:L40)) | N40: =IF(B40="","",IF(COUNTIF(G40:I40,"×")>0,"✕ 足切り",IF(COUNTA(G40:I40)<3,"未チェック","◎ 通過"))) | O40: =IF(OR(M40="",N40="✕ 足切り"),"",COUNTIFS($N$40:$N$51,"<>✕ 足切り",$M$40:$M$51,">"&M40)+1)
A41: 2 | B41: 「30代」の大きな文字と、本人の顔 | C41: 新奇性型 | D41: 大きな数字／顔 | E41: 30代 | F41: =IF(OR(E41="",E41="なし"),0,LEN(E41)) | J41: 4 | K41: 5 | L41: 4 | M41: =IF(COUNT(J41:L41)<3,"",SUM(J41:L41)) | N41: =IF(B41="","",IF(COUNTIF(G41:I41,"×")>0,"✕ 足切り",IF(COUNTA(G41:I41)<3,"未チェック","◎ 通過"))) | O41: =IF(OR(M41="",N41="✕ 足切り"),"",COUNTIFS($N$40:$N$51,"<>✕ 足切り",$M$40:$M$51,">"&M41)+1)
A42: 3 | B42: 20代の集団と本人を左右に分けた対比 | C42: 変身型 | D42: 対比／人物 | E42: 20代と30代 | F42: =IF(OR(E42="",E42="なし"),0,LEN(E42)) | J42: 4 | K42: 4 | L42: 4 | M42: =IF(COUNT(J42:L42)<3,"",SUM(J42:L42)) | N42: =IF(B42="","",IF(COUNTIF(G42:I42,"×")>0,"✕ 足切り",IF(COUNTA(G42:I42)<3,"未チェック","◎ 通過"))) | O42: =IF(OR(M42="",N42="✕ 足切り"),"",COUNTIFS($N$40:$N$51,"<>✕ 足切り",$M$40:$M$51,">"&M42)+1)
A43: 4 | B43: パスポートと本人の顔、上に「6年」 | C43: ストーリー型 | D43: 小物／数字 | E43: 6年 | F43: =IF(OR(E43="",E43="なし"),0,LEN(E43)) | J43: 4 | K43: 4 | L43: 4 | M43: =IF(COUNT(J43:L43)<3,"",SUM(J43:L43)) | N43: =IF(B43="","",IF(COUNTIF(G43:I43,"×")>0,"✕ 足切り",IF(COUNTA(G43:I43)<3,"未チェック","◎ 通過"))) | O43: =IF(OR(M43="",N43="✕ 足切り"),"",COUNTIFS($N$40:$N$51,"<>✕ 足切り",$M$40:$M$51,">"&M43)+1)
A44: 5 | B44: 30代の本人が笑っている、明るい背景 | C44: 結果型 | D44: 顔（感情） | E44: 正解だった | F44: =IF(OR(E44="",E44="なし"),0,LEN(E44)) | J44: 5 | K44: 4 | L44: 4 | M44: =IF(COUNT(J44:L44)<3,"",SUM(J44:L44)) | N44: =IF(B44="","",IF(COUNTIF(G44:I44,"×")>0,"✕ 足切り",IF(COUNTA(G44:I44)<3,"未チェック","◎ 通過"))) | O44: =IF(OR(M44="",N44="✕ 足切り"),"",COUNTIFS($N$40:$N$51,"<>✕ 足切り",$M$40:$M$51,">"&M44)+1)
A45: 6 | B45: 迷っている後ろ姿、暗い廊下 | C45: ストーリー型 | D45: 後ろ姿 | E45: 迷ってる？ | F45: =IF(OR(E45="",E45="なし"),0,LEN(E45)) | J45: 4 | K45: 4 | L45: 4 | M45: =IF(COUNT(J45:L45)<3,"",SUM(J45:L45)) | N45: =IF(B45="","",IF(COUNTIF(G45:I45,"×")>0,"✕ 足切り",IF(COUNTA(G45:I45)<3,"未チェック","◎ 通過"))) | O45: =IF(OR(M45="",N45="✕ 足切り"),"",COUNTIFS($N$40:$N$51,"<>✕ 足切り",$M$40:$M$51,">"&M45)+1)
A46: 7 | B46: 階段を上っていく人たちと、立ち止まる本人 | C46: ストーリー型 | D46: 動き／人物 | E46: 焦り | F46: =IF(OR(E46="",E46="なし"),0,LEN(E46)) | J46: 3 | K46: 3 | L46: 4 | M46: =IF(COUNT(J46:L46)<3,"",SUM(J46:L46)) | N46: =IF(B46="","",IF(COUNTIF(G46:I46,"×")>0,"✕ 足切り",IF(COUNTA(G46:I46)<3,"未チェック","◎ 通過"))) | O46: =IF(OR(M46="",N46="✕ 足切り"),"",COUNTIFS($N$40:$N$51,"<>✕ 足切り",$M$40:$M$51,">"&M46)+1)
A47: 8 | B47: 本人が手で「遅くない」と示しているアップ | C47: 瞬間型 | D47: 顔／手 | E47: 遅くない | F47: =IF(OR(E47="",E47="なし"),0,LEN(E47)) | J47: 5 | K47: 5 | L47: 3 | M47: =IF(COUNT(J47:L47)<3,"",SUM(J47:L47)) | N47: =IF(B47="","",IF(COUNTIF(G47:I47,"×")>0,"✕ 足切り",IF(COUNTA(G47:I47)<3,"未チェック","◎ 通過"))) | O47: =IF(OR(M47="",N47="✕ 足切り"),"",COUNTIFS($N$40:$N$51,"<>✕ 足切り",$M$40:$M$51,">"&M47)+1)
A48: 9 | B48: 鏡の前に立つ本人（以前と今の対比） | C48: 変身型 | D48: 人物／鏡 | E48: 変わった | F48: =IF(OR(E48="",E48="なし"),0,LEN(E48)) | J48: 4 | K48: 4 | L48: 4 | M48: =IF(COUNT(J48:L48)<3,"",SUM(J48:L48)) | N48: =IF(B48="","",IF(COUNTIF(G48:I48,"×")>0,"✕ 足切り",IF(COUNTA(G48:I48)<3,"未チェック","◎ 通過"))) | O48: =IF(OR(M48="",N48="✕ 足切り"),"",COUNTIFS($N$40:$N$51,"<>✕ 足切り",$M$40:$M$51,">"&M48)+1)
A49: 10 | B49: カレンダーと本人の顔を並べる | C49: ストーリー型 | D49: 小物／顔 | E49: 30代 | F49: =IF(OR(E49="",E49="なし"),0,LEN(E49)) | J49: 4 | K49: 4 | L49: 3 | M49: =IF(COUNT(J49:L49)<3,"",SUM(J49:L49)) | N49: =IF(B49="","",IF(COUNTIF(G49:I49,"×")>0,"✕ 足切り",IF(COUNTA(G49:I49)<3,"未チェック","◎ 通過"))) | O49: =IF(OR(M49="",N49="✕ 足切り"),"",COUNTIFS($N$40:$N$51,"<>✕ 足切り",$M$40:$M$51,">"&M49)+1)
A50: 11 | B50: ボーディングパスと本人の写真 | C50: 結果型 | D50: 小物（証拠）／顔 | E50: 行ってきた | F50: =IF(OR(E50="",E50="なし"),0,LEN(E50)) | J50: 5 | K50: 4 | L50: 4 | M50: =IF(COUNT(J50:L50)<3,"",SUM(J50:L50)) | N50: =IF(B50="","",IF(COUNTIF(G50:I50,"×")>0,"✕ 足切り",IF(COUNTA(G50:I50)<3,"未チェック","◎ 通過"))) | O50: =IF(OR(M50="",N50="✕ 足切り"),"",COUNTIFS($N$40:$N$51,"<>✕ 足切り",$M$40:$M$51,">"&M50)+1)
...

Sheet ③ 3週間で伸びる人と伸びない人の練習の違い
A1: タイトル・サムネ決定シート｜③ 3週間で伸びる人と伸びない人の練習の違い
A2: 手順：❶タイトル足切り（○/×）→ ❷タイトル採点（1〜5）→ ❸サムネ足切り → ❹サムネ採点 → ❺上位からA/B/Cの組み合わせを作る → ❻1組だけ「公開用」にする。黄色セルだけ入力、他は自動。
A4: 動画のテーマ | C4: IELTSスピーキング｜3週間で伸びる人と伸びない人の練習の違い
A5: 好奇心の型 | C5: 対立（比べて戦わせる）＋結果型
A6: 伏せる情報（答え） | C6: 伸びた人が具体的にやめた練習／伸びなかった人がつまずいた点
A7: 借りる要素（アウトライヤー） | C7: Nepal BBC「BAND 6.0 vs 7.5」6.9x／11,926の比較提示 ＋ ORIENT ACADEMY 58x／76,246の模試型 → 借りるのは1つ：同じ条件の2人を並べる構図
A8: ストッパー（1〜2個） | C8: 大きな数字（3週間）／対比（分割・矢印）／感情（焦り）
A10: ■ 決定（自動）：下の組み合わせで「公開用」を選んだものが表示されます
A11: 公開するタイトル | C11: =IFERROR(INDEX($B$56:$B$58,MATCH("公開用",$L$56:$L$58,0)),"未決定（組み合わせ表で「公開用」を選んでください）")
A12: 公開するサムネ | C12: =IFERROR(INDEX($D$56:$D$58,MATCH("公開用",$L$56:$L$58,0)),"未決定")
A13: 差し替え用 | C13: =COUNTIF($L$56:$L$58,"差し替え用")&" 組"
A14: ■ タイトル案（20案） 足切り：1つでも×なら除外 ／ 採点：1〜5（5が最高）
A15: No | B15: タイトル案 | C15: 字数 | D15: スマホで見える前半30字 | E15: ①中身と 一致 | F15: ②答えを 伏せる | G15: ③30字で 伝わる | H15: 好奇心 | I15: 強い言葉 | J15: 分かり やすさ | K15: サムネと 重複しない | L15: 合計 /20 | M15: 判定 | N15: 順位 | O15: 最終判断 | P15: メモ
A16: 1 | B16: 3週間で伸びた人と伸びなかった人、練習の何が違ったか | C16: =IF(B16="","",LEN(B16)) | D16: =IF(B16="","",LEFT(B16,30)) | H16: 5 | I16: 4 | J16: 5 | K16: 4 | L16: =IF(COUNT(H16:K16)<4,"",SUM(H16:K16)) | M16: =IF(B16="","",IF(COUNTIF(E16:G16,"×")>0,"✕ 足切り",IF(COUNTA(E16:G16)<3,"未チェック","◎ 通過"))) | N16: =IF(OR(L16="",M16="✕ 足切り"),"",COUNTIFS($M$16:$M$35,"<>✕ 足切り",$L$16:$L$35,">"&L16)+1)
A17: 2 | B17: 同じ3週間でも、スコアが上がる人と上がらない人の差 | C17: =IF(B17="","",LEN(B17)) | D17: =IF(B17="","",LEFT(B17,30)) | H17: 5 | I17: 4 | J17: 5 | K17: 4 | L17: =IF(COUNT(H17:K17)<4,"",SUM(H17:K17)) | M17: =IF(B17="","",IF(COUNTIF(E17:G17,"×")>0,"✕ 足切り",IF(COUNTA(E17:G17)<3,"未チェック","◎ 通過"))) | N17: =IF(OR(L17="",M17="✕ 足切り"),"",COUNTIFS($M$16:$M$35,"<>✕ 足切り",$L$16:$L$35,">"&L17)+1)
A18: 3 | B18: 3週間で6.0→6.5を取った人が、やめた練習 | C18: =IF(B18="","",LEN(B18)) | D18: =IF(B18="","",LEFT(B18,30)) | H18: 5 | I18: 5 | J18: 5 | K18: 4 | L18: =IF(COUNT(H18:K18)<4,"",SUM(H18:K18)) | M18: =IF(B18="","",IF(COUNTIF(E18:G18,"×")>0,"✕ 足切り",IF(COUNTA(E18:G18)<3,"未チェック","◎ 通過"))) | N18: =IF(OR(L18="",M18="✕ 足切り"),"",COUNTIFS($M$16:$M$35,"<>✕ 足切り",$L$16:$L$35,">"&L18)+1)
A19: 4 | B19: 伸びる人は3週間で何を変えたのか。受講生を比べて分かったこと | C19: =IF(B19="","",LEN(B19)) | D19: =IF(B19="","",LEFT(B19,30)) | H19: 4 | I19: 3 | J19: 4 | K19: 4 | L19: =IF(COUNT(H19:K19)<4,"",SUM(H19:K19)) | M19: =IF(B19="","",IF(COUNTIF(E19:G19,"×")>0,"✕ 足切り",IF(COUNTA(E19:G19)<3,"未チェック","◎ 通過"))) | N19: =IF(OR(L19="",M19="✕ 足切り"),"",COUNTIFS($M$16:$M$35,"<>✕ 足切り",$L$16:$L$35,">"&L19)+1)
A20: 5 | B20: 3週間で結果を出す人と出せない人、分かれ目はここでした | C20: =IF(B20="","",LEN(B20)) | D20: =IF(B20="","",LEFT(B20,30)) | H20: 5 | I20: 4 | J20: 5 | K20: 4 | L20: =IF(COUNT(H20:K20)<4,"",SUM(H20:K20)) | M20: =IF(B20="","",IF(COUNTIF(E20:G20,"×")>0,"✕ 足切り",IF(COUNTA(E20:G20)<3,"未チェック","◎ 通過"))) | N20: =IF(OR(L20="",M20="✕ 足切り"),"",COUNTIFS($M$16:$M$35,"<>✕ 足切り",$L$16:$L$35,">"&L20)+1)
A21: 6 | B21: 同じ教材を使っても伸びる人と伸びない人がいる理由 | C21: =IF(B21="","",LEN(B21)) | D21: =IF(B21="","",LEFT(B21,30)) | H21: 5 | I21: 4 | J21: 5 | K21: 5 | L21: =IF(COUNT(H21:K21)<4,"",SUM(H21:K21)) | M21: =IF(B21="","",IF(COUNTIF(E21:G21,"×")>0,"✕ 足切り",IF(COUNTA(E21:G21)<3,"未チェック","◎ 通過"))) | N21: =IF(OR(L21="",M21="✕ 足切り"),"",COUNTIFS($M$16:$M$35,"<>✕ 足切り",$L$16:$L$35,">"&L21)+1)
A22: 7 | B22: 3週間で0.5上げた人の練習メニュー、全部公開します | C22: =IF(B22="","",LEN(B22)) | D22: =IF(B22="","",LEFT(B22,30)) | H22: 4 | I22: 3 | J22: 4 | K22: 3 | L22: =IF(COUNT(H22:K22)<4,"",SUM(H22:K22)) | M22: =IF(B22="","",IF(COUNTIF(E22:G22,"×")>0,"✕ 足切り",IF(COUNTA(E22:G22)<3,"未チェック","◎ 通過"))) | N22: =IF(OR(L22="",M22="✕ 足切り"),"",COUNTIFS($M$16:$M$35,"<>✕ 足切り",$L$16:$L$35,">"&L22)+1)
A23: 8 | B23: 伸びない人は3週間、何をしていたのか | C23: =IF(B23="","",LEN(B23)) | D23: =IF(B23="","",LEFT(B23,30)) | H23: 5 | I23: 5 | J23: 5 | K23: 5 | L23: =IF(COUNT(H23:K23)<4,"",SUM(H23:K23)) | M23: =IF(B23="","",IF(COUNTIF(E23:G23,"×")>0,"✕ 足切り",IF(COUNTA(E23:G23)<3,"未チェック","◎ 通過"))) | N23: =IF(OR(L23="",M23="✕ 足切り"),"",COUNTIFS($M$16:$M$35,"<>✕ 足切り",$L$16:$L$35,">"&L23)+1)
A24: 9 | B24: 短期間でスコアを上げた人だけがやっていた3つのこと | C24: =IF(B24="","",LEN(B24)) | D24: =IF(B24="","",LEFT(B24,30)) | H24: 4 | I24: 3 | J24: 4 | K24: 5 | L24: =IF(COUNT(H24:K24)<4,"",SUM(H24:K24)) | M24: =IF(B24="","",IF(COUNTIF(E24:G24,"×")>0,"✕ 足切り",IF(COUNTA(E24:G24)<3,"未チェック","◎ 通過"))) | N24: =IF(OR(L24="",M24="✕ 足切り"),"",COUNTIFS($M$16:$M$35,"<>✕ 足切り",$L$16:$L$35,">"&L24)+1)
A25: 10 | B25: 3週間で結果を変えた人と変えられなかった人の差 | C25: =IF(B25="","",LEN(B25)) | D25: =IF(B25="","",LEFT(B25,30)) | H25: 4 | I25: 4 | J25: 5 | K25: 4 | L25: =IF(COUNT(H25:K25)<4,"",SUM(H25:K25)) | M25: =IF(B25="","",IF(COUNTIF(E25:G25,"×")>0,"✕ 足切り",IF(COUNTA(E25:G25)<3,"未チェック","◎ 通過"))) | N25: =IF(OR(L25="",M25="✕ 足切り"),"",COUNTIFS($M$16:$M$35,"<>✕ 足切り",$L$16:$L$35,">"&L25)+1)
A26: 11 | B26: 同じ期間・同じ教材。それでも差がついた理由を話します | C26: =IF(B26="","",LEN(B26)) | D26: =IF(B26="","",LEFT(B26,30)) | H26: 4 | I26: 3 | J26: 5 | K26: 4 | L26: =IF(COUNT(H26:K26)<4,"",SUM(H26:K26)) | M26: =IF(B26="","",IF(COUNTIF(E26:G26,"×")>0,"✕ 足切り",IF(COUNTA(E26:G26)<3,"未チェック","◎ 通過"))) | N26: =IF(OR(L26="",M26="✕ 足切り"),"",COUNTIFS($M$16:$M$35,"<>✕ 足切り",$L$16:$L$35,">"&L26)+1)
A27: 12 | B27: 3週間でスコアが動く人の練習は、ここが違っていた | C27: =IF(B27="","",LEN(B27)) | D27: =IF(B27="","",LEFT(B27,30)) | H27: 4 | I27: 3 | J27: 4 | K27: 4 | L27: =IF(COUNT(H27:K27)<4,"",SUM(H27:K27)) | M27: =IF(B27="","",IF(COUNTIF(E27:G27,"×")>0,"✕ 足切り",IF(COUNTA(E27:G27)<3,"未チェック","◎ 通過"))) | N27: =IF(OR(L27="",M27="✕ 足切り"),"",COUNTIFS($M$16:$M$35,"<>✕ 足切り",$L$16:$L$35,">"&L27)+1)
... A35: 20 | B35: 3週間で伸びなかった人は、ここでつまずいていました | C35: =IF(B35="","",LEN(B35)) | D35: =IF(B35="","",LEFT(B35,30)) | H35: 5 | I35: 4 | J35: 5 | K35: 5 | L35: =IF(COUNT(H35:K35)<4,"",SUM(H35:K35)) | M35: =IF(B35="","",IF(COUNTIF(E35:G35,"×")>0,"✕ 足切り",IF(COUNTA(E35:G35)<3,"未チェック","◎ 通過"))) | N35: =IF(OR(L35="",M35="✕ 足切り"),"",COUNTIFS($M$16:$M$35,"<>✕ 足切り",$L$16:$L$35,">"&L35)+1)
A36: ※字数が40字を超えると赤字（長すぎの目安）。順位は足切りされていない案の中での順位（同点は同順位）。上位3位は紫。
A38: ■ サムネ下書き（12案） 足切り：1つでも×なら除外 ／ 採点：1〜5
A39: No | B39: コンセプト（何が映っている？） | C39: 型 | D39: 主役／ストッパー | E39: 文字 | F39: 字数 | G39: ①縮小でも 読める | H39: ②主役は 1つ | I39: ③制作 できる | J39: 好奇心 | K39: 2秒で 伝わる | L39: 目立つ | M39: 合計 /15 | N39: 判定 | O39: 順位 | P39: 最終判断
A40: 1 | B40: 左に伸びた受講生、右に伸びなかった受講生、間に矢印 | C40: 変身型 | D40: 2人／矢印 | E40: 差 | F40: =IF(OR(E40="",E40="なし"),0,LEN(E40)) | J40: 4 | K40: 5 | L40: 4 | M40: =IF(COUNT(J40:L40)<3,"",SUM(J40:L40)) | N40: =IF(B40="","",IF(COUNTIF(G40:I40,"×")>0,"✕ 足切り",IF(COUNTA(G40:I40)<3,"未チェック","◎ 通過"))) | O40: =IF(OR(M40="",N40="✕ 足切り"),"",COUNTIFS($N$40:$N$51,"<>✕ 足切り",$M$40:$M$51,">"&M40)+1)
A41: 2 | B41: 3週間のカレンダーとスコアの推移グラフ | C41: 結果型 | D41: グラフ | E41: 3週間 | F41: =IF(OR(E41="",E41="なし"),0,LEN(E41)) | J41: 5 | K41: 5 | L41: 4 | M41: =IF(COUNT(J41:L41)<3,"",SUM(J41:L41)) | N41: =IF(B41="","",IF(COUNTIF(G41:I41,"×")>0,"✕ 足切り",IF(COUNTA(G41:I41)<3,"未チェック","◎ 通過"))) | O41: =IF(OR(M41="",N41="✕ 足切り"),"",COUNTIFS($N$40:$N$51,"<>✕ 足切り",$M$40:$M$51,">"&M41)+1)
A42: 3 | B42: 2人の机の上を並べる（教材の量が違う） | C42: 新奇性型 | D42: 机／教材 | E42: 同じ教材 | F42: =IF(OR(E42="",E42="なし"),0,LEN(E42)) | J42: 4 | K42: 4 | L42: 4 | M42: =IF(COUNT(J42:L42)<3,"",SUM(J42:L42)) | N42: =IF(B42="","",IF(COUNTIF(G42:I42,"×")>0,"✕ 足切り",IF(COUNTA(G42:I42)<3,"未チェック","◎ 通過"))) | O42: =IF(OR(M42="",N42="✕ 足切り"),"",COUNTIFS($N$40:$N$51,"<>✕ 足切り",$M$40:$M$51,">"&M42)+1)
A43: 4 | B43: 本人が2人の答案を指している | C43: ストーリー型 | D43: 人物の指／答案 | E43: ここが違う | F43: =IF(OR(E43="",E43="なし"),0,LEN(E43)) | J43: 4 | K43: 5 | L43: 4 | M43: =IF(COUNT(J43:L43)<3,"",SUM(J43:L43)) | N43: =IF(B43="","",IF(COUNTIF(G43:I43,"×")>0,"✕ 足切り",IF(COUNTA(G43:I43)<3,"未チェック","◎ 通過"))) | O43: =IF(OR(M43="",N43="✕ 足切り"),"",COUNTIFS($N$40:$N$51,"<>✕ 足切り",$M$40:$M$51,">"&M43)+1)
A44: 5 | B44: 「6.0」と「6.5」の大きな文字、間に3週間 | C44: 結果型 | D44: 大きな数字 | E44: 3週間 | F44: =IF(OR(E44="",E44="なし"),0,LEN(E44)) | J44: 5 | K44: 5 | L44: 4 | M44: =IF(COUNT(J44:L44)<3,"",SUM(J44:L44)) | N44: =IF(B44="","",IF(COUNTIF(G44:I44,"×")>0,"✕ 足切り",IF(COUNTA(G44:I44)<3,"未チェック","◎ 通過"))) | O44: =IF(OR(M44="",N44="✕ 足切り"),"",COUNTIFS($N$40:$N$51,"<>✕ 足切り",$M$40:$M$51,">"&M44)+1)
A45: 6 | B45: 時計と焦っている表情 | C45: 瞬間型 | D45: 時計／顔 | E45: 間に合う？ | F45: =IF(OR(E45="",E45="なし"),0,LEN(E45)) | J45: 4 | K45: 4 | L45: 4 | M45: =IF(COUNT(J45:L45)<3,"",SUM(J45:L45)) | N45: =IF(B45="","",IF(COUNTIF(G45:I45,"×")>0,"✕ 足切り",IF(COUNTA(G45:I45)<3,"未チェック","◎ 通過"))) | O45: =IF(OR(M45="",N45="✕ 足切り"),"",COUNTIFS($N$40:$N$51,"<>✕ 足切り",$M$40:$M$51,">"&M45)+1)
A46: 7 | B46: 練習メニュー2枚を並べる（やめたもの／やったもの） | C46: 変身型 | D46: リスト2枚 | E46: やめた練習 | F46: =IF(OR(E46="",E46="なし"),0,LEN(E46)) | J46: 5 | K46: 4 | L46: 4 | M46: =IF(COUNT(J46:L46)<3,"",SUM(J46:L46)) | N46: =IF(B46="","",IF(COUNTIF(G46:I46,"×")>0,"✕ 足切り",IF(COUNTA(G46:I46)<3,"未チェック","◎ 通過"))) | O46: =IF(OR(M46="",N46="✕ 足切り"),"",COUNTIFS($N$40:$N$51,"<>✕ 足切り",$M$40:$M$51,">"&M46)+1)
A47: 8 | B47: 右肩上がりのスコアグラフだけ、背景は暗く | C47: 結果型 | D47: グラフ | E47: なし | F47: =IF(OR(E47="",E47="なし"),0,LEN(E47)) | J47: 5 | K47: 5 | L47: 5 | M47: =IF(COUNT(J47:L47)<3,"",SUM(J47:L47)) | N47: =IF(B47="","",IF(COUNTIF(G47:I47,"×")>0,"✕ 足切り",IF(COUNTA(G47:I47)<3,"未チェック","◎ 通過"))) | O47: =IF(OR(M47="",N47="✕ 足切り"),"",COUNTIFS($N$40:$N$51,"<>✕ 足切り",$M$40:$M$51,">"&M47)+1)
A48: 9 | B48: 消しゴムで消された単語（削った練習の象徴） | C48: 新奇性型 | D48: 小物 | E48: 削った | F48: =IF(OR(E48="",E48="なし"),0,LEN(E48)) | J48: 3 | K48: 4 | L48: 3 | M48: =IF(COUNT(J48:L48)<3,"",SUM(J48:L48)) | N48: =IF(B48="","",IF(COUNTIF(G48:I48,"×")>0,"✕ 足切り",IF(COUNTA(G48:I48)<3,"未チェック","◎ 通過"))) | O48: =IF(OR(M48="",N48="✕ 足切り"),"",COUNTIFS($N$40:$N$51,"<>✕ 足切り",$M$40:$M$51,">"&M48)+1)
A49: 10 | B49: 2人のノートを見開きで対比 | C49: 変身型 | D49: ノート2冊 | E49: ノートの差 | F49: =IF(OR(E49="",E49="なし"),0,LEN(E49)) | J49: 4 | K49: 4 | L49: 4 | M49: =IF(COUNT(J49:L49)<3,"",SUM(J49:L49)) | N49: =IF(B49="","",IF(COUNTIF(G49:I49,"×")>0,"✕ 足切り",IF(COUNTA(G49:I49)<3,"未チェック","◎ 通過"))) | O49: =IF(OR(M49="",N49="✕ 足切り"),"",COUNTIFS($N$40:$N$51,"<>✕ 足切り",$M$40:$M$51,">"&M49)+1)
A50: 11 | B50: 本人が腕時計を気にしている横顔 | C50: 瞬間型 | D50: 顔／時計 | E50: 3週間 | F50: =IF(OR(E50="",E50="なし"),0,LEN(E50)) | J50: 4 | K50: 4 | L50: 4 | M50: =IF(COUNT(J50:L50)<3,"",SUM(J50:L50)) | N50: =IF(B50="","",IF(COUNTIF(G50:I50,"×")>0,"✕ 足切り",IF(COUNTA(G50:I50)<3,"未チェック","◎ 通過"))) | O50: =IF(OR(M50="",N50="✕ 足切り"),"",COUNTIFS($N$40:$N$51,"<>✕ 足切り",$M$40:$M$51,">"&M50)+1)
...
