Workbook

Sheet 使い方
A1: Self Assessment 記帳表（2025年4月〜2026年12月）
A2: 対象：英国のソールトレーダー（個人事業主）。£で収入を受け取り、日本円で外注費を払うケースに対応。
A4: 【タブの構成】
A5: 使い方 | B5: このシート
A6: 為替レート | B6: 月ごとの円→ポンドの換算レート（1£＝何円か）を入力。円で払った外注費などはここのレートで£に自動換算
A7: 年度集計 | B7: 2025/26・2026/27の税年度別に、Tax return（SA103 自営欄）に入れる数字が自動で集まる
A8: 税額シミュレーション | B8: 純利益から所得税・Class 4 NICを概算。会社員としての給与（P60）があればここに入力
A9: 2025-04 〜 2026-12 | B9: 月ごとのタブ（21タブ）。収入と経費を1行1件で記入
A11: 【税年度について】
A12: 英国の税年度 | B12: 4月6日〜翌年4月5日。各行の「税年度」列が日付から自動判定されるので、2026年4月タブに1〜5日と6日以降が混在しても自動で振り分けられる
A13: 2025/26 | B13: 2025/4/6〜2026/4/5。オンライン申告・納付期限：2027年1月31日
A14: 2026/27 | B14: 2026/4/6〜2027/4/5。このファイルは2026年12月まで。申告期限：2028年1月31日
A16: 【記録のルール】
A17: Cash basis（現金主義） | B17: ソールトレーダーの既定方式。収入は入金した日、経費は支払った日で記録（請求書の日付ではない）
A18: 1行＝1件 | B18: 入金・支払い1件につき1行。レシートや明細の写真は日付順に保存しておく
A19: 事業使用率 | B19: 仕事と私用で兼用するもの（スマホ、ネット等）は仕事の割合を入力（例：50%）。空欄なら100%として計算
A20: 領収書・明細 | B20: 提出は不要だが、申告期限から5年間（2025/26分は2032年1月31日まで）保管義務あり。写真・PDFでもOK
A21: 色の意味 | B21: 黄色＝記入するセル／緑＝自動計算（触らない）／2025-04タブの「例」の行は確認後に削除
A23: 【日本円で払った外注費の記入方法】
A24: ① 実際の£額がわかる場合 | B24: Wise・銀行の明細に引き落とされた£額が載っていれば「実際の£額」列に入力（最優先で使われる。送金手数料は別行で「銀行・カード・送金手数料」に記入）
A25: ② わからない場合 | B25: 「通貨」をJPY、「元の金額」に円の金額を入れるだけ。「為替レート」タブのその月のレートで自動換算
A26: レートの出典 | B26: HMRCの月次為替レート（GOV.UK「HMRC exchange rates」で検索。Trade Tariffサイトで月別に公開）か、自分の銀行の実レート。どちらでもよいが、年間を通じて同じ方法を使うこと
A27: カテゴリ | B27: 日本の外注先（デザイナー、翻訳者など）への支払いは「外注費・仕入」。SA103では Costs of goods bought for resale or goods used 欄に入る
A29: 【カテゴリとTax returnの欄の対応】
A30: 外注費・仕入 | B30: Costs of goods bought for resale or goods used（CIS以外の外注費を含む）
A31: 給与・スタッフ費 | B31: Wages, salaries and other staff costs
A32: 交通費・車両費 | B32: Car, van and travel expenses
A33: 家賃・光熱費・保険（自宅オフィス含む） | B33: Rent, rates, power and insurance costs
A34: 修繕・メンテナンス | B34: Repairs and maintenance of property and equipment
A35: 通信・事務・ソフトウェア | B35: Phone, fax, stationery and other office costs
A36: 広告・マーケティング | B36: Advertising and business entertainment costs（接待費は不可）
A37: 借入金の利息 | B37: Interest on bank and other loans
A38: 銀行・カード・送金手数料 | B38: Bank, credit card and other financial charges
A39: 会計・法律・専門家費用 | B39: Accountancy, legal and other professional fees
A40: 研修・教材・書籍 | B40: Other allowable business expenses
A41: その他経費 | B41: Other allowable business expenses
A42: 機材（資本的支出・AIA） | B42: Annual Investment Allowance（Capital allowances欄。経費欄ではない）
A44: 【経費にできないもの】
A45: 私的な支出 | B45: 食事（通常の昼食など）、私用の服、通勤費（自宅→常設の職場）
A46: 罰金・接待 | B46: 駐車違反の罰金、顧客の接待費
...

Sheet 為替レート
A1: 為替レート（1£＝何円か）
A2: 黄色のセルに毎月のレートを入力。HMRCの月次為替レート（GOV.UK「HMRC exchange rates」）を推奨。
A4: 月 | B4: 1£＝円（入力） | C4: 出典・メモ
A5: 2025-04 | B5: 207 | C5: 例：仮の値。HMRCの2025年4月レートに置き換える
A6: 2025-05
A7: 2025-06
A8: 2025-07
A9: 2025-08
A10: 2025-09
A11: 2025-10
A12: 2025-11
A13: 2025-12
A14: 2026-01
A15: 2026-02
A16: 2026-03
A17: 2026-04
... A25: 2026-12

Sheet 年度集計
A1: 年度集計（Tax return用）
A2: すべて自動計算。各月タブの「月まとめ」から集まります。2026/27は2026年12月分までの途中集計です。
A4: 月 | B4: 収入 2025/26 | C4: 経費 2025/26 | D4: 収入 2026/27 | E4: 経費 2026/27
A5: 2025-04 | B5: ='2025-04'!D74 -> 120 | C5: ='2025-04'!D88+'2025-04'!D87 -> 160.92 | D5: ='2025-04'!E74 -> 0 | E5: ='2025-04'!E88+'2025-04'!E87 -> 0
A6: 2025-05 | B6: ='2025-05'!D74 -> 0 | C6: ='2025-05'!D88+'2025-05'!D87 -> 0 | D6: ='2025-05'!E74 -> 0 | E6: ='2025-05'!E88+'2025-05'!E87 -> 0
A7: 2025-06 | B7: ='2025-06'!D74 -> 0 | C7: ='2025-06'!D88+'2025-06'!D87 -> 0 | D7: ='2025-06'!E74 -> 0 | E7: ='2025-06'!E88+'2025-06'!E87 -> 0
A8: 2025-07 | B8: ='2025-07'!D74 -> 0 | C8: ='2025-07'!D88+'2025-07'!D87 -> 0 | D8: ='2025-07'!E74 -> 0 | E8: ='2025-07'!E88+'2025-07'!E87 -> 0
A9: 2025-08 | B9: ='2025-08'!D74 -> 0 | C9: ='2025-08'!D88+'2025-08'!D87 -> 0 | D9: ='2025-08'!E74 -> 0 | E9: ='2025-08'!E88+'2025-08'!E87 -> 0
A10: 2025-09 | B10: ='2025-09'!D74 -> 0 | C10: ='2025-09'!D88+'2025-09'!D87 -> 0 | D10: ='2025-09'!E74 -> 0 | E10: ='2025-09'!E88+'2025-09'!E87 -> 0
A11: 2025-10 | B11: ='2025-10'!D74 -> 0 | C11: ='2025-10'!D88+'2025-10'!D87 -> 0 | D11: ='2025-10'!E74 -> 0 | E11: ='2025-10'!E88+'2025-10'!E87 -> 0
A12: 2025-11 | B12: ='2025-11'!D74 -> 0 | C12: ='2025-11'!D88+'2025-11'!D87 -> 0 | D12: ='2025-11'!E74 -> 0 | E12: ='2025-11'!E88+'2025-11'!E87 -> 0
A13: 2025-12 | B13: ='2025-12'!D74 -> 0 | C13: ='2025-12'!D88+'2025-12'!D87 -> 0 | D13: ='2025-12'!E74 -> 0 | E13: ='2025-12'!E88+'2025-12'!E87 -> 0
A14: 2026-01 | B14: ='2026-01'!D74 -> 0 | C14: ='2026-01'!D88+'2026-01'!D87 -> 0 | D14: ='2026-01'!E74 -> 0 | E14: ='2026-01'!E88+'2026-01'!E87 -> 0
A15: 2026-02 | B15: ='2026-02'!D74 -> 0 | C15: ='2026-02'!D88+'2026-02'!D87 -> 0 | D15: ='2026-02'!E74 -> 0 | E15: ='2026-02'!E88+'2026-02'!E87 -> 0
A16: 2026-03 | B16: ='2026-03'!D74 -> 0 | C16: ='2026-03'!D88+'2026-03'!D87 -> 0 | D16: ='2026-03'!E74 -> 0 | E16: ='2026-03'!E88+'2026-03'!E87 -> 0
A17: 2026-04 | B17: ='2026-04'!D74 -> 0 | C17: ='2026-04'!D88+'2026-04'!D87 -> 0 | D17: ='2026-04'!E74 -> 0 | E17: ='2026-04'!E88+'2026-04'!E87 -> 0
A18: 2026-05 | B18: ='2026-05'!D74 -> 0 | C18: ='2026-05'!D88+'2026-05'!D87 -> 0 | D18: ='2026-05'!E74 -> 0 | E18: ='2026-05'!E88+'2026-05'!E87 -> 0
A19: 2026-06 | B19: ='2026-06'!D74 -> 0 | C19: ='2026-06'!D88+'2026-06'!D87 -> 0 | D19: ='2026-06'!E74 -> 0 | E19: ='2026-06'!E88+'2026-06'!E87 -> 0
A20: 2026-07 | B20: ='2026-07'!D74 -> 0 | C20: ='2026-07'!D88+'2026-07'!D87 -> 0 | D20: ='2026-07'!E74 -> 0 | E20: ='2026-07'!E88+'2026-07'!E87 -> 0
A21: 2026-08 | B21: ='2026-08'!D74 -> 0 | C21: ='2026-08'!D88+'2026-08'!D87 -> 0 | D21: ='2026-08'!E74 -> 0 | E21: ='2026-08'!E88+'2026-08'!E87 -> 0
A22: 2026-09 | B22: ='2026-09'!D74 -> 0 | C22: ='2026-09'!D88+'2026-09'!D87 -> 0 | D22: ='2026-09'!E74 -> 0 | E22: ='2026-09'!E88+'2026-09'!E87 -> 0
A23: 2026-10 | B23: ='2026-10'!D74 -> 0 | C23: ='2026-10'!D88+'2026-10'!D87 -> 0 | D23: ='2026-10'!E74 -> 0 | E23: ='2026-10'!E88+'2026-10'!E87 -> 0
A24: 2026-11 | B24: ='2026-11'!D74 -> 0 | C24: ='2026-11'!D88+'2026-11'!D87 -> 0 | D24: ='2026-11'!E74 -> 0 | E24: ='2026-11'!E88+'2026-11'!E87 -> 0
A25: 2026-12 | B25: ='2026-12'!D74 -> 0 | C25: ='2026-12'!D88+'2026-12'!D87 -> 0 | D25: ='2026-12'!E74 -> 0 | E25: ='2026-12'!E88+'2026-12'!E87 -> 0 | F25: ※経費列は機材（AIA）を含む
A26: 合計 | B26: =SUM(B5:B25) -> 120 | C26: =SUM(C5:C25) -> 160.92 | D26: =SUM(D5:D25) -> 0 | E26: =SUM(E5:E25) -> 0
A28: 【SA103（自営業）に入力する数字】
A29: カテゴリ | B29: 2025/26 | C29: 2026/27 | F29: SA103の欄（英語表記）
A30: Turnover（売上・入金の合計） | B30: ='2025-04'!D74+'2025-05'!D74+'2025-06'!D74+'2025-07'!D74+'2025-08'!D74+'2025-09'!D74+'2025-10'!D74+'2025-11'!D74+'2025-12'!D74+'2026-01'!D74+'2026-02'!D74+'2026-03'!D74+'2026-04'!D74+'2026-05'!D74+'2026-06'!D74+'2026-07'!D74+'2026-08'!D74+'2026-09'!D74+'2026-10'!D74+'2026-11'!D74+'2026-12'!D74 -> 120 | C30: ='2025-04'!E74+'2025-05'!E74+'2025-06'!E74+'2025-07'!E74+'2025-08'!E74+'2025-09'!E74+'2025-10'!E74+'2025-11'!E74+'2025-12'!E74+'2026-01'!E74+'2026-02'!E74+'2026-03'!E74+'2026-04'!E74+'2026-05'!E74+'2026-06'!E74+'2026-07'!E74+'2026-08'!E74+'2026-09'!E74+'2026-10'!E74+'2026-11'!E74+'2026-12'!E74 -> 0 | F30: Your turnover – the takings, fees, sales or money earned by your business
A31: 外注費・仕入 | B31: ='2025-04'!D75+'2025-05'!D75+'2025-06'!D75+'2025-07'!D75+'2025-08'!D75+'2025-09'!D75+'2025-10'!D75+'2025-11'!D75+'2025-12'!D75+'2026-01'!D75+'2026-02'!D75+'2026-03'!D75+'2026-04'!D75+'2026-05'!D75+'2026-06'!D75+'2026-07'!D75+'2026-08'!D75+'2026-09'!D75+'2026-10'!D75+'2026-11'!D75+'2026-12'!D75 -> 144.93 | C31: ='2025-04'!E75+'2025-05'!E75+'2025-06'!E75+'2025-07'!E75+'2025-08'!E75+'2025-09'!E75+'2025-10'!E75+'2025-11'!E75+'2025-12'!E75+'2026-01'!E75+'2026-02'!E75+'2026-03'!E75+'2026-04'!E75+'2026-05'!E75+'2026-06'!E75+'2026-07'!E75+'2026-08'!E75+'2026-09'!E75+'2026-10'!E75+'2026-11'!E75+'2026-12'!E75 -> 0 | F31: Costs of goods bought for resale or goods used（CIS以外の外注費を含む）
A32: 給与・スタッフ費 | B32: ='2025-04'!D76+'2025-05'!D76+'2025-06'!D76+'2025-07'!D76+'2025-08'!D76+'2025-09'!D76+'2025-10'!D76+'2025-11'!D76+'2025-12'!D76+'2026-01'!D76+'2026-02'!D76+'2026-03'!D76+'2026-04'!D76+'2026-05'!D76+'2026-06'!D76+'2026-07'!D76+'2026-08'!D76+'2026-09'!D76+'2026-10'!D76+'2026-11'!D76+'2026-12'!D76 -> 0 | C32: ='2025-04'!E76+'2025-05'!E76+'2025-06'!E76+'2025-07'!E76+'2025-08'!E76+'2025-09'!E76+'2025-10'!E76+'2025-11'!E76+'2025-12'!E76+'2026-01'!E76+'2026-02'!E76+'2026-03'!E76+'2026-04'!E76+'2026-05'!E76+'2026-06'!E76+'2026-07'!E76+'2026-08'!E76+'2026-09'!E76+'2026-10'!E76+'2026-11'!E76+'2026-12'!E76 -> 0 | F32: Wages, salaries and other staff costs
A33: 交通費・車両費 | B33: ='2025-04'!D77+'2025-05'!D77+'2025-06'!D77+'2025-07'!D77+'2025-08'!D77+'2025-09'!D77+'2025-10'!D77+'2025-11'!D77+'2025-12'!D77+'2026-01'!D77+'2026-02'!D77+'2026-03'!D77+'2026-04'!D77+'2026-05'!D77+'2026-06'!D77+'2026-07'!D77+'2026-08'!D77+'2026-09'!D77+'2026-10'!D77+'2026-11'!D77+'2026-12'!D77 -> 0 | C33: ='2025-04'!E77+'2025-05'!E77+'2025-06'!E77+'2025-07'!E77+'2025-08'!E77+'2025-09'!E77+'2025-10'!E77+'2025-11'!E77+'2025-12'!E77+'2026-01'!E77+'2026-02'!E77+'2026-03'!E77+'2026-04'!E77+'2026-05'!E77+'2026-06'!E77+'2026-07'!E77+'2026-08'!E77+'2026-09'!E77+'2026-10'!E77+'2026-11'!E77+'2026-12'!E77 -> 0 | F33: Car, van and travel expenses
A34: 家賃・光熱費・保険（自宅オフィス含む） | B34: ='2025-04'!D78+'2025-05'!D78+'2025-06'!D78+'2025-07'!D78+'2025-08'!D78+'2025-09'!D78+'2025-10'!D78+'2025-11'!D78+'2025-12'!D78+'2026-01'!D78+'2026-02'!D78+'2026-03'!D78+'2026-04'!D78+'2026-05'!D78+'2026-06'!D78+'2026-07'!D78+'2026-08'!D78+'2026-09'!D78+'2026-10'!D78+'2026-11'!D78+'2026-12'!D78 -> 0 | C34: ='2025-04'!E78+'2025-05'!E78+'2025-06'!E78+'2025-07'!E78+'2025-08'!E78+'2025-09'!E78+'2025-10'!E78+'2025-11'!E78+'2025-12'!E78+'2026-01'!E78+'2026-02'!E78+'2026-03'!E78+'2026-04'!E78+'2026-05'!E78+'2026-06'!E78+'2026-07'!E78+'2026-08'!E78+'2026-09'!E78+'2026-10'!E78+'2026-11'!E78+'2026-12'!E78 -> 0 | F34: Rent, rates, power and insurance costs
A35: 修繕・メンテナンス | B35: ='2025-04'!D79+'2025-05'!D79+'2025-06'!D79+'2025-07'!D79+'2025-08'!D79+'2025-09'!D79+'2025-10'!D79+'2025-11'!D79+'2025-12'!D79+'2026-01'!D79+'2026-02'!D79+'2026-03'!D79+'2026-04'!D79+'2026-05'!D79+'2026-06'!D79+'2026-07'!D79+'2026-08'!D79+'2026-09'!D79+'2026-10'!D79+'2026-11'!D79+'2026-12'!D79 -> 0 | C35: ='2025-04'!E79+'2025-05'!E79+'2025-06'!E79+'2025-07'!E79+'2025-08'!E79+'2025-09'!E79+'2025-10'!E79+'2025-11'!E79+'2025-12'!E79+'2026-01'!E79+'2026-02'!E79+'2026-03'!E79+'2026-04'!E79+'2026-05'!E79+'2026-06'!E79+'2026-07'!E79+'2026-08'!E79+'2026-09'!E79+'2026-10'!E79+'2026-11'!E79+'2026-12'!E79 -> 0 | F35: Repairs and maintenance of property and equipment
A36: 通信・事務・ソフトウェア | B36: ='2025-04'!D80+'2025-05'!D80+'2025-06'!D80+'2025-07'!D80+'2025-08'!D80+'2025-09'!D80+'2025-10'!D80+'2025-11'!D80+'2025-12'!D80+'2026-01'!D80+'2026-02'!D80+'2026-03'!D80+'2026-04'!D80+'2026-05'!D80+'2026-06'!D80+'2026-07'!D80+'2026-08'!D80+'2026-09'!D80+'2026-10'!D80+'2026-11'!D80+'2026-12'!D80 -> 15.99 | C36: ='2025-04'!E80+'2025-05'!E80+'2025-06'!E80+'2025-07'!E80+'2025-08'!E80+'2025-09'!E80+'2025-10'!E80+'2025-11'!E80+'2025-12'!E80+'2026-01'!E80+'2026-02'!E80+'2026-03'!E80+'2026-04'!E80+'2026-05'!E80+'2026-06'!E80+'2026-07'!E80+'2026-08'!E80+'2026-09'!E80+'2026-10'!E80+'2026-11'!E80+'2026-12'!E80 -> 0 | F36: Phone, fax, stationery and other office costs
A37: 広告・マーケティング | B37: ='2025-04'!D81+'2025-05'!D81+'2025-06'!D81+'2025-07'!D81+'2025-08'!D81+'2025-09'!D81+'2025-10'!D81+'2025-11'!D81+'2025-12'!D81+'2026-01'!D81+'2026-02'!D81+'2026-03'!D81+'2026-04'!D81+'2026-05'!D81+'2026-06'!D81+'2026-07'!D81+'2026-08'!D81+'2026-09'!D81+'2026-10'!D81+'2026-11'!D81+'2026-12'!D81 -> 0 | C37: ='2025-04'!E81+'2025-05'!E81+'2025-06'!E81+'2025-07'!E81+'2025-08'!E81+'2025-09'!E81+'2025-10'!E81+'2025-11'!E81+'2025-12'!E81+'2026-01'!E81+'2026-02'!E81+'2026-03'!E81+'2026-04'!E81+'2026-05'!E81+'2026-06'!E81+'2026-07'!E81+'2026-08'!E81+'2026-09'!E81+'2026-10'!E81+'2026-11'!E81+'2026-12'!E81 -> 0 | F37: Advertising and business entertainment costs（接待費は不可）
A38: 借入金の利息 | B38: ='2025-04'!D82+'2025-05'!D82+'2025-06'!D82+'2025-07'!D82+'2025-08'!D82+'2025-09'!D82+'2025-10'!D82+'2025-11'!D82+'2025-12'!D82+'2026-01'!D82+'2026-02'!D82+'2026-03'!D82+'2026-04'!D82+'2026-05'!D82+'2026-06'!D82+'2026-07'!D82+'2026-08'!D82+'2026-09'!D82+'2026-10'!D82+'2026-11'!D82+'2026-12'!D82 -> 0 | C38: ='2025-04'!E82+'2025-05'!E82+'2025-06'!E82+'2025-07'!E82+'2025-08'!E82+'2025-09'!E82+'2025-10'!E82+'2025-11'!E82+'2025-12'!E82+'2026-01'!E82+'2026-02'!E82+'2026-03'!E82+'2026-04'!E82+'2026-05'!E82+'2026-06'!E82+'2026-07'!E82+'2026-08'!E82+'2026-09'!E82+'2026-10'!E82+'2026-11'!E82+'2026-12'!E82 -> 0 | F38: Interest on bank and other loans
A39: 銀行・カード・送金手数料 | B39: ='2025-04'!D83+'2025-05'!D83+'2025-06'!D83+'2025-07'!D83+'2025-08'!D83+'2025-09'!D83+'2025-10'!D83+'2025-11'!D83+'2025-12'!D83+'2026-01'!D83+'2026-02'!D83+'2026-03'!D83+'2026-04'!D83+'2026-05'!D83+'2026-06'!D83+'2026-07'!D83+'2026-08'!D83+'2026-09'!D83+'2026-10'!D83+'2026-11'!D83+'2026-12'!D83 -> 0 | C39: ='2025-04'!E83+'2025-05'!E83+'2025-06'!E83+'2025-07'!E83+'2025-08'!E83+'2025-09'!E83+'2025-10'!E83+'2025-11'!E83+'2025-12'!E83+'2026-01'!E83+'2026-02'!E83+'2026-03'!E83+'2026-04'!E83+'2026-05'!E83+'2026-06'!E83+'2026-07'!E83+'2026-08'!E83+'2026-09'!E83+'2026-10'!E83+'2026-11'!E83+'2026-12'!E83 -> 0 | F39: Bank, credit card and other financial charges
A40: 会計・法律・専門家費用 | B40: ='2025-04'!D84+'2025-05'!D84+'2025-06'!D84+'2025-07'!D84+'2025-08'!D84+'2025-09'!D84+'2025-10'!D84+'2025-11'!D84+'2025-12'!D84+'2026-01'!D84+'2026-02'!D84+'2026-03'!D84+'2026-04'!D84+'2026-05'!D84+'2026-06'!D84+'2026-07'!D84+'2026-08'!D84+'2026-09'!D84+'2026-10'!D84+'2026-11'!D84+'2026-12'!D84 -> 0 | C40: ='2025-04'!E84+'2025-05'!E84+'2025-06'!E84+'2025-07'!E84+'2025-08'!E84+'2025-09'!E84+'2025-10'!E84+'2025-11'!E84+'2025-12'!E84+'2026-01'!E84+'2026-02'!E84+'2026-03'!E84+'2026-04'!E84+'2026-05'!E84+'2026-06'!E84+'2026-07'!E84+'2026-08'!E84+'2026-09'!E84+'2026-10'!E84+'2026-11'!E84+'2026-12'!E84 -> 0 | F40: Accountancy, legal and other professional fees
A41: 研修・教材・書籍 | B41: ='2025-04'!D85+'2025-05'!D85+'2025-06'!D85+'2025-07'!D85+'2025-08'!D85+'2025-09'!D85+'2025-10'!D85+'2025-11'!D85+'2025-12'!D85+'2026-01'!D85+'2026-02'!D85+'2026-03'!D85+'2026-04'!D85+'2026-05'!D85+'2026-06'!D85+'2026-07'!D85+'2026-08'!D85+'2026-09'!D85+'2026-10'!D85+'2026-11'!D85+'2026-12'!D85 -> 0 | C41: ='2025-04'!E85+'2025-05'!E85+'2025-06'!E85+'2025-07'!E85+'2025-08'!E85+'2025-09'!E85+'2025-10'!E85+'2025-11'!E85+'2025-12'!E85+'2026-01'!E85+'2026-02'!E85+'2026-03'!E85+'2026-04'!E85+'2026-05'!E85+'2026-06'!E85+'2026-07'!E85+'2026-08'!E85+'2026-09'!E85+'2026-10'!E85+'2026-11'!E85+'2026-12'!E85 -> 0 | F41: Other allowable business expenses
A42: その他経費 | B42: ='2025-04'!D86+'2025-05'!D86+'2025-06'!D86+'2025-07'!D86+'2025-08'!D86+'2025-09'!D86+'2025-10'!D86+'2025-11'!D86+'2025-12'!D86+'2026-01'!D86+'2026-02'!D86+'2026-03'!D86+'2026-04'!D86+'2026-05'!D86+'2026-06'!D86+'2026-07'!D86+'2026-08'!D86+'2026-09'!D86+'2026-10'!D86+'2026-11'!D86+'2026-12'!D86 -> 0 | C42: ='2025-04'!E86+'2025-05'!E86+'2025-06'!E86+'2025-07'!E86+'2025-08'!E86+'2025-09'!E86+'2025-10'!E86+'2025-11'!E86+'2025-12'!E86+'2026-01'!E86+'2026-02'!E86+'2026-03'!E86+'2026-04'!E86+'2026-05'!E86+'2026-06'!E86+'2026-07'!E86+'2026-08'!E86+'2026-09'!E86+'2026-10'!E86+'2026-11'!E86+'2026-12'!E86 -> 0 | F42: Other allowable business expenses
...

Sheet 税額シミュレーション
A1: 税額シミュレーション（イングランド・ウェールズ・北アイルランドの税率／概算）
A3: 項目 | B3: 2025/26 | C3: 2026/27 | D3: 説明
A4: 自営業の純利益 | B4: =年度集計!B45 -> -40.92 | C4: =年度集計!C45 -> 0 | D4: 年度集計タブから自動
A5: 会社員としての給与（P60の Pay） | B5: 0 | C5: 0 | D5: 勤め先からの給与があれば入力。なければ0
A6: 給与から天引き済みの所得税（P60の Tax） | B6: 0 | C6: 0 | D6: PAYEで既に払った税金
A7: その他の課税所得（利子・家賃収入など） | B7: 0 | C7: 0 | D7: なければ0
A8: 所得合計 | B8: =MAX(0,B4)+B5+B7 -> 0 | C8: =MAX(0,C4)+C5+C7 -> 0
A9: Personal Allowance（非課税枠） | B9: =MAX(0,12570-MAX(0,ROUNDDOWN((B8-100000)/2,0))) -> 12570 | C9: =MAX(0,12570-MAX(0,ROUNDDOWN((C8-100000)/2,0))) -> 12570 | D9: £12,570。所得£100,000超で£2ごとに£1減額
A10: 課税所得 | B10: =MAX(0,B8-B9) -> 0 | C10: =MAX(0,C8-C9) -> 0
A11: 所得税 | B11: =ROUND(MIN(B10,37700)*0.2+MAX(0,MIN(B10,125140)-37700)*0.4+MAX(0,B10-125140)*0.45,2) -> 0 | C11: =ROUND(MIN(C10,37700)*0.2+MAX(0,MIN(C10,125140)-37700)*0.4+MAX(0,C10-125140)*0.45,2) -> 0 | D11: 20%（〜£37,700）／40%（〜£125,140）／45%（超過分）
A12: Class 4 NIC（自営業分のみ） | B12: =ROUND(MAX(0,MIN(B4,50270)-12570)*0.06+MAX(0,B4-50270)*0.02,2) -> 0 | C12: =ROUND(MAX(0,MIN(C4,50270)-12570)*0.06+MAX(0,C4-50270)*0.02,2) -> 0 | D12: 利益£12,570〜£50,270に6%、超過分に2%
A13: 税金の合計（概算） | B13: =B11+B12 -> 0 | C13: =C11+C12 -> 0
A14: Self Assessmentで払う額（概算） | B14: =B13-B6 -> 0 | C14: =C13-C6 -> 0 | D14: 合計から天引き済み分を差し引いた額
A15: 中間前払い（Payments on Account）の可能性 | B15: =IF(AND(B14>1000,B6<B13*0.8),"対象の可能性大","おそらく対象外") -> おそらく対象外 | C15: =IF(AND(C14>1000,C6<C13*0.8),"対象の可能性大","おそらく対象外") -> おそらく対象外 | D15: 支払額が£1,000超、かつ天引き分が80%未満だと翌年度の前払いが必要（1月31日と7月31日に半額ずつ）
A17: ※2026/27は2026年12月までの途中データ・同じ税率を仮定。スコットランド在住の場合は所得税率が異なります。
A18: ※Class 2 NICは2024/25から廃止（利益£6,845未満なら任意で納付し年金加入記録を残せる）。
A19: ※学生ローン返済・Gift Aid・個人年金の控除は未反映。正確な税額は申告後にHMRCが計算します。

Sheet 2025-04
A1: 2025年4月 | J1: 今月のレート 1£＝ | L1: =IF(為替レート!$B$5="","未入力",為替レート!$B$5) -> 207
A2: 黄色＝記入／緑＝自動計算。円の支払いは「為替レート」タブのレートで自動換算（実際の£額があればそちらを優先）。
A4: 【収入】仕事の入金（入金した日で記録）
A5: 日付 | B5: 取引先 | C5: 内容 | D5: 入金方法 | E5: 通貨 | F5: 元の金額 | G5: 実際の£額 (分かれば) | H5: 金額(£) 自動 | I5: 請求書No. | J5: 税年度 自動 | N5: メモ
A6: 45775 | B6: Example Ltd（例） | C6: IELTSコーチング 60分×2（例：削除） | D6: 銀行振込 | E6: GBP | F6: 120 | H6: =IF(F6="","",IF(G6<>"",G6,IF(E6="JPY",IF(ISNUMBER($L$1),ROUND(F6/$L$1,2),"レート未入力"),F6))) -> 120 | I6: INV-001 | J6: =IF(A6="","",IF(A6<DATE(2025,4,6),"2024/25",IF(A6<DATE(2026,4,6),"2025/26",IF(A6<DATE(2027,4,6),"2026/27","2027/28")))) -> 2025/26
H7: =IF(F7="","",IF(G7<>"",G7,IF(E7="JPY",IF(ISNUMBER($L$1),ROUND(F7/$L$1,2),"レート未入力"),F7))) | J7: =IF(A7="","",IF(A7<DATE(2025,4,6),"2024/25",IF(A7<DATE(2026,4,6),"2025/26",IF(A7<DATE(2027,4,6),"2026/27","2027/28"))))
H8: =IF(F8="","",IF(G8<>"",G8,IF(E8="JPY",IF(ISNUMBER($L$1),ROUND(F8/$L$1,2),"レート未入力"),F8))) | J8: =IF(A8="","",IF(A8<DATE(2025,4,6),"2024/25",IF(A8<DATE(2026,4,6),"2025/26",IF(A8<DATE(2027,4,6),"2026/27","2027/28"))))
H9: =IF(F9="","",IF(G9<>"",G9,IF(E9="JPY",IF(ISNUMBER($L$1),ROUND(F9/$L$1,2),"レート未入力"),F9))) | J9: =IF(A9="","",IF(A9<DATE(2025,4,6),"2024/25",IF(A9<DATE(2026,4,6),"2025/26",IF(A9<DATE(2027,4,6),"2026/27","2027/28"))))
H10: =IF(F10="","",IF(G10<>"",G10,IF(E10="JPY",IF(ISNUMBER($L$1),ROUND(F10/$L$1,2),"レート未入力"),F10))) | J10: =IF(A10="","",IF(A10<DATE(2025,4,6),"2024/25",IF(A10<DATE(2026,4,6),"2025/26",IF(A10<DATE(2027,4,6),"2026/27","2027/28"))))
H11: =IF(F11="","",IF(G11<>"",G11,IF(E11="JPY",IF(ISNUMBER($L$1),ROUND(F11/$L$1,2),"レート未入力"),F11))) | J11: =IF(A11="","",IF(A11<DATE(2025,4,6),"2024/25",IF(A11<DATE(2026,4,6),"2025/26",IF(A11<DATE(2027,4,6),"2026/27","2027/28"))))
H12: =IF(F12="","",IF(G12<>"",G12,IF(E12="JPY",IF(ISNUMBER($L$1),ROUND(F12/$L$1,2),"レート未入力"),F12))) | J12: =IF(A12="","",IF(A12<DATE(2025,4,6),"2024/25",IF(A12<DATE(2026,4,6),"2025/26",IF(A12<DATE(2027,4,6),"2026/27","2027/28"))))
H13: =IF(F13="","",IF(G13<>"",G13,IF(E13="JPY",IF(ISNUMBER($L$1),ROUND(F13/$L$1,2),"レート未入力"),F13))) | J13: =IF(A13="","",IF(A13<DATE(2025,4,6),"2024/25",IF(A13<DATE(2026,4,6),"2025/26",IF(A13<DATE(2027,4,6),"2026/27","2027/28"))))
H14: =IF(F14="","",IF(G14<>"",G14,IF(E14="JPY",IF(ISNUMBER($L$1),ROUND(F14/$L$1,2),"レート未入力"),F14))) | J14: =IF(A14="","",IF(A14<DATE(2025,4,6),"2024/25",IF(A14<DATE(2026,4,6),"2025/26",IF(A14<DATE(2027,4,6),"2026/27","2027/28"))))
H15: =IF(F15="","",IF(G15<>"",G15,IF(E15="JPY",IF(ISNUMBER($L$1),ROUND(F15/$L$1,2),"レート未入力"),F15))) | J15: =IF(A15="","",IF(A15<DATE(2025,4,6),"2024/25",IF(A15<DATE(2026,4,6),"2025/26",IF(A15<DATE(2027,4,6),"2026/27","2027/28"))))
H16: =IF(F16="","",IF(G16<>"",G16,IF(E16="JPY",IF(ISNUMBER($L$1),ROUND(F16/$L$1,2),"レート未入力"),F16))) | J16: =IF(A16="","",IF(A16<DATE(2025,4,6),"2024/25",IF(A16<DATE(2026,4,6),"2025/26",IF(A16<DATE(2027,4,6),"2026/27","2027/28"))))
H17: =IF(F17="","",IF(G17<>"",G17,IF(E17="JPY",IF(ISNUMBER($L$1),ROUND(F17/$L$1,2),"レート未入力"),F17))) | J17: =IF(A17="","",IF(A17<DATE(2025,4,6),"2024/25",IF(A17<DATE(2026,4,6),"2025/26",IF(A17<DATE(2027,4,6),"2026/27","2027/28"))))
H18: =IF(F18="","",IF(G18<>"",G18,IF(E18="JPY",IF(ISNUMBER($L$1),ROUND(F18/$L$1,2),"レート未入力"),F18))) | J18: =IF(A18="","",IF(A18<DATE(2025,4,6),"2024/25",IF(A18<DATE(2026,4,6),"2025/26",IF(A18<DATE(2027,4,6),"2026/27","2027/28"))))
... H25: =IF(F25="","",IF(G25<>"",G25,IF(E25="JPY",IF(ISNUMBER($L$1),ROUND(F25/$L$1,2),"レート未入力"),F25))) | J25: =IF(A25="","",IF(A25<DATE(2025,4,6),"2024/25",IF(A25<DATE(2026,4,6),"2025/26",IF(A25<DATE(2027,4,6),"2026/27","2027/28"))))
A26: 収入合計 | H26: =SUM(H6:H25) -> 120
A28: 【経費】仕事で支払った費用（支払った日で記録・領収書を保管）
A29: 日付 | B29: 支払先 | C29: 内容 | D29: カテゴリ | E29: 通貨 | F29: 元の金額 | G29: 実際の£額 (分かれば) | H29: £換算額 自動 | I29: 事業使用率 (空欄=100%) | J29: 認定経費(£) 自動 | K29: 領収書 ○ | L29: 税年度 自動 | N29: メモ
A30: 45776 | B30: 山田さん（例） | C30: 教材デザイン外注（例：削除） | D30: 外注費・仕入 | E30: JPY | F30: 30000 | H30: =IF(F30="","",IF(G30<>"",G30,IF(E30="JPY",IF(ISNUMBER($L$1),ROUND(F30/$L$1,2),"レート未入力"),F30))) -> 144.93 | J30: =IF(ISNUMBER(H30),ROUND(H30*IF(I30="",1,I30),2),"") -> 144.93 | K30: ○ | L30: =IF(A30="","",IF(A30<DATE(2025,4,6),"2024/25",IF(A30<DATE(2026,4,6),"2025/26",IF(A30<DATE(2027,4,6),"2026/27","2027/28")))) -> 2025/26
A31: 45777 | B31: Zoom（例） | C31: オンライン授業ツール月額（例：削除） | D31: 通信・事務・ソフトウェア | E31: GBP | F31: 15.99 | H31: =IF(F31="","",IF(G31<>"",G31,IF(E31="JPY",IF(ISNUMBER($L$1),ROUND(F31/$L$1,2),"レート未入力"),F31))) -> 15.99 | J31: =IF(ISNUMBER(H31),ROUND(H31*IF(I31="",1,I31),2),"") -> 15.99 | K31: ○ | L31: =IF(A31="","",IF(A31<DATE(2025,4,6),"2024/25",IF(A31<DATE(2026,4,6),"2025/26",IF(A31<DATE(2027,4,6),"2026/27","2027/28")))) -> 2025/26
H32: =IF(F32="","",IF(G32<>"",G32,IF(E32="JPY",IF(ISNUMBER($L$1),ROUND(F32/$L$1,2),"レート未入力"),F32))) | J32: =IF(ISNUMBER(H32),ROUND(H32*IF(I32="",1,I32),2),"") | L32: =IF(A32="","",IF(A32<DATE(2025,4,6),"2024/25",IF(A32<DATE(2026,4,6),"2025/26",IF(A32<DATE(2027,4,6),"2026/27","2027/28"))))
H33: =IF(F33="","",IF(G33<>"",G33,IF(E33="JPY",IF(ISNUMBER($L$1),ROUND(F33/$L$1,2),"レート未入力"),F33))) | J33: =IF(ISNUMBER(H33),ROUND(H33*IF(I33="",1,I33),2),"") | L33: =IF(A33="","",IF(A33<DATE(2025,4,6),"2024/25",IF(A33<DATE(2026,4,6),"2025/26",IF(A33<DATE(2027,4,6),"2026/27","2027/28"))))
H34: =IF(F34="","",IF(G34<>"",G34,IF(E34="JPY",IF(ISNUMBER($L$1),ROUND(F34/$L$1,2),"レート未入力"),F34))) | J34: =IF(ISNUMBER(H34),ROUND(H34*IF(I34="",1,I34),2),"") | L34: =IF(A34="","",IF(A34<DATE(2025,4,6),"2024/25",IF(A34<DATE(2026,4,6),"2025/26",IF(A34<DATE(2027,4,6),"2026/27","2027/28"))))
H35: =IF(F35="","",IF(G35<>"",G35,IF(E35="JPY",IF(ISNUMBER($L$1),ROUND(F35/$L$1,2),"レート未入力"),F35))) | J35: =IF(ISNUMBER(H35),ROUND(H35*IF(I35="",1,I35),2),"") | L35: =IF(A35="","",IF(A35<DATE(2025,4,6),"2024/25",IF(A35<DATE(2026,4,6),"2025/26",IF(A35<DATE(2027,4,6),"2026/27","2027/28"))))
H36: =IF(F36="","",IF(G36<>"",G36,IF(E36="JPY",IF(ISNUMBER($L$1),ROUND(F36/$L$1,2),"レート未入力"),F36))) | J36: =IF(ISNUMBER(H36),ROUND(H36*IF(I36="",1,I36),2),"") | L36: =IF(A36="","",IF(A36<DATE(2025,4,6),"2024/25",IF(A36<DATE(2026,4,6),"2025/26",IF(A36<DATE(2027,4,6),"2026/27","2027/28"))))
H37: =IF(F37="","",IF(G37<>"",G37,IF(E37="JPY",IF(ISNUMBER($L$1),ROUND(F37/$L$1,2),"レート未入力"),F37))) | J37: =IF(ISNUMBER(H37),ROUND(H37*IF(I37="",1,I37),2),"") | L37: =IF(A37="","",IF(A37<DATE(2025,4,6),"2024/25",IF(A37<DATE(2026,4,6),"2025/26",IF(A37<DATE(2027,4,6),"2026/27","2027/28"))))
H38: =IF(F38="","",IF(G38<>"",G38,IF(E38="JPY",IF(ISNUMBER($L$1),ROUND(F38/$L$1,2),"レート未入力"),F38))) | J38: =IF(ISNUMBER(H38),ROUND(H38*IF(I38="",1,I38),2),"") | L38: =IF(A38="","",IF(A38<DATE(2025,4,6),"2024/25",IF(A38<DATE(2026,4,6),"2025/26",IF(A38<DATE(2027,4,6),"2026/27","2027/28"))))
H39: =IF(F39="","",IF(G39<>"",G39,IF(E39="JPY",IF(ISNUMBER($L$1),ROUND(F39/$L$1,2),"レート未入力"),F39))) | J39: =IF(ISNUMBER(H39),ROUND(H39*IF(I39="",1,I39),2),"") | L39: =IF(A39="","",IF(A39<DATE(2025,4,6),"2024/25",IF(A39<DATE(2026,4,6),"2025/26",IF(A39<DATE(2027,4,6),"2026/27","2027/28"))))
H40: =IF(F40="","",IF(G40<>"",G40,IF(E40="JPY",IF(ISNUMBER($L$1),ROUND(F40/$L$1,2),"レート未入力"),F40))) | J40: =IF(ISNUMBER(H40),ROUND(H40*IF(I40="",1,I40),2),"") | L40: =IF(A40="","",IF(A40<DATE(2025,4,6),"2024/25",IF(A40<DATE(2026,4,6),"2025/26",IF(A40<DATE(2027,4,6),"2026/27","2027/28"))))
H41: =IF(F41="","",IF(G41<>"",G41,IF(E41="JPY",IF(ISNUMBER($L$1),ROUND(F41/$L$1,2),"レート未入力"),F41))) | J41: =IF(ISNUMBER(H41),ROUND(H41*IF(I41="",1,I41),2),"") | L41: =IF(A41="","",IF(A41<DATE(2025,4,6),"2024/25",IF(A41<DATE(2026,4,6),"2025/26",IF(A41<DATE(2027,4,6),"2026/27","2027/28"))))
H42: =IF(F42="","",IF(G42<>"",G42,IF(E42="JPY",IF(ISNUMBER($L$1),ROUND(F42/$L$1,2),"レート未入力"),F42))) | J42: =IF(ISNUMBER(H42),ROUND(H42*IF(I42="",1,I42),2),"") | L42: =IF(A42="","",IF(A42<DATE(2025,4,6),"2024/25",IF(A42<DATE(2026,4,6),"2025/26",IF(A42<DATE(2027,4,6),"2026/27","2027/28"))))
H43: =IF(F43="","",IF(G43<>"",G43,IF(E43="JPY",IF(ISNUMBER($L$1),ROUND(F43/$L$1,2),"レート未入力"),F43))) | J43: =IF(ISNUMBER(H43),ROUND(H43*IF(I43="",1,I43),2),"") | L43: =IF(A43="","",IF(A43<DATE(2025,4,6),"2024/25",IF(A43<DATE(2026,4,6),"2025/26",IF(A43<DATE(2027,4,6),"2026/27","2027/28"))))
... H69: =IF(F69="","",IF(G69<>"",G69,IF(E69="JPY",IF(ISNUMBER($L$1),ROUND(F69/$L$1,2),"レート未入力"),F69))) | J69: =IF(ISNUMBER(H69),ROUND(H69*IF(I69="",1,I69),2),"") | L69: =IF(A69="","",IF(A69<DATE(2025,4,6),"2024/25",IF(A69<DATE(2026,4,6),"2025/26",IF(A69<DATE(2027,4,6),"2026/27","2027/28"))))
A70: 支払合計（按分後・機材含む） | J70: =SUM(J30:J69) -> 160.92
A72: 【月まとめ（税年度別）】自動計算
A73: 項目 | D73: 2025/26 | E73: 2026/27
A74: 収入合計 | D74: =SUMIFS($H$6:$H$25,$J$6:$J$25,"2025/26") -> 120 | E74: =SUMIFS($H$6:$H$25,$J$6:$J$25,"2026/27") -> 0
...

Sheet 2025-05
A1: 2025年5月 | J1: 今月のレート 1£＝ | L1: =IF(為替レート!$B$6="","未入力",為替レート!$B$6) -> 未入力
A2: 黄色＝記入／緑＝自動計算。円の支払いは「為替レート」タブのレートで自動換算（実際の£額があればそちらを優先）。
A4: 【収入】仕事の入金（入金した日で記録）
A5: 日付 | B5: 取引先 | C5: 内容 | D5: 入金方法 | E5: 通貨 | F5: 元の金額 | G5: 実際の£額 (分かれば) | H5: 金額(£) 自動 | I5: 請求書No. | J5: 税年度 自動 | N5: メモ
H6: =IF(F6="","",IF(G6<>"",G6,IF(E6="JPY",IF(ISNUMBER($L$1),ROUND(F6/$L$1,2),"レート未入力"),F6))) | J6: =IF(A6="","",IF(A6<DATE(2025,4,6),"2024/25",IF(A6<DATE(2026,4,6),"2025/26",IF(A6<DATE(2027,4,6),"2026/27","2027/28"))))
H7: =IF(F7="","",IF(G7<>"",G7,IF(E7="JPY",IF(ISNUMBER($L$1),ROUND(F7/$L$1,2),"レート未入力"),F7))) | J7: =IF(A7="","",IF(A7<DATE(2025,4,6),"2024/25",IF(A7<DATE(2026,4,6),"2025/26",IF(A7<DATE(2027,4,6),"2026/27","2027/28"))))
H8: =IF(F8="","",IF(G8<>"",G8,IF(E8="JPY",IF(ISNUMBER($L$1),ROUND(F8/$L$1,2),"レート未入力"),F8))) | J8: =IF(A8="","",IF(A8<DATE(2025,4,6),"2024/25",IF(A8<DATE(2026,4,6),"2025/26",IF(A8<DATE(2027,4,6),"2026/27","2027/28"))))
H9: =IF(F9="","",IF(G9<>"",G9,IF(E9="JPY",IF(ISNUMBER($L$1),ROUND(F9/$L$1,2),"レート未入力"),F9))) | J9: =IF(A9="","",IF(A9<DATE(2025,4,6),"2024/25",IF(A9<DATE(2026,4,6),"2025/26",IF(A9<DATE(2027,4,6),"2026/27","2027/28"))))
H10: =IF(F10="","",IF(G10<>"",G10,IF(E10="JPY",IF(ISNUMBER($L$1),ROUND(F10/$L$1,2),"レート未入力"),F10))) | J10: =IF(A10="","",IF(A10<DATE(2025,4,6),"2024/25",IF(A10<DATE(2026,4,6),"2025/26",IF(A10<DATE(2027,4,6),"2026/27","2027/28"))))
H11: =IF(F11="","",IF(G11<>"",G11,IF(E11="JPY",IF(ISNUMBER($L$1),ROUND(F11/$L$1,2),"レート未入力"),F11))) | J11: =IF(A11="","",IF(A11<DATE(2025,4,6),"2024/25",IF(A11<DATE(2026,4,6),"2025/26",IF(A11<DATE(2027,4,6),"2026/27","2027/28"))))
H12: =IF(F12="","",IF(G12<>"",G12,IF(E12="JPY",IF(ISNUMBER($L$1),ROUND(F12/$L$1,2),"レート未入力"),F12))) | J12: =IF(A12="","",IF(A12<DATE(2025,4,6),"2024/25",IF(A12<DATE(2026,4,6),"2025/26",IF(A12<DATE(2027,4,6),"2026/27","2027/28"))))
H13: =IF(F13="","",IF(G13<>"",G13,IF(E13="JPY",IF(ISNUMBER($L$1),ROUND(F13/$L$1,2),"レート未入力"),F13))) | J13: =IF(A13="","",IF(A13<DATE(2025,4,6),"2024/25",IF(A13<DATE(2026,4,6),"2025/26",IF(A13<DATE(2027,4,6),"2026/27","2027/28"))))
H14: =IF(F14="","",IF(G14<>"",G14,IF(E14="JPY",IF(ISNUMBER($L$1),ROUND(F14/$L$1,2),"レート未入力"),F14))) | J14: =IF(A14="","",IF(A14<DATE(2025,4,6),"2024/25",IF(A14<DATE(2026,4,6),"2025/26",IF(A14<DATE(2027,4,6),"2026/27","2027/28"))))
H15: =IF(F15="","",IF(G15<>"",G15,IF(E15="JPY",IF(ISNUMBER($L$1),ROUND(F15/$L$1,2),"レート未入力"),F15))) | J15: =IF(A15="","",IF(A15<DATE(2025,4,6),"2024/25",IF(A15<DATE(2026,4,6),"2025/26",IF(A15<DATE(2027,4,6),"2026/27","2027/28"))))
H16: =IF(F16="","",IF(G16<>"",G16,IF(E16="JPY",IF(ISNUMBER($L$1),ROUND(F16/$L$1,2),"レート未入力"),F16))) | J16: =IF(A16="","",IF(A16<DATE(2025,4,6),"2024/25",IF(A16<DATE(2026,4,6),"2025/26",IF(A16<DATE(2027,4,6),"2026/27","2027/28"))))
H17: =IF(F17="","",IF(G17<>"",G17,IF(E17="JPY",IF(ISNUMBER($L$1),ROUND(F17/$L$1,2),"レート未入力"),F17))) | J17: =IF(A17="","",IF(A17<DATE(2025,4,6),"2024/25",IF(A17<DATE(2026,4,6),"2025/26",IF(A17<DATE(2027,4,6),"2026/27","2027/28"))))
... H25: =IF(F25="","",IF(G25<>"",G25,IF(E25="JPY",IF(ISNUMBER($L$1),ROUND(F25/$L$1,2),"レート未入力"),F25))) | J25: =IF(A25="","",IF(A25<DATE(2025,4,6),"2024/25",IF(A25<DATE(2026,4,6),"2025/26",IF(A25<DATE(2027,4,6),"2026/27","2027/28"))))
A26: 収入合計 | H26: =SUM(H6:H25) -> 0
A28: 【経費】仕事で支払った費用（支払った日で記録・領収書を保管）
A29: 日付 | B29: 支払先 | C29: 内容 | D29: カテゴリ | E29: 通貨 | F29: 元の金額 | G29: 実際の£額 (分かれば) | H29: £換算額 自動 | I29: 事業使用率 (空欄=100%) | J29: 認定経費(£) 自動 | K29: 領収書 ○ | L29: 税年度 自動 | N29: メモ
H30: =IF(F30="","",IF(G30<>"",G30,IF(E30="JPY",IF(ISNUMBER($L$1),ROUND(F30/$L$1,2),"レート未入力"),F30))) | J30: =IF(ISNUMBER(H30),ROUND(H30*IF(I30="",1,I30),2),"") | L30: =IF(A30="","",IF(A30<DATE(2025,4,6),"2024/25",IF(A30<DATE(2026,4,6),"2025/26",IF(A30<DATE(2027,4,6),"2026/27","2027/28"))))
H31: =IF(F31="","",IF(G31<>"",G31,IF(E31="JPY",IF(ISNUMBER($L$1),ROUND(F31/$L$1,2),"レート未入力"),F31))) | J31: =IF(ISNUMBER(H31),ROUND(H31*IF(I31="",1,I31),2),"") | L31: =IF(A31="","",IF(A31<DATE(2025,4,6),"2024/25",IF(A31<DATE(2026,4,6),"2025/26",IF(A31<DATE(2027,4,6),"2026/27","2027/28"))))
H32: =IF(F32="","",IF(G32<>"",G32,IF(E32="JPY",IF(ISNUMBER($L$1),ROUND(F32/$L$1,2),"レート未入力"),F32))) | J32: =IF(ISNUMBER(H32),ROUND(H32*IF(I32="",1,I32),2),"") | L32: =IF(A32="","",IF(A32<DATE(2025,4,6),"2024/25",IF(A32<DATE(2026,4,6),"2025/26",IF(A32<DATE(2027,4,6),"2026/27","2027/28"))))
H33: =IF(F33="","",IF(G33<>"",G33,IF(E33="JPY",IF(ISNUMBER($L$1),ROUND(F33/$L$1,2),"レート未入力"),F33))) | J33: =IF(ISNUMBER(H33),ROUND(H33*IF(I33="",1,I33),2),"") | L33: =IF(A33="","",IF(A33<DATE(2025,4,6),"2024/25",IF(A33<DATE(2026,4,6),"2025/26",IF(A33<DATE(2027,4,6),"2026/27","2027/28"))))
H34: =IF(F34="","",IF(G34<>"",G34,IF(E34="JPY",IF(ISNUMBER($L$1),ROUND(F34/$L$1,2),"レート未入力"),F34))) | J34: =IF(ISNUMBER(H34),ROUND(H34*IF(I34="",1,I34),2),"") | L34: =IF(A34="","",IF(A34<DATE(2025,4,6),"2024/25",IF(A34<DATE(2026,4,6),"2025/26",IF(A34<DATE(2027,4,6),"2026/27","2027/28"))))
H35: =IF(F35="","",IF(G35<>"",G35,IF(E35="JPY",IF(ISNUMBER($L$1),ROUND(F35/$L$1,2),"レート未入力"),F35))) | J35: =IF(ISNUMBER(H35),ROUND(H35*IF(I35="",1,I35),2),"") | L35: =IF(A35="","",IF(A35<DATE(2025,4,6),"2024/25",IF(A35<DATE(2026,4,6),"2025/26",IF(A35<DATE(2027,4,6),"2026/27","2027/28"))))
H36: =IF(F36="","",IF(G36<>"",G36,IF(E36="JPY",IF(ISNUMBER($L$1),ROUND(F36/$L$1,2),"レート未入力"),F36))) | J36: =IF(ISNUMBER(H36),ROUND(H36*IF(I36="",1,I36),2),"") | L36: =IF(A36="","",IF(A36<DATE(2025,4,6),"2024/25",IF(A36<DATE(2026,4,6),"2025/26",IF(A36<DATE(2027,4,6),"2026/27","2027/28"))))
H37: =IF(F37="","",IF(G37<>"",G37,IF(E37="JPY",IF(ISNUMBER($L$1),ROUND(F37/$L$1,2),"レート未入力"),F37))) | J37: =IF(ISNUMBER(H37),ROUND(H37*IF(I37="",1,I37),2),"") | L37: =IF(A37="","",IF(A37<DATE(2025,4,6),"2024/25",IF(A37<DATE(2026,4,6),"2025/26",IF(A37<DATE(2027,4,6),"2026/27","2027/28"))))
H38: =IF(F38="","",IF(G38<>"",G38,IF(E38="JPY",IF(ISNUMBER($L$1),ROUND(F38/$L$1,2),"レート未入力"),F38))) | J38: =IF(ISNUMBER(H38),ROUND(H38*IF(I38="",1,I38),2),"") | L38: =IF(A38="","",IF(A38<DATE(2025,4,6),"2024/25",IF(A38<DATE(2026,4,6),"2025/26",IF(A38<DATE(2027,4,6),"2026/27","2027/28"))))
H39: =IF(F39="","",IF(G39<>"",G39,IF(E39="JPY",IF(ISNUMBER($L$1),ROUND(F39/$L$1,2),"レート未入力"),F39))) | J39: =IF(ISNUMBER(H39),ROUND(H39*IF(I39="",1,I39),2),"") | L39: =IF(A39="","",IF(A39<DATE(2025,4,6),"2024/25",IF(A39<DATE(2026,4,6),"2025/26",IF(A39<DATE(2027,4,6),"2026/27","2027/28"))))
H40: =IF(F40="","",IF(G40<>"",G40,IF(E40="JPY",IF(ISNUMBER($L$1),ROUND(F40/$L$1,2),"レート未入力"),F40))) | J40: =IF(ISNUMBER(H40),ROUND(H40*IF(I40="",1,I40),2),"") | L40: =IF(A40="","",IF(A40<DATE(2025,4,6),"2024/25",IF(A40<DATE(2026,4,6),"2025/26",IF(A40<DATE(2027,4,6),"2026/27","2027/28"))))
H41: =IF(F41="","",IF(G41<>"",G41,IF(E41="JPY",IF(ISNUMBER($L$1),ROUND(F41/$L$1,2),"レート未入力"),F41))) | J41: =IF(ISNUMBER(H41),ROUND(H41*IF(I41="",1,I41),2),"") | L41: =IF(A41="","",IF(A41<DATE(2025,4,6),"2024/25",IF(A41<DATE(2026,4,6),"2025/26",IF(A41<DATE(2027,4,6),"2026/27","2027/28"))))
... H69: =IF(F69="","",IF(G69<>"",G69,IF(E69="JPY",IF(ISNUMBER($L$1),ROUND(F69/$L$1,2),"レート未入力"),F69))) | J69: =IF(ISNUMBER(H69),ROUND(H69*IF(I69="",1,I69),2),"") | L69: =IF(A69="","",IF(A69<DATE(2025,4,6),"2024/25",IF(A69<DATE(2026,4,6),"2025/26",IF(A69<DATE(2027,4,6),"2026/27","2027/28"))))
A70: 支払合計（按分後・機材含む） | J70: =SUM(J30:J69) -> 0
A72: 【月まとめ（税年度別）】自動計算
A73: 項目 | D73: 2025/26 | E73: 2026/27
A74: 収入合計 | D74: =SUMIFS($H$6:$H$25,$J$6:$J$25,"2025/26") -> 0 | E74: =SUMIFS($H$6:$H$25,$J$6:$J$25,"2026/27") -> 0
A75: 外注費・仕入 | D75: =SUMIFS($J$30:$J$69,$D$30:$D$69,$A75,$L$30:$L$69,"2025/26") -> 0 | E75: =SUMIFS($J$30:$J$69,$D$30:$D$69,$A75,$L$30:$L$69,"2026/27") -> 0
A76: 給与・スタッフ費 | D76: =SUMIFS($J$30:$J$69,$D$30:$D$69,$A76,$L$30:$L$69,"2025/26") -> 0 | E76: =SUMIFS($J$30:$J$69,$D$30:$D$69,$A76,$L$30:$L$69,"2026/27") -> 0
A77: 交通費・車両費 | D77: =SUMIFS($J$30:$J$69,$D$30:$D$69,$A77,$L$30:$L$69,"2025/26") -> 0 | E77: =SUMIFS($J$30:$J$69,$D$30:$D$69,$A77,$L$30:$L$69,"2026/27") -> 0
...

Sheet 2025-06
A1: 2025年6月 | J1: 今月のレート 1£＝ | L1: =IF(為替レート!$B$7="","未入力",為替レート!$B$7) -> 未入力
A2: 黄色＝記入／緑＝自動計算。円の支払いは「為替レート」タブのレートで自動換算（実際の£額があればそちらを優先）。
A4: 【収入】仕事の入金（入金した日で記録）
A5: 日付 | B5: 取引先 | C5: 内容 | D5: 入金方法 | E5: 通貨 | F5: 元の金額 | G5: 実際の£額 (分かれば) | H5: 金額(£) 自動 | I5: 請求書No. | J5: 税年度 自動 | N5: メモ
H6: =IF(F6="","",IF(G6<>"",G6,IF(E6="JPY",IF(ISNUMBER($L$1),ROUND(F6/$L$1,2),"レート未入力"),F6))) | J6: =IF(A6="","",IF(A6<DATE(2025,4,6),"2024/25",IF(A6<DATE(2026,4,6),"2025/26",IF(A6<DATE(2027,4,6),"2026/27","2027/28"))))
H7: =IF(F7="","",IF(G7<>"",G7,IF(E7="JPY",IF(ISNUMBER($L$1),ROUND(F7/$L$1,2),"レート未入力"),F7))) | J7: =IF(A7="","",IF(A7<DATE(2025,4,6),"2024/25",IF(A7<DATE(2026,4,6),"2025/26",IF(A7<DATE(2027,4,6),"2026/27","2027/28"))))
H8: =IF(F8="","",IF(G8<>"",G8,IF(E8="JPY",IF(ISNUMBER($L$1),ROUND(F8/$L$1,2),"レート未入力"),F8))) | J8: =IF(A8="","",IF(A8<DATE(2025,4,6),"2024/25",IF(A8<DATE(2026,4,6),"2025/26",IF(A8<DATE(2027,4,6),"2026/27","2027/28"))))
H9: =IF(F9="","",IF(G9<>"",G9,IF(E9="JPY",IF(ISNUMBER($L$1),ROUND(F9/$L$1,2),"レート未入力"),F9))) | J9: =IF(A9="","",IF(A9<DATE(2025,4,6),"2024/25",IF(A9<DATE(2026,4,6),"2025/26",IF(A9<DATE(2027,4,6),"2026/27","2027/28"))))
H10: =IF(F10="","",IF(G10<>"",G10,IF(E10="JPY",IF(ISNUMBER($L$1),ROUND(F10/$L$1,2),"レート未入力"),F10))) | J10: =IF(A10="","",IF(A10<DATE(2025,4,6),"2024/25",IF(A10<DATE(2026,4,6),"2025/26",IF(A10<DATE(2027,4,6),"2026/27","2027/28"))))
H11: =IF(F11="","",IF(G11<>"",G11,IF(E11="JPY",IF(ISNUMBER($L$1),ROUND(F11/$L$1,2),"レート未入力"),F11))) | J11: =IF(A11="","",IF(A11<DATE(2025,4,6),"2024/25",IF(A11<DATE(2026,4,6),"2025/26",IF(A11<DATE(2027,4,6),"2026/27","2027/28"))))
H12: =IF(F12="","",IF(G12<>"",G12,IF(E12="JPY",IF(ISNUMBER($L$1),ROUND(F12/$L$1,2),"レート未入力"),F12))) | J12: =IF(A12="","",IF(A12<DATE(2025,4,6),"2024/25",IF(A12<DATE(2026,4,6),"2025/26",IF(A12<DATE(2027,4,6),"2026/27","2027/28"))))
H13: =IF(F13="","",IF(G13<>"",G13,IF(E13="JPY",IF(ISNUMBER($L$1),ROUND(F13/$L$1,2),"レート未入力"),F13))) | J13: =IF(A13="","",IF(A13<DATE(2025,4,6),"2024/25",IF(A13<DATE(2026,4,6),"2025/26",IF(A13<DATE(2027,4,6),"2026/27","2027/28"))))
H14: =IF(F14="","",IF(G14<>"",G14,IF(E14="JPY",IF(ISNUMBER($L$1),ROUND(F14/$L$1,2),"レート未入力"),F14))) | J14: =IF(A14="","",IF(A14<DATE(2025,4,6),"2024/25",IF(A14<DATE(2026,4,6),"2025/26",IF(A14<DATE(2027,4,6),"2026/27","2027/28"))))
H15: =IF(F15="","",IF(G15<>"",G15,IF(E15="JPY",IF(ISNUMBER($L$1),ROUND(F15/$L$1,2),"レート未入力"),F15))) | J15: =IF(A15="","",IF(A15<DATE(2025,4,6),"2024/25",IF(A15<DATE(2026,4,6),"2025/26",IF(A15<DATE(2027,4,6),"2026/27","2027/28"))))
H16: =IF(F16="","",IF(G16<>"",G16,IF(E16="JPY",IF(ISNUMBER($L$1),ROUND(F16/$L$1,2),"レート未入力"),F16))) | J16: =IF(A16="","",IF(A16<DATE(2025,4,6),"2024/25",IF(A16<DATE(2026,4,6),"2025/26",IF(A16<DATE(2027,4,6),"2026/27","2027/28"))))
H17: =IF(F17="","",IF(G17<>"",G17,IF(E17="JPY",IF(ISNUMBER($L$1),ROUND(F17/$L$1,2),"レート未入力"),F17))) | J17: =IF(A17="","",IF(A17<DATE(2025,4,6),"2024/25",IF(A17<DATE(2026,4,6),"2025/26",IF(A17<DATE(2027,4,6),"2026/27","2027/28"))))
... H25: =IF(F25="","",IF(G25<>"",G25,IF(E25="JPY",IF(ISNUMBER($L$1),ROUND(F25/$L$1,2),"レート未入力"),F25))) | J25: =IF(A25="","",IF(A25<DATE(2025,4,6),"2024/25",IF(A25<DATE(2026,4,6),"2025/26",IF(A25<DATE(2027,4,6),"2026/27","2027/28"))))
A26: 収入合計 | H26: =SUM(H6:H25) -> 0
A28: 【経費】仕事で支払った費用（支払った日で記録・領収書を保管）
A29: 日付 | B29: 支払先 | C29: 内容 | D29: カテゴリ | E29: 通貨 | F29: 元の金額 | G29: 実際の£額 (分かれば) | H29: £換算額 自動 | I29: 事業使用率 (空欄=100%) | J29: 認定経費(£) 自動 | K29: 領収書 ○ | L29: 税年度 自動 | N29: メモ
H30: =IF(F30="","",IF(G30<>"",G30,IF(E30="JPY",IF(ISNUMBER($L$1),ROUND(F30/$L$1,2),"レート未入力"),F30))) | J30: =IF(ISNUMBER(H30),ROUND(H30*IF(I30="",1,I30),2),"") | L30: =IF(A30="","",IF(A30<DATE(2025,4,6),"2024/25",IF(A30<DATE(2026,4,6),"2025/26",IF(A30<DATE(2027,4,6),"2026/27","2027/28"))))
H31: =IF(F31="","",IF(G31<>"",G31,IF(E31="JPY",IF(ISNUMBER($L$1),ROUND(F31/$L$1,2),"レート未入力"),F31))) | J31: =IF(ISNUMBER(H31),ROUND(H31*IF(I31="",1,I31),2),"") | L31: =IF(A31="","",IF(A31<DATE(2025,4,6),"2024/25",IF(A31<DATE(2026,4,6),"2025/26",IF(A31<DATE(2027,4,6),"2026/27","2027/28"))))
H32: =IF(F32="","",IF(G32<>"",G32,IF(E32="JPY",IF(ISNUMBER($L$1),ROUND(F32/$L$1,2),"レート未入力"),F32))) | J32: =IF(ISNUMBER(H32),ROUND(H32*IF(I32="",1,I32),2),"") | L32: =IF(A32="","",IF(A32<DATE(2025,4,6),"2024/25",IF(A32<DATE(2026,4,6),"2025/26",IF(A32<DATE(2027,4,6),"2026/27","2027/28"))))
H33: =IF(F33="","",IF(G33<>"",G33,IF(E33="JPY",IF(ISNUMBER($L$1),ROUND(F33/$L$1,2),"レート未入力"),F33))) | J33: =IF(ISNUMBER(H33),ROUND(H33*IF(I33="",1,I33),2),"") | L33: =IF(A33="","",IF(A33<DATE(2025,4,6),"2024/25",IF(A33<DATE(2026,4,6),"2025/26",IF(A33<DATE(2027,4,6),"2026/27","2027/28"))))
H34: =IF(F34="","",IF(G34<>"",G34,IF(E34="JPY",IF(ISNUMBER($L$1),ROUND(F34/$L$1,2),"レート未入力"),F34))) | J34: =IF(ISNUMBER(H34),ROUND(H34*IF(I34="",1,I34),2),"") | L34: =IF(A34="","",IF(A34<DATE(2025,4,6),"2024/25",IF(A34<DATE(2026,4,6),"2025/26",IF(A34<DATE(2027,4,6),"2026/27","2027/28"))))
H35: =IF(F35="","",IF(G35<>"",G35,IF(E35="JPY",IF(ISNUMBER($L$1),ROUND(F35/$L$1,2),"レート未入力"),F35))) | J35: =IF(ISNUMBER(H35),ROUND(H35*IF(I35="",1,I35),2),"") | L35: =IF(A35="","",IF(A35<DATE(2025,4,6),"2024/25",IF(A35<DATE(2026,4,6),"2025/26",IF(A35<DATE(2027,4,6),"2026/27","2027/28"))))
H36: =IF(F36="","",IF(G36<>"",G36,IF(E36="JPY",IF(ISNUMBER($L$1),ROUND(F36/$L$1,2),"レート未入力"),F36))) | J36: =IF(ISNUMBER(H36),ROUND(H36*IF(I36="",1,I36),2),"") | L36: =IF(A36="","",IF(A36<DATE(2025,4,6),"2024/25",IF(A36<DATE(2026,4,6),"2025/26",IF(A36<DATE(2027,4,6),"2026/27","2027/28"))))
H37: =IF(F37="","",IF(G37<>"",G37,IF(E37="JPY",IF(ISNUMBER($L$1),ROUND(F37/$L$1,2),"レート未入力"),F37))) | J37: =IF(ISNUMBER(H37),ROUND(H37*IF(I37="",1,I37),2),"") | L37: =IF(A37="","",IF(A37<DATE(2025,4,6),"2024/25",IF(A37<DATE(2026,4,6),"2025/26",IF(A37<DATE(2027,4,6),"2026/27","2027/28"))))
H38: =IF(F38="","",IF(G38<>"",G38,IF(E38="JPY",IF(ISNUMBER($L$1),ROUND(F38/$L$1,2),"レート未入力"),F38))) | J38: =IF(ISNUMBER(H38),ROUND(H38*IF(I38="",1,I38),2),"") | L38: =IF(A38="","",IF(A38<DATE(2025,4,6),"2024/25",IF(A38<DATE(2026,4,6),"2025/26",IF(A38<DATE(2027,4,6),"2026/27","2027/28"))))
H39: =IF(F39="","",IF(G39<>"",G39,IF(E39="JPY",IF(ISNUMBER($L$1),ROUND(F39/$L$1,2),"レート未入力"),F39))) | J39: =IF(ISNUMBER(H39),ROUND(H39*IF(I39="",1,I39),2),"") | L39: =IF(A39="","",IF(A39<DATE(2025,4,6),"2024/25",IF(A39<DATE(2026,4,6),"2025/26",IF(A39<DATE(2027,4,6),"2026/27","2027/28"))))
H40: =IF(F40="","",IF(G40<>"",G40,IF(E40="JPY",IF(ISNUMBER($L$1),ROUND(F40/$L$1,2),"レート未入力"),F40))) | J40: =IF(ISNUMBER(H40),ROUND(H40*IF(I40="",1,I40),2),"") | L40: =IF(A40="","",IF(A40<DATE(2025,4,6),"2024/25",IF(A40<DATE(2026,4,6),"2025/26",IF(A40<DATE(2027,4,6),"2026/27","2027/28"))))
H41: =IF(F41="","",IF(G41<>"",G41,IF(E41="JPY",IF(ISNUMBER($L$1),ROUND(F41/$L$1,2),"レート未入力"),F41))) | J41: =IF(ISNUMBER(H41),ROUND(H41*IF(I41="",1,I41),2),"") | L41: =IF(A41="","",IF(A41<DATE(2025,4,6),"2024/25",IF(A41<DATE(2026,4,6),"2025/26",IF(A41<DATE(2027,4,6),"2026/27","2027/28"))))
... H69: =IF(F69="","",IF(G69<>"",G69,IF(E69="JPY",IF(ISNUMBER($L$1),ROUND(F69/$L$1,2),"レート未入力"),F69))) | J69: =IF(ISNUMBER(H69),ROUND(H69*IF(I69="",1,I69),2),"") | L69: =IF(A69="","",IF(A69<DATE(2025,4,6),"2024/25",IF(A69<DATE(2026,4,6),"2025/26",IF(A69<DATE(2027,4,6),"2026/27","2027/28"))))
A70: 支払合計（按分後・機材含む） | J70: =SUM(J30:J69) -> 0
A72: 【月まとめ（税年度別）】自動計算
A73: 項目 | D73: 2025/26 | E73: 2026/27
A74: 収入合計 | D74: =SUMIFS($H$6:$H$25,$J$6:$J$25,"2025/26") -> 0 | E74: =SUMIFS($H$6:$H$25,$J$6:$J$25,"2026/27") -> 0
A75: 外注費・仕入 | D75: =SUMIFS($J$30:$J$69,$D$30:$D$69,$A75,$L$30:$L$69,"2025/26") -> 0 | E75: =SUMIFS($J$30:$J$69,$D$30:$D$69,$A75,$L$30:$L$69,"2026/27") -> 0
A76: 給与・スタッフ費 | D76: =SUMIFS($J$30:$J$69,$D$30:$D$69,$A76,$L$30:$L$69,"2025/26") -> 0 | E76: =SUMIFS($J$30:$J$69,$D$30:$D$69,$A76,$L$30:$L$69,"2026/27") -> 0
A77: 交通費・車両費 | D77: =SUMIFS($J$30:$J$69,$D$30:$D$69,$A77,$L$30:$L$69,"2025/26") -> 0 | E77: =SUMIFS($J$30:$J$69,$D$30:$D$69,$A77,$L$30:$L$69,"2026/27") -> 0
...

Sheet 2025-07
A1: 2025年7月 | J1: 今月のレート 1£＝ | L1: =IF(為替レート!$B$8="","未入力",為替レート!$B$8) -> 未入力
A2: 黄色＝記入／緑＝自動計算。円の支払いは「為替レート」タブのレートで自動換算（実際の£額があればそちらを優先）。
A4: 【収入】仕事の入金（入金した日で記録）
A5: 日付 | B5: 取引先 | C5: 内容 | D5: 入金方法 | E5: 通貨 | F5: 元の金額 | G5: 実際の£額 (分かれば) | H5: 金額(£) 自動 | I5: 請求書No. | J5: 税年度 自動 | N5: メモ
H6: =IF(F6="","",IF(G6<>"",G6,IF(E6="JPY",IF(ISNUMBER($L$1),ROUND(F6/$L$1,2),"レート未入力"),F6))) | J6: =IF(A6="","",IF(A6<DATE(2025,4,6),"2024/25",IF(A6<DATE(2026,4,6),"2025/26",IF(A6<DATE(2027,4,6),"2026/27","2027/28"))))
H7: =IF(F7="","",IF(G7<>"",G7,IF(E7="JPY",IF(ISNUMBER($L$1),ROUND(F7/$L$1,2),"レート未入力"),F7))) | J7: =IF(A7="","",IF(A7<DATE(2025,4,6),"2024/25",IF(A7<DATE(2026,4,6),"2025/26",IF(A7<DATE(2027,4,6),"2026/27","2027/28"))))
H8: =IF(F8="","",IF(G8<>"",G8,IF(E8="JPY",IF(ISNUMBER($L$1),ROUND(F8/$L$1,2),"レート未入力"),F8))) | J8: =IF(A8="","",IF(A8<DATE(2025,4,6),"2024/25",IF(A8<DATE(2026,4,6),"2025/26",IF(A8<DATE(2027,4,6),"2026/27","2027/28"))))
H9: =IF(F9="","",IF(G9<>"",G9,IF(E9="JPY",IF(ISNUMBER($L$1),ROUND(F9/$L$1,2),"レート未入力"),F9))) | J9: =IF(A9="","",IF(A9<DATE(2025,4,6),"2024/25",IF(A9<DATE(2026,4,6),"2025/26",IF(A9<DATE(2027,4,6),"2026/27","2027/28"))))
H10: =IF(F10="","",IF(G10<>"",G10,IF(E10="JPY",IF(ISNUMBER($L$1),ROUND(F10/$L$1,2),"レート未入力"),F10))) | J10: =IF(A10="","",IF(A10<DATE(2025,4,6),"2024/25",IF(A10<DATE(2026,4,6),"2025/26",IF(A10<DATE(2027,4,6),"2026/27","2027/28"))))
H11: =IF(F11="","",IF(G11<>"",G11,IF(E11="JPY",IF(ISNUMBER($L$1),ROUND(F11/$L$1,2),"レート未入力"),F11))) | J11: =IF(A11="","",IF(A11<DATE(2025,4,6),"2024/25",IF(A11<DATE(2026,4,6),"2025/26",IF(A11<DATE(2027,4,6),"2026/27","2027/28"))))
H12: =IF(F12="","",IF(G12<>"",G12,IF(E12="JPY",IF(ISNUMBER($L$1),ROUND(F12/$L$1,2),"レート未入力"),F12))) | J12: =IF(A12="","",IF(A12<DATE(2025,4,6),"2024/25",IF(A12<DATE(2026,4,6),"2025/26",IF(A12<DATE(2027,4,6),"2026/27","2027/28"))))
H13: =IF(F13="","",IF(G13<>"",G13,IF(E13="JPY",IF(ISNUMBER($L$1),ROUND(F13/$L$1,2),"レート未入力"),F13))) | J13: =IF(A13="","",IF(A13<DATE(2025,4,6),"2024/25",IF(A13<DATE(2026,4,6),"2025/26",IF(A13<DATE(2027,4,6),"2026/27","2027/28"))))
H14: =IF(F14="","",IF(G14<>"",G14,IF(E14="JPY",IF(ISNUMBER($L$1),ROUND(F14/$L$1,2),"レート未入力"),F14))) | J14: =IF(A14="","",IF(A14<DATE(2025,4,6),"2024/25",IF(A14<DATE(2026,4,6),"2025/26",IF(A14<DATE(2027,4,6),"2026/27","2027/28"))))
H15: =IF(F15="","",IF(G15<>"",G15,IF(E15="JPY",IF(ISNUMBER($L$1),ROUND(F15/$L$1,2),"レート未入力"),F15))) | J15: =IF(A15="","",IF(A15<DATE(2025,4,6),"2024/25",IF(A15<DATE(2026,4,6),"2025/26",IF(A15<DATE(2027,4,6),"2026/27","2027/28"))))
H16: =IF(F16="","",IF(G16<>"",G16,IF(E16="JPY",IF(ISNUMBER($L$1),ROUND(F16/$L$1,2),"レート未入力"),F16))) | J16: =IF(A16="","",IF(A16<DATE(2025,4,6),"2024/25",IF(A16<DATE(2026,4,6),"2025/26",IF(A16<DATE(2027,4,6),"2026/27","2027/28"))))
H17: =IF(F17="","",IF(G17<>"",G17,IF(E17="JPY",IF(ISNUMBER($L$1),ROUND(F17/$L$1,2),"レート未入力"),F17))) | J17: =IF(A17="","",IF(A17<DATE(2025,4,6),"2024/25",IF(A17<DATE(2026,4,6),"2025/26",IF(A17<DATE(2027,4,6),"2026/27","2027/28"))))
... H25: =IF(F25="","",IF(G25<>"",G25,IF(E25="JPY",IF(ISNUMBER($L$1),ROUND(F25/$L$1,2),"レート未入力"),F25))) | J25: =IF(A25="","",IF(A25<DATE(2025,4,6),"2024/25",IF(A25<DATE(2026,4,6),"2025/26",IF(A25<DATE(2027,4,6),"2026/27","2027/28"))))
A26: 収入合計 | H26: =SUM(H6:H25) -> 0
A28: 【経費】仕事で支払った費用（支払った日で記録・領収書を保管）
A29: 日付 | B29: 支払先 | C29: 内容 | D29: カテゴリ | E29: 通貨 | F29: 元の金額 | G29: 実際の£額 (分かれば) | H29: £換算額 自動 | I29: 事業使用率 (空欄=100%) | J29: 認定経費(£) 自動 | K29: 領収書 ○ | L29: 税年度 自動 | N29: メモ
H30: =IF(F30="","",IF(G30<>"",G30,IF(E30="JPY",IF(ISNUMBER($L$1),ROUND(F30/$L$1,2),"レート未入力"),F30))) | J30: =IF(ISNUMBER(H30),ROUND(H30*IF(I30="",1,I30),2),"") | L30: =IF(A30="","",IF(A30<DATE(2025,4,6),"2024/25",IF(A30<DATE(2026,4,6),"2025/26",IF(A30<DATE(2027,4,6),"2026/27","2027/28"))))
H31: =IF(F31="","",IF(G31<>"",G31,IF(E31="JPY",IF(ISNUMBER($L$1),ROUND(F31/$L$1,2),"レート未入力"),F31))) | J31: =IF(ISNUMBER(H31),ROUND(H31*IF(I31="",1,I31),2),"") | L31: =IF(A31="","",IF(A31<DATE(2025,4,6),"2024/25",IF(A31<DATE(2026,4,6),"2025/26",IF(A31<DATE(2027,4,6),"2026/27","2027/28"))))
H32: =IF(F32="","",IF(G32<>"",G32,IF(E32="JPY",IF(ISNUMBER($L$1),ROUND(F32/$L$1,2),"レート未入力"),F32))) | J32: =IF(ISNUMBER(H32),ROUND(H32*IF(I32="",1,I32),2),"") | L32: =IF(A32="","",IF(A32<DATE(2025,4,6),"2024/25",IF(A32<DATE(2026,4,6),"2025/26",IF(A32<DATE(2027,4,6),"2026/27","2027/28"))))
H33: =IF(F33="","",IF(G33<>"",G33,IF(E33="JPY",IF(ISNUMBER($L$1),ROUND(F33/$L$1,2),"レート未入力"),F33))) | J33: =IF(ISNUMBER(H33),ROUND(H33*IF(I33="",1,I33),2),"") | L33: =IF(A33="","",IF(A33<DATE(2025,4,6),"2024/25",IF(A33<DATE(2026,4,6),"2025/26",IF(A33<DATE(2027,4,6),"2026/27","2027/28"))))
H34: =IF(F34="","",IF(G34<>"",G34,IF(E34="JPY",IF(ISNUMBER($L$1),ROUND(F34/$L$1,2),"レート未入力"),F34))) | J34: =IF(ISNUMBER(H34),ROUND(H34*IF(I34="",1,I34),2),"") | L34: =IF(A34="","",IF(A34<DATE(2025,4,6),"2024/25",IF(A34<DATE(2026,4,6),"2025/26",IF(A34<DATE(2027,4,6),"2026/27","2027/28"))))
H35: =IF(F35="","",IF(G35<>"",G35,IF(E35="JPY",IF(ISNUMBER($L$1),ROUND(F35/$L$1,2),"レート未入力"),F35))) | J35: =IF(ISNUMBER(H35),ROUND(H35*IF(I35="",1,I35),2),"") | L35: =IF(A35="","",IF(A35<DATE(2025,4,6),"2024/25",IF(A35<DATE(2026,4,6),"2025/26",IF(A35<DATE(2027,4,6),"2026/27","2027/28"))))
H36: =IF(F36="","",IF(G36<>"",G36,IF(E36="JPY",IF(ISNUMBER($L$1),ROUND(F36/$L$1,2),"レート未入力"),F36))) | J36: =IF(ISNUMBER(H36),ROUND(H36*IF(I36="",1,I36),2),"") | L36: =IF(A36="","",IF(A36<DATE(2025,4,6),"2024/25",IF(A36<DATE(2026,4,6),"2025/26",IF(A36<DATE(2027,4,6),"2026/27","2027/28"))))
H37: =IF(F37="","",IF(G37<>"",G37,IF(E37="JPY",IF(ISNUMBER($L$1),ROUND(F37/$L$1,2),"レート未入力"),F37))) | J37: =IF(ISNUMBER(H37),ROUND(H37*IF(I37="",1,I37),2),"") | L37: =IF(A37="","",IF(A37<DATE(2025,4,6),"2024/25",IF(A37<DATE(2026,4,6),"2025/26",IF(A37<DATE(2027,4,6),"2026/27","2027/28"))))
H38: =IF(F38="","",IF(G38<>"",G38,IF(E38="JPY",IF(ISNUMBER($L$1),ROUND(F38/$L$1,2),"レート未入力"),F38))) | J38: =IF(ISNUMBER(H38),ROUND(H38*IF(I38="",1,I38),2),"") | L38: =IF(A38="","",IF(A38<DATE(2025,4,6),"2024/25",IF(A38<DATE(2026,4,6),"2025/26",IF(A38<DATE(2027,4,6),"2026/27","2027/28"))))
H39: =IF(F39="","",IF(G39<>"",G39,IF(E39="JPY",IF(ISNUMBER($L$1),ROUND(F39/$L$1,2),"レート未入力"),F39))) | J39: =IF(ISNUMBER(H39),ROUND(H39*IF(I39="",1,I39),2),"") | L39: =IF(A39="","",IF(A39<DATE(2025,4,6),"2024/25",IF(A39<DATE(2026,4,6),"2025/26",IF(A39<DATE(2027,4,6),"2026/27","2027/28"))))
H40: =IF(F40="","",IF(G40<>"",G40,IF(E40="JPY",IF(ISNUMBER($L$1),ROUND(F40/$L$1,2),"レート未入力"),F40))) | J40: =IF(ISNUMBER(H40),ROUND(H40*IF(I40="",1,I40),2),"") | L40: =IF(A40="","",IF(A40<DATE(2025,4,6),"2024/25",IF(A40<DATE(2026,4,6),"2025/26",IF(A40<DATE(2027,4,6),"2026/27","2027/28"))))
H41: =IF(F41="","",IF(G41<>"",G41,IF(E41="JPY",IF(ISNUMBER($L$1),ROUND(F41/$L$1,2),"レート未入力"),F41))) | J41: =IF(ISNUMBER(H41),ROUND(H41*IF(I41="",1,I41),2),"") | L41: =IF(A41="","",IF(A41<DATE(2025,4,6),"2024/25",IF(A41<DATE(2026,4,6),"2025/26",IF(A41<DATE(2027,4,6),"2026/27","2027/28"))))
... H69: =IF(F69="","",IF(G69<>"",G69,IF(E69="JPY",IF(ISNUMBER($L$1),ROUND(F69/$L$1,2),"レート未入力"),F69))) | J69: =IF(ISNUMBER(H69),ROUND(H69*IF(I69="",1,I69),2),"") | L69: =IF(A69="","",IF(A69<DATE(2025,4,6),"2024/25",IF(A69<DATE(2026,4,6),"2025/26",IF(A69<DATE(2027,4,6),"2026/27","2027/28"))))
A70: 支払合計（按分後・機材含む） | J70: =SUM(J30:J69) -> 0
A72: 【月まとめ（税年度別）】自動計算
A73: 項目 | D73: 2025/26 | E73: 2026/27
A74: 収入合計 | D74: =SUMIFS($H$6:$H$25,$J$6:$J$25,"2025/26") -> 0 | E74: =SUMIFS($H$6:$H$25,$J$6:$J$25,"2026/27") -> 0
A75: 外注費・仕入 | D75: =SUMIFS($J$30:$J$69,$D$30:$D$69,$A75,$L$30:$L$69,"2025/26") -> 0 | E75: =SUMIFS($J$30:$J$69,$D$30:$D$69,$A75,$L$30:$L$69,"2026/27") -> 0
A76: 給与・スタッフ費 | D76: =SUMIFS($J$30:$J$69,$D$30:$D$69,$A76,$L$30:$L$69,"2025/26") -> 0 | E76: =SUMIFS($J$30:$J$69,$D$30:$D$69,$A76,$L$30:$L$69,"2026/27") -> 0
A77: 交通費・車両費 | D77: =SUMIFS($J$30:$J$69,$D$30:$D$69,$A77,$L$30:$L$69,"2025/26") -> 0 | E77: =SUMIFS($J$30:$J$69,$D$30:$D$69,$A77,$L$30:$L$69,"2026/27") -> 0
...

Sheet 2025-08
A1: 2025年8月 | J1: 今月のレート 1£＝ | L1: =IF(為替レート!$B$9="","未入力",為替レート!$B$9) -> 未入力
A2: 黄色＝記入／緑＝自動計算。円の支払いは「為替レート」タブのレートで自動換算（実際の£額があればそちらを優先）。
A4: 【収入】仕事の入金（入金した日で記録）
A5: 日付 | B5: 取引先 | C5: 内容 | D5: 入金方法 | E5: 通貨 | F5: 元の金額 | G5: 実際の£額 (分かれば) | H5: 金額(£) 自動 | I5: 請求書No. | J5: 税年度 自動 | N5: メモ
H6: =IF(F6="","",IF(G6<>"",G6,IF(E6="JPY",IF(ISNUMBER($L$1),ROUND(F6/$L$1,2),"レート未入力"),F6))) | J6: =IF(A6="","",IF(A6<DATE(2025,4,6),"2024/25",IF(A6<DATE(2026,4,6),"2025/26",IF(A6<DATE(2027,4,6),"2026/27","2027/28"))))
H7: =IF(F7="","",IF(G7<>"",G7,IF(E7="JPY",IF(ISNUMBER($L$1),ROUND(F7/$L$1,2),"レート未入力"),F7))) | J7: =IF(A7="","",IF(A7<DATE(2025,4,6),"2024/25",IF(A7<DATE(2026,4,6),"2025/26",IF(A7<DATE(2027,4,6),"2026/27","2027/28"))))
H8: =IF(F8="","",IF(G8<>"",G8,IF(E8="JPY",IF(ISNUMBER($L$1),ROUND(F8/$L$1,2),"レート未入力"),F8))) | J8: =IF(A8="","",IF(A8<DATE(2025,4,6),"2024/25",IF(A8<DATE(2026,4,6),"2025/26",IF(A8<DATE(2027,4,6),"2026/27","2027/28"))))
H9: =IF(F9="","",IF(G9<>"",G9,IF(E9="JPY",IF(ISNUMBER($L$1),ROUND(F9/$L$1,2),"レート未入力"),F9))) | J9: =IF(A9="","",IF(A9<DATE(2025,4,6),"2024/25",IF(A9<DATE(2026,4,6),"2025/26",IF(A9<DATE(2027,4,6),"2026/27","2027/28"))))
H10: =IF(F10="","",IF(G10<>"",G10,IF(E10="JPY",IF(ISNUMBER($L$1),ROUND(F10/$L$1,2),"レート未入力"),F10))) | J10: =IF(A10="","",IF(A10<DATE(2025,4,6),"2024/25",IF(A10<DATE(2026,4,6),"2025/26",IF(A10<DATE(2027,4,6),"2026/27","2027/28"))))
H11: =IF(F11="","",IF(G11<>"",G11,IF(E11="JPY",IF(ISNUMBER($L$1),ROUND(F11/$L$1,2),"レート未入力"),F11))) | J11: =IF(A11="","",IF(A11<DATE(2025,4,6),"2024/25",IF(A11<DATE(2026,4,6),"2025/26",IF(A11<DATE(2027,4,6),"2026/27","2027/28"))))
H12: =IF(F12="","",IF(G12<>"",G12,IF(E12="JPY",IF(ISNUMBER($L$1),ROUND(F12/$L$1,2),"レート未入力"),F12))) | J12: =IF(A12="","",IF(A12<DATE(2025,4,6),"2024/25",IF(A12<DATE(2026,4,6),"2025/26",IF(A12<DATE(2027,4,6),"2026/27","2027/28"))))
H13: =IF(F13="","",IF(G13<>"",G13,IF(E13="JPY",IF(ISNUMBER($L$1),ROUND(F13/$L$1,2),"レート未入力"),F13))) | J13: =IF(A13="","",IF(A13<DATE(2025,4,6),"2024/25",IF(A13<DATE(2026,4,6),"2025/26",IF(A13<DATE(2027,4,6),"2026/27","2027/28"))))
H14: =IF(F14="","",IF(G14<>"",G14,IF(E14="JPY",IF(ISNUMBER($L$1),ROUND(F14/$L$1,2),"レート未入力"),F14))) | J14: =IF(A14="","",IF(A14<DATE(2025,4,6),"2024/25",IF(A14<DATE(2026,4,6),"2025/26",IF(A14<DATE(2027,4,6),"2026/27","2027/28"))))
H15: =IF(F15="","",IF(G15<>"",G15,IF(E15="JPY",IF(ISNUMBER($L$1),ROUND(F15/$L$1,2),"レート未入力"),F15))) | J15: =IF(A15="","",IF(A15<DATE(2025,4,6),"2024/25",IF(A15<DATE(2026,4,6),"2025/26",IF(A15<DATE(2027,4,6),"2026/27","2027/28"))))
H16: =IF(F16="","",IF(G16<>"",G16,IF(E16="JPY",IF(ISNUMBER($L$1),ROUND(F16/$L$1,2),"レート未入力"),F16))) | J16: =IF(A16="","",IF(A16<DATE(2025,4,6),"2024/25",IF(A16<DATE(2026,4,6),"2025/26",IF(A16<DATE(2027,4,6),"2026/27","2027/28"))))
H17: =IF(F17="","",IF(G17<>"",G17,IF(E17="JPY",IF(ISNUMBER($L$1),ROUND(F17/$L$1,2),"レート未入力"),F17))) | J17: =IF(A17="","",IF(A17<DATE(2025,4,6),"2024/25",IF(A17<DATE(2026,4,6),"2025/26",IF(A17<DATE(2027,4,6),"2026/27","2027/28"))))
... H25: =IF(F25="","",IF(G25<>"",G25,IF(E25="JPY",IF(ISNUMBER($L$1),ROUND(F25/$L$1,2),"レート未入力"),F25))) | J25: =IF(A25="","",IF(A25<DATE(2025,4,6),"2024/25",IF(A25<DATE(2026,4,6),"2025/26",IF(A25<DATE(2027,4,6),"2026/27","2027/28"))))
A26: 収入合計 | H26: =SUM(H6:H25) -> 0
A28: 【経費】仕事で支払った費用（支払った日で記録・領収書を保管）
A29: 日付 | B29: 支払先 | C29: 内容 | D29: カテゴリ | E29: 通貨 | F29: 元の金額 | G29: 実際の£額 (分かれば) | H29: £換算額 自動 | I29: 事業使用率 (空欄=100%) | J29: 認定経費(£) 自動 | K29: 領収書 ○ | L29: 税年度 自動 | N29: メモ
H30: =IF(F30="","",IF(G30<>"",G30,IF(E30="JPY",IF(ISNUMBER($L$1),ROUND(F30/$L$1,2),"レート未入力"),F30))) | J30: =IF(ISNUMBER(H30),ROUND(H30*IF(I30="",1,I30),2),"") | L30: =IF(A30="","",IF(A30<DATE(2025,4,6),"2024/25",IF(A30<DATE(2026,4,6),"2025/26",IF(A30<DATE(2027,4,6),"2026/27","2027/28"))))
H31: =IF(F31="","",IF(G31<>"",G31,IF(E31="JPY",IF(ISNUMBER($L$1),ROUND(F31/$L$1,2),"レート未入力"),F31))) | J31: =IF(ISNUMBER(H31),ROUND(H31*IF(I31="",1,I31),2),"") | L31: =IF(A31="","",IF(A31<DATE(2025,4,6),"2024/25",IF(A31<DATE(2026,4,6),"2025/26",IF(A31<DATE(2027,4,6),"2026/27","2027/28"))))
H32: =IF(F32="","",IF(G32<>"",G32,IF(E32="JPY",IF(ISNUMBER($L$1),ROUND(F32/$L$1,2),"レート未入力"),F32))) | J32: =IF(ISNUMBER(H32),ROUND(H32*IF(I32="",1,I32),2),"") | L32: =IF(A32="","",IF(A32<DATE(2025,4,6),"2024/25",IF(A32<DATE(2026,4,6),"2025/26",IF(A32<DATE(2027,4,6),"2026/27","2027/28"))))
H33: =IF(F33="","",IF(G33<>"",G33,IF(E33="JPY",IF(ISNUMBER($L$1),ROUND(F33/$L$1,2),"レート未入力"),F33))) | J33: =IF(ISNUMBER(H33),ROUND(H33*IF(I33="",1,I33),2),"") | L33: =IF(A33="","",IF(A33<DATE(2025,4,6),"2024/25",IF(A33<DATE(2026,4,6),"2025/26",IF(A33<DATE(2027,4,6),"2026/27","2027/28"))))
H34: =IF(F34="","",IF(G34<>"",G34,IF(E34="JPY",IF(ISNUMBER($L$1),ROUND(F34/$L$1,2),"レート未入力"),F34))) | J34: =IF(ISNUMBER(H34),ROUND(H34*IF(I34="",1,I34),2),"") | L34: =IF(A34="","",IF(A34<DATE(2025,4,6),"2024/25",IF(A34<DATE(2026,4,6),"2025/26",IF(A34<DATE(2027,4,6),"2026/27","2027/28"))))
H35: =IF(F35="","",IF(G35<>"",G35,IF(E35="JPY",IF(ISNUMBER($L$1),ROUND(F35/$L$1,2),"レート未入力"),F35))) | J35: =IF(ISNUMBER(H35),ROUND(H35*IF(I35="",1,I35),2),"") | L35: =IF(A35="","",IF(A35<DATE(2025,4,6),"2024/25",IF(A35<DATE(2026,4,6),"2025/26",IF(A35<DATE(2027,4,6),"2026/27","2027/28"))))
H36: =IF(F36="","",IF(G36<>"",G36,IF(E36="JPY",IF(ISNUMBER($L$1),ROUND(F36/$L$1,2),"レート未入力"),F36))) | J36: =IF(ISNUMBER(H36),ROUND(H36*IF(I36="",1,I36),2),"") | L36: =IF(A36="","",IF(A36<DATE(2025,4,6),"2024/25",IF(A36<DATE(2026,4,6),"2025/26",IF(A36<DATE(2027,4,6),"2026/27","2027/28"))))
H37: =IF(F37="","",IF(G37<>"",G37,IF(E37="JPY",IF(ISNUMBER($L$1),ROUND(F37/$L$1,2),"レート未入力"),F37))) | J37: =IF(ISNUMBER(H37),ROUND(H37*IF(I37="",1,I37),2),"") | L37: =IF(A37="","",IF(A37<DATE(2025,4,6),"2024/25",IF(A37<DATE(2026,4,6),"2025/26",IF(A37<DATE(2027,4,6),"2026/27","2027/28"))))
H38: =IF(F38="","",IF(G38<>"",G38,IF(E38="JPY",IF(ISNUMBER($L$1),ROUND(F38/$L$1,2),"レート未入力"),F38))) | J38: =IF(ISNUMBER(H38),ROUND(H38*IF(I38="",1,I38),2),"") | L38: =IF(A38="","",IF(A38<DATE(2025,4,6),"2024/25",IF(A38<DATE(2026,4,6),"2025/26",IF(A38<DATE(2027,4,6),"2026/27","2027/28"))))
H39: =IF(F39="","",IF(G39<>"",G39,IF(E39="JPY",IF(ISNUMBER($L$1),ROUND(F39/$L$1,2),"レート未入力"),F39))) | J39: =IF(ISNUMBER(H39),ROUND(H39*IF(I39="",1,I39),2),"") | L39: =IF(A39="","",IF(A39<DATE(2025,4,6),"2024/25",IF(A39<DATE(2026,4,6),"2025/26",IF(A39<DATE(2027,4,6),"2026/27","2027/28"))))
H40: =IF(F40="","",IF(G40<>"",G40,IF(E40="JPY",IF(ISNUMBER($L$1),ROUND(F40/$L$1,2),"レート未入力"),F40))) | J40: =IF(ISNUMBER(H40),ROUND(H40*IF(I40="",1,I40),2),"") | L40: =IF(A40="","",IF(A40<DATE(2025,4,6),"2024/25",IF(A40<DATE(2026,4,6),"2025/26",IF(A40<DATE(2027,4,6),"2026/27","2027/28"))))
H41: =IF(F41="","",IF(G41<>"",G41,IF(E41="JPY",IF(ISNUMBER($L$1),ROUND(F41/$L$1,2),"レート未入力"),F41))) | J41: =IF(ISNUMBER(H41),ROUND(H41*IF(I41="",1,I41),2),"") | L41: =IF(A41="","",IF(A41<DATE(2025,4,6),"2024/25",IF(A41<DATE(2026,4,6),"2025/26",IF(A41<DATE(2027,4,6),"2026/27","2027/28"))))
... H69: =IF(F69="","",IF(G69<>"",G69,IF(E69="JPY",IF(ISNUMBER($L$1),ROUND(F69/$L$1,2),"レート未入力"),F69))) | J69: =IF(ISNUMBER(H69),ROUND(H69*IF(I69="",1,I69),2),"") | L69: =IF(A69="","",IF(A69<DATE(2025,4,6),"2024/25",IF(A69<DATE(2026,4,6),"2025/26",IF(A69<DATE(2027,4,6),"2026/27","2027/28"))))
A70: 支払合計（按分後・機材含む） | J70: =SUM(J30:J69) -> 0
A72: 【月まとめ（税年度別）】自動計算
A73: 項目 | D73: 2025/26 | E73: 2026/27
A74: 収入合計 | D74: =SUMIFS($H$6:$H$25,$J$6:$J$25,"2025/26") -> 0 | E74: =SUMIFS($H$6:$H$25,$J$6:$J$25,"2026/27") -> 0
A75: 外注費・仕入 | D75: =SUMIFS($J$30:$J$69,$D$30:$D$69,$A75,$L$30:$L$69,"2025/26") -> 0 | E75: =SUMIFS($J$30:$J$69,$D$30:$D$69,$A75,$L$30:$L$69,"2026/27") -> 0
A76: 給与・スタッフ費 | D76: =SUMIFS($J$30:$J$69,$D$30:$D$69,$A76,$L$30:$L$69,"2025/26") -> 0 | E76: =SUMIFS($J$30:$J$69,$D$30:$D$69,$A76,$L$30:$L$69,"2026/27") -> 0
A77: 交通費・車両費 | D77: =SUMIFS($J$30:$J$69,$D$30:$D$69,$A77,$L$30:$L$69,"2025/26") -> 0 | E77: =SUMIFS($J$30:$J$69,$D$30:$D$69,$A77,$L$30:$L$69,"2026/27") -> 0
...

Sheet 2025-09
A1: 2025年9月 | J1: 今月のレート 1£＝ | L1: =IF(為替レート!$B$10="","未入力",為替レート!$B$10) -> 未入力
A2: 黄色＝記入／緑＝自動計算。円の支払いは「為替レート」タブのレートで自動換算（実際の£額があればそちらを優先）。
A4: 【収入】仕事の入金（入金した日で記録）
A5: 日付 | B5: 取引先 | C5: 内容 | D5: 入金方法 | E5: 通貨 | F5: 元の金額 | G5: 実際の£額 (分かれば) | H5: 金額(£) 自動 | I5: 請求書No. | J5: 税年度 自動 | N5: メモ
H6: =IF(F6="","",IF(G6<>"",G6,IF(E6="JPY",IF(ISNUMBER($L$1),ROUND(F6/$L$1,2),"レート未入力"),F6))) | J6: =IF(A6="","",IF(A6<DATE(2025,4,6),"2024/25",IF(A6<DATE(2026,4,6),"2025/26",IF(A6<DATE(2027,4,6),"2026/27","2027/28"))))
H7: =IF(F7="","",IF(G7<>"",G7,IF(E7="JPY",IF(ISNUMBER($L$1),ROUND(F7/$L$1,2),"レート未入力"),F7))) | J7: =IF(A7="","",IF(A7<DATE(2025,4,6),"2024/25",IF(A7<DATE(2026,4,6),"2025/26",IF(A7<DATE(2027,4,6),"2026/27","2027/28"))))
H8: =IF(F8="","",IF(G8<>"",G8,IF(E8="JPY",IF(ISNUMBER($L$1),ROUND(F8/$L$1,2),"レート未入力"),F8))) | J8: =IF(A8="","",IF(A8<DATE(2025,4,6),"2024/25",IF(A8<DATE(2026,4,6),"2025/26",IF(A8<DATE(2027,4,6),"2026/27","2027/28"))))
H9: =IF(F9="","",IF(G9<>"",G9,IF(E9="JPY",IF(ISNUMBER($L$1),ROUND(F9/$L$1,2),"レート未入力"),F9))) | J9: =IF(A9="","",IF(A9<DATE(2025,4,6),"2024/25",IF(A9<DATE(2026,4,6),"2025/26",IF(A9<DATE(2027,4,6),"2026/27","2027/28"))))
H10: =IF(F10="","",IF(G10<>"",G10,IF(E10="JPY",IF(ISNUMBER($L$1),ROUND(F10/$L$1,2),"レート未入力"),F10))) | J10: =IF(A10="","",IF(A10<DATE(2025,4,6),"2024/25",IF(A10<DATE(2026,4,6),"2025/26",IF(A10<DATE(2027,4,6),"2026/27","2027/28"))))
H11: =IF(F11="","",IF(G11<>"",G11,IF(E11="JPY",IF(ISNUMBER($L$1),ROUND(F11/$L$1,2),"レート未入力"),F11))) | J11: =IF(A11="","",IF(A11<DATE(2025,4,6),"2024/25",IF(A11<DATE(2026,4,6),"2025/26",IF(A11<DATE(2027,4,6),"2026/27","2027/28"))))
H12: =IF(F12="","",IF(G12<>"",G12,IF(E12="JPY",IF(ISNUMBER($L$1),ROUND(F12/$L$1,2),"レート未入力"),F12))) | J12: =IF(A12="","",IF(A12<DATE(2025,4,6),"2024/25",IF(A12<DATE(2026,4,6),"2025/26",IF(A12<DATE(2027,4,6),"2026/27","2027/28"))))
H13: =IF(F13="","",IF(G13<>"",G13,IF(E13="JPY",IF(ISNUMBER($L$1),ROUND(F13/$L$1,2),"レート未入力"),F13))) | J13: =IF(A13="","",IF(A13<DATE(2025,4,6),"2024/25",IF(A13<DATE(2026,4,6),"2025/26",IF(A13<DATE(2027,4,6),"2026/27","2027/28"))))
H14: =IF(F14="","",IF(G14<>"",G14,IF(E14="JPY",IF(ISNUMBER($L$1),ROUND(F14/$L$1,2),"レート未入力"),F14))) | J14: =IF(A14="","",IF(A14<DATE(2025,4,6),"2024/25",IF(A14<DATE(2026,4,6),"2025/26",IF(A14<DATE(2027,4,6),"2026/27","2027/28"))))
