Workbook

Sheet LINE登録数
A1: 日付 | B1: 曜日 | C1: LINE登録数 | D1: 累計 | E1: 📝 その日の投稿内容 | F1: 投稿先 | G1: メモ
A2: 46296 | B2: 木 | D2: =IF(C2="","",SUM($C$2:C2))
A3: 46297 | B3: 金 | D3: =IF(C3="","",SUM($C$2:C3))
A4: 46298 | B4: 土 | D4: =IF(C4="","",SUM($C$2:C4))
A5: 46299 | B5: 日 | D5: =IF(C5="","",SUM($C$2:C5))
A6: 46300 | B6: 月 | D6: =IF(C6="","",SUM($C$2:C6))
A7: 46301 | B7: 火 | D7: =IF(C7="","",SUM($C$2:C7))
A8: 46302 | B8: 水 | D8: =IF(C8="","",SUM($C$2:C8))
A9: 46303 | B9: 木 | D9: =IF(C9="","",SUM($C$2:C9))
A10: 46304 | B10: 金 | D10: =IF(C10="","",SUM($C$2:C10))
A11: 46305 | B11: 土 | D11: =IF(C11="","",SUM($C$2:C11))
A12: 46306 | B12: 日 | D12: =IF(C12="","",SUM($C$2:C12))
A13: 46307 | B13: 月 | D13: =IF(C13="","",SUM($C$2:C13))
... A183: 46477 | B183: 水 | D183: =IF(C183="","",SUM($C$2:C183))

Sheet 月別まとめ
A1: 月 | B1: LINE登録数（合計） | C1: 1日平均 | D1: ストーリーズ本数 | E1: 閲覧数（合計） | F1: 閲覧数（平均）
A2: 2026年10月 | B2: =SUMIFS('LINE登録数'!C:C,'LINE登録数'!A:A,">="&DATE(2026,10,1),'LINE登録数'!A:A,"<="&DATE(2026,10,31)) | C2: =ROUND(B2/31,1) | D2: =SUM('10月ストーリーズ'!C5:C97) | E2: =SUM('10月ストーリーズ'!D5:D97) | F2: =IFERROR(ROUND(E2/COUNT('10月ストーリーズ'!F5:O97),0),"")
A3: 2026年11月 | B3: =SUMIFS('LINE登録数'!C:C,'LINE登録数'!A:A,">="&DATE(2026,11,1),'LINE登録数'!A:A,"<="&DATE(2026,11,30)) | C3: =ROUND(B3/30,1) | D3: =SUM('11月ストーリーズ'!C5:C94) | E3: =SUM('11月ストーリーズ'!D5:D94) | F3: =IFERROR(ROUND(E3/COUNT('11月ストーリーズ'!F5:O94),0),"")
A4: 2026年12月 | B4: =SUMIFS('LINE登録数'!C:C,'LINE登録数'!A:A,">="&DATE(2026,12,1),'LINE登録数'!A:A,"<="&DATE(2026,12,31)) | C4: =ROUND(B4/31,1) | D4: =SUM('12月ストーリーズ'!C5:C97) | E4: =SUM('12月ストーリーズ'!D5:D97) | F4: =IFERROR(ROUND(E4/COUNT('12月ストーリーズ'!F5:O97),0),"")
A5: 2027年1月 | B5: =SUMIFS('LINE登録数'!C:C,'LINE登録数'!A:A,">="&DATE(2027,1,1),'LINE登録数'!A:A,"<="&DATE(2027,1,31)) | C5: =ROUND(B5/31,1) | D5: =SUM('1月ストーリーズ'!C5:C97) | E5: =SUM('1月ストーリーズ'!D5:D97) | F5: =IFERROR(ROUND(E5/COUNT('1月ストーリーズ'!F5:O97),0),"")
A6: 2027年2月 | B6: =SUMIFS('LINE登録数'!C:C,'LINE登録数'!A:A,">="&DATE(2027,2,1),'LINE登録数'!A:A,"<="&DATE(2027,2,28)) | C6: =ROUND(B6/28,1) | D6: =SUM('2月ストーリーズ'!C5:C88) | E6: =SUM('2月ストーリーズ'!D5:D88) | F6: =IFERROR(ROUND(E6/COUNT('2月ストーリーズ'!F5:O88),0),"")
A7: 2027年3月 | B7: =SUMIFS('LINE登録数'!C:C,'LINE登録数'!A:A,">="&DATE(2027,3,1),'LINE登録数'!A:A,"<="&DATE(2027,3,31)) | C7: =ROUND(B7/31,1) | D7: =SUM('3月ストーリーズ'!C5:C97) | E7: =SUM('3月ストーリーズ'!D5:D97) | F7: =IFERROR(ROUND(E7/COUNT('3月ストーリーズ'!F5:O97),0),"")

Sheet 10月ストーリーズ
A1: 2026年10月 ストーリーズ記録
F2: 本数 | G2: 閲覧数合計 | H2: 閲覧数平均 | I2: 最高閲覧数
F3: =SUM(C5:C97) | G3: =SUM(D5:D97) | H3: =IFERROR(ROUND(SUM(D5:D97)/COUNT(F5:O97),0),"") | I3: =IF(COUNT(F5:O97)=0,"",MAX(F5:O97))
A4: 日付 | B4: 曜日 | C4: 本数 | D4: 閲覧数合計 | F4: 1枚目 | G4: 2枚目 | H4: 3枚目 | I4: 4枚目 | J4: 5枚目 | K4: 6枚目 | L4: 7枚目 | M4: 8枚目 | N4: 9枚目 | O4: 10枚目
A5: 46296 | B5: 木 | C5: =COUNTA(F6:O6) | D5: =SUM(F7:O7) | E5: 📷
E6: 内容 | F6: ポッドキャスト更新 #3 負け癖からの脱却 | G6: YouTubeに届いたコメント（社会人は時間がないから伸びない？→答えはNO） | H6: 個別学習相談に来られる方々からの声（つまり…） | I6: 正しい方向に最短で進める仕組みが必要／IELTS個別学習相談リンク
E7: 閲覧数
A8: 46297 | B8: 金 | C8: =COUNTA(F9:O9) | D8: =SUM(F10:O10) | E8: 📷
E9: 内容 | F9: 今週早速一歩踏み出したみなさま（相談申込みフォーム通知） | G9: 完璧を待っていたら何も始まらない／「気になる」DM誘導
E10: 閲覧数
A11: 46298 | B11: 土 | C11: =COUNTA(F12:O12) | D11: =SUM(F13:O13) | E11: 📷
E12: 内容 | F12: 惜しい!! ライティングの勉強法を変えたら伸びる人 | G12: 評価基準に沿った書き方を知らないから | H12: 頑張りどころを間違えなければ／書き方の方法知りたい？（😍スタンプ）
E13: 閲覧数
A14: 46299 | B14: 日 | C14: =COUNTA(F15:O15) | D14: =SUM(F16:O16) | E14: 📷
E15: 内容 | F15: 昨日のリアクションありがとう→3ステップで解説 | G15: ステップ1：評価基準に沿ったライティング教材を選ぶ | H15: ステップ2：タスクごとの書き方ルールをインプット | I15: ステップ3：ルール確認のために書く／受講生の声 | J15: 動画講座：全9コース・100本以上 | K15: 1本5分以内／W5.5→6.5受講生インタビューリンク | L15: ライブ告知（22時〜 タスク2「書くことがない」を解決）
E16: 閲覧数
A17: 46300 | B17: 月 | C17: =COUNTA(F18:O18) | D17: =SUM(F19:O19) | E17: 📷
E18: 内容 | F18: YouTube台本は自分で作ってる（今週末公開の動画から→） | G18: スライド追加で見やすく／土曜日の公開をお楽しみに
E19: 閲覧数
A20: 46301 | B20: 火 | C20: =COUNTA(F21:O21) | D20: =SUM(F22:O22) | E20: 📷
E21: 内容 | F21: 春にOA5.0→6.5以上を達成したい／個別学習相談が増えました | G21: 大学院奨学金応募に向けてラストスパート
E22: 閲覧数
A23: 46302 | B23: 水 | C23: =COUNTA(F24:O24) | D23: =SUM(F25:O25) | E23: 📷
E24: 内容
E25: 閲覧数
A26: 46303 | B26: 木 | C26: =COUNTA(F27:O27) | D26: =SUM(F28:O28) | E26: 📷
E27: 内容 | F27: 「テンプレートもらえますか？」→お渡ししていません | G27: テンプレート通りに書いてもスコアは上がらないから | H27: 受講生の例：テンプレをやめて3ヶ月で6.0→6.5 | I27: 半年後、差がつく人とつかない人
E28: 閲覧数
A29: 46304 | B29: 金 | C29: =COUNTA(F30:O30) | D29: =SUM(F31:O31) | E29: 📷
E30: 内容 | F30: テーマ関連語彙を覚えるのは一種のギャンブル（音声あり） | G30: YouTube動画公開：スコアが一気に伸びる人の特徴
E31: 閲覧数
A32: 46305 | B32: 土 | C32: =COUNTA(F33:O33) | D32: =SUM(F34:O34) | E32: 📷
E33: 内容 | F33: 嬉しいお知らせが届きました | G33: 2ヶ月で3技能ベストスコア更新（高校生） | H33: やる気にもつながってます／次の目標
E34: 閲覧数
A35: 46306 | B35: 日 | C35: =COUNTA(F36:O36) | D35: =SUM(F37:O37) | E35: 📷
E36: 内容 | F36: こんなこと言われたら泣いてしまう | G36: 娘の良き先生になってくれそう（相談の感想） | H36: ライブ告知（22時〜 手遅れになる前に知っておくべきこと）
E37: 閲覧数
A38: 46307 | B38: 月 | C38: =COUNTA(F39:O39) | D38: =SUM(F40:O40) | E38: 📷
E39: 内容 | F39: 「苦手」を観察すると本当の課題が見えてくる（相談の感想）
E40: 閲覧数
...

Sheet 11月ストーリーズ
A1: 2026年11月 ストーリーズ記録
F2: 本数 | G2: 閲覧数合計 | H2: 閲覧数平均 | I2: 最高閲覧数
F3: =SUM(C5:C94) | G3: =SUM(D5:D94) | H3: =IFERROR(ROUND(SUM(D5:D94)/COUNT(F5:O94),0),"") | I3: =IF(COUNT(F5:O94)=0,"",MAX(F5:O94))
A4: 日付 | B4: 曜日 | C4: 本数 | D4: 閲覧数合計 | F4: 1枚目 | G4: 2枚目 | H4: 3枚目 | I4: 4枚目 | J4: 5枚目 | K4: 6枚目 | L4: 7枚目 | M4: 8枚目 | N4: 9枚目 | O4: 10枚目
A5: 46327 | B5: 日 | C5: =COUNTA(F6:O6) | D5: =SUM(F7:O7) | E5: 📷
E6: 内容
E7: 閲覧数
A8: 46328 | B8: 月 | C8: =COUNTA(F9:O9) | D8: =SUM(F10:O10) | E8: 📷
E9: 内容
E10: 閲覧数
A11: 46329 | B11: 火 | C11: =COUNTA(F12:O12) | D11: =SUM(F13:O13) | E11: 📷
E12: 内容
E13: 閲覧数
A14: 46330 | B14: 水 | C14: =COUNTA(F15:O15) | D14: =SUM(F16:O16) | E14: 📷
E15: 内容
E16: 閲覧数
A17: 46331 | B17: 木 | C17: =COUNTA(F18:O18) | D17: =SUM(F19:O19) | E17: 📷
E18: 内容
E19: 閲覧数
A20: 46332 | B20: 金 | C20: =COUNTA(F21:O21) | D20: =SUM(F22:O22) | E20: 📷
E21: 内容
E22: 閲覧数
A23: 46333 | B23: 土 | C23: =COUNTA(F24:O24) | D23: =SUM(F25:O25) | E23: 📷
E24: 内容
E25: 閲覧数
A26: 46334 | B26: 日 | C26: =COUNTA(F27:O27) | D26: =SUM(F28:O28) | E26: 📷
E27: 内容
E28: 閲覧数
A29: 46335 | B29: 月 | C29: =COUNTA(F30:O30) | D29: =SUM(F31:O31) | E29: 📷
E30: 内容
E31: 閲覧数
A32: 46336 | B32: 火 | C32: =COUNTA(F33:O33) | D32: =SUM(F34:O34) | E32: 📷
E33: 内容
E34: 閲覧数
A35: 46337 | B35: 水 | C35: =COUNTA(F36:O36) | D35: =SUM(F37:O37) | E35: 📷
E36: 内容
E37: 閲覧数
A38: 46338 | B38: 木 | C38: =COUNTA(F39:O39) | D38: =SUM(F40:O40) | E38: 📷
E39: 内容
E40: 閲覧数
...

Sheet 12月ストーリーズ
A1: 2026年12月 ストーリーズ記録
F2: 本数 | G2: 閲覧数合計 | H2: 閲覧数平均 | I2: 最高閲覧数
F3: =SUM(C5:C97) | G3: =SUM(D5:D97) | H3: =IFERROR(ROUND(SUM(D5:D97)/COUNT(F5:O97),0),"") | I3: =IF(COUNT(F5:O97)=0,"",MAX(F5:O97))
A4: 日付 | B4: 曜日 | C4: 本数 | D4: 閲覧数合計 | F4: 1枚目 | G4: 2枚目 | H4: 3枚目 | I4: 4枚目 | J4: 5枚目 | K4: 6枚目 | L4: 7枚目 | M4: 8枚目 | N4: 9枚目 | O4: 10枚目
A5: 46357 | B5: 火 | C5: =COUNTA(F6:O6) | D5: =SUM(F7:O7) | E5: 📷
E6: 内容
E7: 閲覧数
A8: 46358 | B8: 水 | C8: =COUNTA(F9:O9) | D8: =SUM(F10:O10) | E8: 📷
E9: 内容
E10: 閲覧数
A11: 46359 | B11: 木 | C11: =COUNTA(F12:O12) | D11: =SUM(F13:O13) | E11: 📷
E12: 内容
E13: 閲覧数
A14: 46360 | B14: 金 | C14: =COUNTA(F15:O15) | D14: =SUM(F16:O16) | E14: 📷
E15: 内容
E16: 閲覧数
A17: 46361 | B17: 土 | C17: =COUNTA(F18:O18) | D17: =SUM(F19:O19) | E17: 📷
E18: 内容
E19: 閲覧数
A20: 46362 | B20: 日 | C20: =COUNTA(F21:O21) | D20: =SUM(F22:O22) | E20: 📷
E21: 内容
E22: 閲覧数
A23: 46363 | B23: 月 | C23: =COUNTA(F24:O24) | D23: =SUM(F25:O25) | E23: 📷
E24: 内容
E25: 閲覧数
A26: 46364 | B26: 火 | C26: =COUNTA(F27:O27) | D26: =SUM(F28:O28) | E26: 📷
E27: 内容
E28: 閲覧数
A29: 46365 | B29: 水 | C29: =COUNTA(F30:O30) | D29: =SUM(F31:O31) | E29: 📷
E30: 内容
E31: 閲覧数
A32: 46366 | B32: 木 | C32: =COUNTA(F33:O33) | D32: =SUM(F34:O34) | E32: 📷
E33: 内容
E34: 閲覧数
A35: 46367 | B35: 金 | C35: =COUNTA(F36:O36) | D35: =SUM(F37:O37) | E35: 📷
E36: 内容
E37: 閲覧数
A38: 46368 | B38: 土 | C38: =COUNTA(F39:O39) | D38: =SUM(F40:O40) | E38: 📷
E39: 内容
E40: 閲覧数
...

Sheet 1月ストーリーズ
A1: 2027年1月 ストーリーズ記録
F2: 本数 | G2: 閲覧数合計 | H2: 閲覧数平均 | I2: 最高閲覧数
F3: =SUM(C5:C97) | G3: =SUM(D5:D97) | H3: =IFERROR(ROUND(SUM(D5:D97)/COUNT(F5:O97),0),"") | I3: =IF(COUNT(F5:O97)=0,"",MAX(F5:O97))
A4: 日付 | B4: 曜日 | C4: 本数 | D4: 閲覧数合計 | F4: 1枚目 | G4: 2枚目 | H4: 3枚目 | I4: 4枚目 | J4: 5枚目 | K4: 6枚目 | L4: 7枚目 | M4: 8枚目 | N4: 9枚目 | O4: 10枚目
A5: 46388 | B5: 金 | C5: =COUNTA(F6:O6) | D5: =SUM(F7:O7) | E5: 📷
E6: 内容
E7: 閲覧数
A8: 46389 | B8: 土 | C8: =COUNTA(F9:O9) | D8: =SUM(F10:O10) | E8: 📷
E9: 内容
E10: 閲覧数
A11: 46390 | B11: 日 | C11: =COUNTA(F12:O12) | D11: =SUM(F13:O13) | E11: 📷
E12: 内容
E13: 閲覧数
A14: 46391 | B14: 月 | C14: =COUNTA(F15:O15) | D14: =SUM(F16:O16) | E14: 📷
E15: 内容
E16: 閲覧数
A17: 46392 | B17: 火 | C17: =COUNTA(F18:O18) | D17: =SUM(F19:O19) | E17: 📷
E18: 内容
E19: 閲覧数
A20: 46393 | B20: 水 | C20: =COUNTA(F21:O21) | D20: =SUM(F22:O22) | E20: 📷
E21: 内容
E22: 閲覧数
A23: 46394 | B23: 木 | C23: =COUNTA(F24:O24) | D23: =SUM(F25:O25) | E23: 📷
E24: 内容
E25: 閲覧数
A26: 46395 | B26: 金 | C26: =COUNTA(F27:O27) | D26: =SUM(F28:O28) | E26: 📷
E27: 内容
E28: 閲覧数
A29: 46396 | B29: 土 | C29: =COUNTA(F30:O30) | D29: =SUM(F31:O31) | E29: 📷
E30: 内容
E31: 閲覧数
A32: 46397 | B32: 日 | C32: =COUNTA(F33:O33) | D32: =SUM(F34:O34) | E32: 📷
E33: 内容
E34: 閲覧数
A35: 46398 | B35: 月 | C35: =COUNTA(F36:O36) | D35: =SUM(F37:O37) | E35: 📷
E36: 内容
E37: 閲覧数
A38: 46399 | B38: 火 | C38: =COUNTA(F39:O39) | D38: =SUM(F40:O40) | E38: 📷
E39: 内容
E40: 閲覧数
...

Sheet 2月ストーリーズ
A1: 2027年2月 ストーリーズ記録
F2: 本数 | G2: 閲覧数合計 | H2: 閲覧数平均 | I2: 最高閲覧数
F3: =SUM(C5:C88) | G3: =SUM(D5:D88) | H3: =IFERROR(ROUND(SUM(D5:D88)/COUNT(F5:O88),0),"") | I3: =IF(COUNT(F5:O88)=0,"",MAX(F5:O88))
A4: 日付 | B4: 曜日 | C4: 本数 | D4: 閲覧数合計 | F4: 1枚目 | G4: 2枚目 | H4: 3枚目 | I4: 4枚目 | J4: 5枚目 | K4: 6枚目 | L4: 7枚目 | M4: 8枚目 | N4: 9枚目 | O4: 10枚目
A5: 46419 | B5: 月 | C5: =COUNTA(F6:O6) | D5: =SUM(F7:O7) | E5: 📷
E6: 内容
E7: 閲覧数
A8: 46420 | B8: 火 | C8: =COUNTA(F9:O9) | D8: =SUM(F10:O10) | E8: 📷
E9: 内容
E10: 閲覧数
A11: 46421 | B11: 水 | C11: =COUNTA(F12:O12) | D11: =SUM(F13:O13) | E11: 📷
E12: 内容
E13: 閲覧数
A14: 46422 | B14: 木 | C14: =COUNTA(F15:O15) | D14: =SUM(F16:O16) | E14: 📷
E15: 内容
E16: 閲覧数
A17: 46423 | B17: 金 | C17: =COUNTA(F18:O18) | D17: =SUM(F19:O19) | E17: 📷
E18: 内容
E19: 閲覧数
A20: 46424 | B20: 土 | C20: =COUNTA(F21:O21) | D20: =SUM(F22:O22) | E20: 📷
E21: 内容
E22: 閲覧数
A23: 46425 | B23: 日 | C23: =COUNTA(F24:O24) | D23: =SUM(F25:O25) | E23: 📷
E24: 内容
E25: 閲覧数
A26: 46426 | B26: 月 | C26: =COUNTA(F27:O27) | D26: =SUM(F28:O28) | E26: 📷
E27: 内容
E28: 閲覧数
A29: 46427 | B29: 火 | C29: =COUNTA(F30:O30) | D29: =SUM(F31:O31) | E29: 📷
E30: 内容
E31: 閲覧数
A32: 46428 | B32: 水 | C32: =COUNTA(F33:O33) | D32: =SUM(F34:O34) | E32: 📷
E33: 内容
E34: 閲覧数
A35: 46429 | B35: 木 | C35: =COUNTA(F36:O36) | D35: =SUM(F37:O37) | E35: 📷
E36: 内容
E37: 閲覧数
A38: 46430 | B38: 金 | C38: =COUNTA(F39:O39) | D38: =SUM(F40:O40) | E38: 📷
E39: 内容
E40: 閲覧数
...

Sheet 3月ストーリーズ
A1: 2027年3月 ストーリーズ記録
F2: 本数 | G2: 閲覧数合計 | H2: 閲覧数平均 | I2: 最高閲覧数
F3: =SUM(C5:C97) | G3: =SUM(D5:D97) | H3: =IFERROR(ROUND(SUM(D5:D97)/COUNT(F5:O97),0),"") | I3: =IF(COUNT(F5:O97)=0,"",MAX(F5:O97))
A4: 日付 | B4: 曜日 | C4: 本数 | D4: 閲覧数合計 | F4: 1枚目 | G4: 2枚目 | H4: 3枚目 | I4: 4枚目 | J4: 5枚目 | K4: 6枚目 | L4: 7枚目 | M4: 8枚目 | N4: 9枚目 | O4: 10枚目
A5: 46447 | B5: 月 | C5: =COUNTA(F6:O6) | D5: =SUM(F7:O7) | E5: 📷
E6: 内容
E7: 閲覧数
A8: 46448 | B8: 火 | C8: =COUNTA(F9:O9) | D8: =SUM(F10:O10) | E8: 📷
E9: 内容
E10: 閲覧数
A11: 46449 | B11: 水 | C11: =COUNTA(F12:O12) | D11: =SUM(F13:O13) | E11: 📷
E12: 内容
E13: 閲覧数
A14: 46450 | B14: 木 | C14: =COUNTA(F15:O15) | D14: =SUM(F16:O16) | E14: 📷
E15: 内容
E16: 閲覧数
A17: 46451 | B17: 金 | C17: =COUNTA(F18:O18) | D17: =SUM(F19:O19) | E17: 📷
E18: 内容
E19: 閲覧数
A20: 46452 | B20: 土 | C20: =COUNTA(F21:O21) | D20: =SUM(F22:O22) | E20: 📷
E21: 内容
E22: 閲覧数
A23: 46453 | B23: 日 | C23: =COUNTA(F24:O24) | D23: =SUM(F25:O25) | E23: 📷
E24: 内容
E25: 閲覧数
A26: 46454 | B26: 月 | C26: =COUNTA(F27:O27) | D26: =SUM(F28:O28) | E26: 📷
E27: 内容
E28: 閲覧数
A29: 46455 | B29: 火 | C29: =COUNTA(F30:O30) | D29: =SUM(F31:O31) | E29: 📷
E30: 内容
E31: 閲覧数
A32: 46456 | B32: 水 | C32: =COUNTA(F33:O33) | D32: =SUM(F34:O34) | E32: 📷
E33: 内容
E34: 閲覧数
A35: 46457 | B35: 木 | C35: =COUNTA(F36:O36) | D35: =SUM(F37:O37) | E35: 📷
E36: 内容
E37: 閲覧数
A38: 46458 | B38: 金 | C38: =COUNTA(F39:O39) | D38: =SUM(F40:O40) | E38: 📷
E39: 内容
E40: 閲覧数
...
