Workbook

Sheet テスト一覧
A1: IELTSリーディング テスト一覧（各テストシートから自動で集計）
A2: このシートは入力不要です。各「テスト」シートに記入すると自動で反映されます。テストを増やす時は「テスト5」シートをコピーし、この表に1行追加してください。
A4: シート | B4: テスト名 | C4: 解いた日 | D4: 分析日 | E4: 正解数 | F4: バンド目安 | G4: 語彙・文法 | H4: 情報検索 | I4: 論理・推論 | J4: 注意力・正確性 | K4: 次回の問題を解く日
A5: 記入例 | B5: =IF('記入例'!C4="","",'記入例'!C4) | C5: =IF('記入例'!C5="","",'記入例'!C5) | D5: =IF('記入例'!C6="","",'記入例'!C6) | E5: =IF(COUNTA('記入例'!D10:D49)=0,"",COUNTIF('記入例'!D10:D49,"正解")) | F5: ='記入例'!G5 | G5: ='記入例'!D53 | H5: ='記入例'!D54 | I5: ='記入例'!D55 | J5: ='記入例'!D56 | K5: =IF('記入例'!C118="","",'記入例'!C118)
A6: テスト1 | B6: =IF('テスト1'!C4="","",'テスト1'!C4) | C6: =IF('テスト1'!C5="","",'テスト1'!C5) | D6: =IF('テスト1'!C6="","",'テスト1'!C6) | E6: =IF(COUNTA('テスト1'!D10:D49)=0,"",COUNTIF('テスト1'!D10:D49,"正解")) | F6: ='テスト1'!G5 | G6: ='テスト1'!D53 | H6: ='テスト1'!D54 | I6: ='テスト1'!D55 | J6: ='テスト1'!D56 | K6: =IF('テスト1'!C118="","",'テスト1'!C118)
A7: テスト2 | B7: =IF('テスト2'!C4="","",'テスト2'!C4) | C7: =IF('テスト2'!C5="","",'テスト2'!C5) | D7: =IF('テスト2'!C6="","",'テスト2'!C6) | E7: =IF(COUNTA('テスト2'!D10:D49)=0,"",COUNTIF('テスト2'!D10:D49,"正解")) | F7: ='テスト2'!G5 | G7: ='テスト2'!D53 | H7: ='テスト2'!D54 | I7: ='テスト2'!D55 | J7: ='テスト2'!D56 | K7: =IF('テスト2'!C118="","",'テスト2'!C118)
A8: テスト3 | B8: =IF('テスト3'!C4="","",'テスト3'!C4) | C8: =IF('テスト3'!C5="","",'テスト3'!C5) | D8: =IF('テスト3'!C6="","",'テスト3'!C6) | E8: =IF(COUNTA('テスト3'!D10:D49)=0,"",COUNTIF('テスト3'!D10:D49,"正解")) | F8: ='テスト3'!G5 | G8: ='テスト3'!D53 | H8: ='テスト3'!D54 | I8: ='テスト3'!D55 | J8: ='テスト3'!D56 | K8: =IF('テスト3'!C118="","",'テスト3'!C118)
A9: テスト4 | B9: =IF('テスト4'!C4="","",'テスト4'!C4) | C9: =IF('テスト4'!C5="","",'テスト4'!C5) | D9: =IF('テスト4'!C6="","",'テスト4'!C6) | E9: =IF(COUNTA('テスト4'!D10:D49)=0,"",COUNTIF('テスト4'!D10:D49,"正解")) | F9: ='テスト4'!G5 | G9: ='テスト4'!D53 | H9: ='テスト4'!D54 | I9: ='テスト4'!D55 | J9: ='テスト4'!D56 | K9: =IF('テスト4'!C118="","",'テスト4'!C118)
A10: テスト5 | B10: =IF('テスト5'!C4="","",'テスト5'!C4) | C10: =IF('テスト5'!C5="","",'テスト5'!C5) | D10: =IF('テスト5'!C6="","",'テスト5'!C6) | E10: =IF(COUNTA('テスト5'!D10:D49)=0,"",COUNTIF('テスト5'!D10:D49,"正解")) | F10: ='テスト5'!G5 | G10: ='テスト5'!D53 | H10: ='テスト5'!D54 | I10: ='テスト5'!D55 | J10: ='テスト5'!D56 | K10: =IF('テスト5'!C118="","",'テスト5'!C118)
A11: ※ 語彙・文法〜注意力・正確性の列は、各テストの不正解の件数です。

Sheet 記入例
A1: IELTSリーディング 間違い分析シート（記入例）
A2: 使い方：黄色のセルに入力 → 正解/不正解・大カテゴリー・詳細理由はプルダウンで選択。集計と円グラフは自動で更新されます。
A4: テスト名 | C4: Cambridge 18 Test 1 | F4: 正解数 | G4: =COUNTIF(D10:D49,"正解")&" / 40"
A5: 解いた日 | C5: 46315 | F5: バンド目安（Academic） | G5: =IF(COUNTA(D10:D49)=0,"",LOOKUP(COUNTIF(D10:D49,"正解"),選択肢マスタ!$E$4:$E$15,選択肢マスタ!$F$4:$F$15))
A6: 分析日 | C6: 46316 | F6: Passage別 正解数 | G6: ="P1: "&COUNTIFS(B10:B49,1,D10:D49,"正解")&"/13 P2: "&COUNTIFS(B10:B49,2,D10:D49,"正解")&"/13 P3: "&COUNTIFS(B10:B49,3,D10:D49,"正解")&"/14"
A7: 解答時間（分） | C7: 62 | F7: 不正解数 | G7: =COUNTIF(D10:D49,"不正解")
A9: 問題番号 | B9: Passage | C9: 設問タイプ | D9: 正解/不正解 | E9: 大カテゴリー | F9: 詳細理由 | G9: 具体的に間違いが起きた箇所 | H9: 同じミスを繰り返さないために
A10: 1 | B10: 1 | C10: TRUE / FALSE / NOT GIVEN | D10: 正解
A11: 2 | B11: 1 | C11: TRUE / FALSE / NOT GIVEN | D11: 正解
A12: 3 | B12: 1 | C12: TRUE / FALSE / NOT GIVEN | D12: 不正解 | E12: 論理的思考・推論の問題 | F12: NOT GIVEN判定の誤り | G12: 本文に近い記述があったのでTRUEにしたが、頻度の情報は書かれていなかった | H12: 本文にない情報を自分の知識で補っていないか確認する
A13: 4 | B13: 1 | C13: TRUE / FALSE / NOT GIVEN | D13: 正解
A14: 5 | B14: 1 | C14: TRUE / FALSE / NOT GIVEN | D14: 正解
A15: 6 | B15: 1 | C15: TRUE / FALSE / NOT GIVEN | D15: 不正解 | E15: 論理的思考・推論の問題 | F15: 限定表現の見落とし | G15: 問題文の only / always を見落とした | H15: only・all・always などの限定語に○をつける
A16: 7 | B16: 1 | C16: TRUE / FALSE / NOT GIVEN | D16: 正解
A17: 8 | B17: 1 | C17: 表・ノート・フローチャート完成 | D17: 正解
A18: 9 | B18: 1 | C18: 表・ノート・フローチャート完成 | D18: 正解
A19: 10 | B19: 1 | C19: 表・ノート・フローチャート完成 | D19: 不正解 | E19: 注意力・正確性の問題 | F19: 単数形・複数形の間違い | G19: 正解は seeds なのに seed と書いた | H19: 転記後に冠詞・複数形を本文と照合する
A20: 11 | B20: 1 | C20: 表・ノート・フローチャート完成 | D20: 正解
A21: 12 | B21: 1 | C21: 表・ノート・フローチャート完成 | D21: 正解
A22: 13 | B22: 1 | C22: 表・ノート・フローチャート完成 | D22: 正解
A23: 14 | B23: 2 | C23: 見出し選択 (Headings) | D23: 正解
A24: 15 | B24: 2 | C24: 見出し選択 (Headings) | D24: 不正解 | E24: 語彙・文法理解の問題 | F24: 同義語・言い換え表現に気づけなかった | G24: decline が decrease の言い換えだと気づかなかった | H24: パラフレーズノートに追加して復習
A25: 16 | B25: 2 | C25: 見出し選択 (Headings) | D25: 正解
A26: 17 | B26: 2 | C26: 見出し選択 (Headings) | D26: 不正解 | E26: 情報検索・スキャニングの問題 | F26: 該当箇所を見つけられなかった | G26: 段落Dの主旨をつかめず見出しを決められなかった | H26: 各段落の1文目と最後の文を先に読む
A27: 18 | B27: 2 | C27: 見出し選択 (Headings) | D27: 正解
A28: 19 | B28: 2 | C28: 見出し選択 (Headings) | D28: 不正解 | E28: 語彙・文法理解の問題 | F28: 同義語・言い換え表現に気づけなかった | G28: feasible = possible と結びつかなかった | H28: パラフレーズノートに追加して復習
A29: 20 | B29: 2 | C29: 見出し選択 (Headings) | D29: 正解
A30: 21 | B30: 2 | C30: YES / NO / NOT GIVEN | D30: 正解
A31: 22 | B31: 2 | C31: YES / NO / NOT GIVEN | D31: 不正解 | E31: 論理的思考・推論の問題 | F31: NOT GIVEN判定の誤り | G31: 筆者の意見が書かれていないのにNOにした | H31: NO＝本文と逆の主張がある時だけ、と確認する
A32: 23 | B32: 2 | C32: YES / NO / NOT GIVEN | D32: 正解
A33: 24 | B33: 2 | C33: YES / NO / NOT GIVEN | D33: 正解
A34: 25 | B34: 2 | C34: YES / NO / NOT GIVEN | D34: 不正解 | E34: 論理的思考・推論の問題 | F34: 否定表現の見落とし | G34: hardly を見落として肯定文として読んだ | H34: 否定語（hardly, rarely, few）に線を引く
A35: 26 | B35: 2 | C35: YES / NO / NOT GIVEN | D35: 正解
A36: 27 | B36: 3 | C36: 多肢選択 (Multiple Choice) | D36: 正解
A37: 28 | B37: 3 | C37: 多肢選択 (Multiple Choice) | D37: 不正解 | E37: 語彙・文法理解の問題 | F37: 文法構造が複雑で理解できなかった | G37: 長い関係詞節で主語と動詞を取り違えた | H37: SVを先に見つけてから修飾部分を読む
A38: 29 | B38: 3 | C38: 多肢選択 (Multiple Choice) | D38: 正解
A39: 30 | B39: 3 | C39: 多肢選択 (Multiple Choice) | D39: 正解
A40: 31 | B40: 3 | C40: 多肢選択 (Multiple Choice) | D40: 正解
A41: 32 | B41: 3 | C41: 特徴の組み合わせ (Matching Features) | D41: 正解
A42: 33 | B42: 3 | C42: 特徴の組み合わせ (Matching Features) | D42: 不正解 | E42: 情報検索・スキャニングの問題 | F42: 似た情報と混同した | G42: 研究者Bの意見を研究者Cのものと混同した | H42: 人名に□をつけて意見を整理しながら読む
...

Sheet テスト1
A1: IELTSリーディング 間違い分析シート（テスト1）
A2: 使い方：黄色のセルに入力 → 正解/不正解・大カテゴリー・詳細理由はプルダウンで選択。集計と円グラフは自動で更新されます。
A4: テスト名 | F4: 正解数 | G4: =COUNTIF(D10:D49,"正解")&" / 40"
A5: 解いた日 | F5: バンド目安（Academic） | G5: =IF(COUNTA(D10:D49)=0,"",LOOKUP(COUNTIF(D10:D49,"正解"),選択肢マスタ!$E$4:$E$15,選択肢マスタ!$F$4:$F$15))
A6: 分析日 | F6: Passage別 正解数 | G6: ="P1: "&COUNTIFS(B10:B49,1,D10:D49,"正解")&"/13 P2: "&COUNTIFS(B10:B49,2,D10:D49,"正解")&"/13 P3: "&COUNTIFS(B10:B49,3,D10:D49,"正解")&"/14"
A7: 解答時間（分） | F7: 不正解数 | G7: =COUNTIF(D10:D49,"不正解")
A9: 問題番号 | B9: Passage | C9: 設問タイプ | D9: 正解/不正解 | E9: 大カテゴリー | F9: 詳細理由 | G9: 具体的に間違いが起きた箇所 | H9: 同じミスを繰り返さないために
A10: 1 | B10: 1
A11: 2 | B11: 1
A12: 3 | B12: 1
A13: 4 | B13: 1
A14: 5 | B14: 1
A15: 6 | B15: 1
A16: 7 | B16: 1
A17: 8 | B17: 1
A18: 9 | B18: 1
A19: 10 | B19: 1
A20: 11 | B20: 1
A21: 12 | B21: 1
... A49: 40 | B49: 3
A51: ■ 何で間違えたのか（不正解の原因の割合）
A52: 大カテゴリー | D52: 件数 | E52: 割合
A53: 語彙・文法理解の問題 | D53: =COUNTIFS($D$10:$D$49,"不正解",$E$10:$E$49,A53) | E53: =IF($D$58=0,"",D53/$D$58)
A54: 情報検索・スキャニングの問題 | D54: =COUNTIFS($D$10:$D$49,"不正解",$E$10:$E$49,A54) | E54: =IF($D$58=0,"",D54/$D$58)
A55: 論理的思考・推論の問題 | D55: =COUNTIFS($D$10:$D$49,"不正解",$E$10:$E$49,A55) | E55: =IF($D$58=0,"",D55/$D$58)
A56: 注意力・正確性の問題 | D56: =COUNTIFS($D$10:$D$49,"不正解",$E$10:$E$49,A56) | E56: =IF($D$58=0,"",D56/$D$58)
A57: （カテゴリー未入力） | D57: =COUNTIFS($D$10:$D$49,"不正解",$E$10:$E$49,"") | E57: =IF($D$58=0,"",D57/$D$58)
A58: 合計（不正解数） | D58: =SUM(D53:D57) | E58: =IF($D$58=0,"",D58/$D$58)
A70: 詳細理由 | D70: 件数 | E70: 割合 | F70: カテゴリー
A71: 単語の意味が分からなかった | D71: =COUNTIFS($D$10:$D$49,"不正解",$F$10:$F$49,A71) | E71: =IF($D$58=0,"",D71/$D$58) | F71: 語彙・文法理解の問題
A72: 多義語の誤認識 | D72: =COUNTIFS($D$10:$D$49,"不正解",$F$10:$F$49,A72) | E72: =IF($D$58=0,"",D72/$D$58) | F72: 語彙・文法理解の問題
A73: 同義語・言い換え表現に気づけなかった | D73: =COUNTIFS($D$10:$D$49,"不正解",$F$10:$F$49,A73) | E73: =IF($D$58=0,"",D73/$D$58) | F73: 語彙・文法理解の問題
A74: 文法構造が複雑で理解できなかった | D74: =COUNTIFS($D$10:$D$49,"不正解",$F$10:$F$49,A74) | E74: =IF($D$58=0,"",D74/$D$58) | F74: 語彙・文法理解の問題
A75: 代名詞・指示語の指す内容を誤解 | D75: =COUNTIFS($D$10:$D$49,"不正解",$F$10:$F$49,A75) | E75: =IF($D$58=0,"",D75/$D$58) | F75: 語彙・文法理解の問題
A76: 接続詞・ディスコースマーカーの見落とし | D76: =COUNTIFS($D$10:$D$49,"不正解",$F$10:$F$49,A76) | E76: =IF($D$58=0,"",D76/$D$58) | F76: 語彙・文法理解の問題
A77: 該当箇所を見つけられなかった | D77: =COUNTIFS($D$10:$D$49,"不正解",$F$10:$F$49,A77) | E77: =IF($D$58=0,"",D77/$D$58) | F77: 情報検索・スキャニングの問題
A78: キーワードのパラフレーズに気づけず探せなかった | D78: =COUNTIFS($D$10:$D$49,"不正解",$F$10:$F$49,A78) | E78: =IF($D$58=0,"",D78/$D$58) | F78: 情報検索・スキャニングの問題
A79: 似た情報と混同した | D79: =COUNTIFS($D$10:$D$49,"不正解",$F$10:$F$49,A79) | E79: =IF($D$58=0,"",D79/$D$58) | F79: 情報検索・スキャニングの問題
A80: 時間が足りず該当部分まで到達できなかった | D80: =COUNTIFS($D$10:$D$49,"不正解",$F$10:$F$49,A80) | E80: =IF($D$58=0,"",D80/$D$58) | F80: 情報検索・スキャニングの問題
A81: 複数パラグラフにまたがる情報を統合できなかった | D81: =COUNTIFS($D$10:$D$49,"不正解",$F$10:$F$49,A81) | E81: =IF($D$58=0,"",D81/$D$58) | F81: 情報検索・スキャニングの問題
...

Sheet テスト2
A1: IELTSリーディング 間違い分析シート（テスト2）
A2: 使い方：黄色のセルに入力 → 正解/不正解・大カテゴリー・詳細理由はプルダウンで選択。集計と円グラフは自動で更新されます。
A4: テスト名 | F4: 正解数 | G4: =COUNTIF(D10:D49,"正解")&" / 40"
A5: 解いた日 | F5: バンド目安（Academic） | G5: =IF(COUNTA(D10:D49)=0,"",LOOKUP(COUNTIF(D10:D49,"正解"),選択肢マスタ!$E$4:$E$15,選択肢マスタ!$F$4:$F$15))
A6: 分析日 | F6: Passage別 正解数 | G6: ="P1: "&COUNTIFS(B10:B49,1,D10:D49,"正解")&"/13 P2: "&COUNTIFS(B10:B49,2,D10:D49,"正解")&"/13 P3: "&COUNTIFS(B10:B49,3,D10:D49,"正解")&"/14"
A7: 解答時間（分） | F7: 不正解数 | G7: =COUNTIF(D10:D49,"不正解")
A9: 問題番号 | B9: Passage | C9: 設問タイプ | D9: 正解/不正解 | E9: 大カテゴリー | F9: 詳細理由 | G9: 具体的に間違いが起きた箇所 | H9: 同じミスを繰り返さないために
A10: 1 | B10: 1
A11: 2 | B11: 1
A12: 3 | B12: 1
A13: 4 | B13: 1
A14: 5 | B14: 1
A15: 6 | B15: 1
A16: 7 | B16: 1
A17: 8 | B17: 1
A18: 9 | B18: 1
A19: 10 | B19: 1
A20: 11 | B20: 1
A21: 12 | B21: 1
... A49: 40 | B49: 3
A51: ■ 何で間違えたのか（不正解の原因の割合）
A52: 大カテゴリー | D52: 件数 | E52: 割合
A53: 語彙・文法理解の問題 | D53: =COUNTIFS($D$10:$D$49,"不正解",$E$10:$E$49,A53) | E53: =IF($D$58=0,"",D53/$D$58)
A54: 情報検索・スキャニングの問題 | D54: =COUNTIFS($D$10:$D$49,"不正解",$E$10:$E$49,A54) | E54: =IF($D$58=0,"",D54/$D$58)
A55: 論理的思考・推論の問題 | D55: =COUNTIFS($D$10:$D$49,"不正解",$E$10:$E$49,A55) | E55: =IF($D$58=0,"",D55/$D$58)
A56: 注意力・正確性の問題 | D56: =COUNTIFS($D$10:$D$49,"不正解",$E$10:$E$49,A56) | E56: =IF($D$58=0,"",D56/$D$58)
A57: （カテゴリー未入力） | D57: =COUNTIFS($D$10:$D$49,"不正解",$E$10:$E$49,"") | E57: =IF($D$58=0,"",D57/$D$58)
A58: 合計（不正解数） | D58: =SUM(D53:D57) | E58: =IF($D$58=0,"",D58/$D$58)
A70: 詳細理由 | D70: 件数 | E70: 割合 | F70: カテゴリー
A71: 単語の意味が分からなかった | D71: =COUNTIFS($D$10:$D$49,"不正解",$F$10:$F$49,A71) | E71: =IF($D$58=0,"",D71/$D$58) | F71: 語彙・文法理解の問題
A72: 多義語の誤認識 | D72: =COUNTIFS($D$10:$D$49,"不正解",$F$10:$F$49,A72) | E72: =IF($D$58=0,"",D72/$D$58) | F72: 語彙・文法理解の問題
A73: 同義語・言い換え表現に気づけなかった | D73: =COUNTIFS($D$10:$D$49,"不正解",$F$10:$F$49,A73) | E73: =IF($D$58=0,"",D73/$D$58) | F73: 語彙・文法理解の問題
A74: 文法構造が複雑で理解できなかった | D74: =COUNTIFS($D$10:$D$49,"不正解",$F$10:$F$49,A74) | E74: =IF($D$58=0,"",D74/$D$58) | F74: 語彙・文法理解の問題
A75: 代名詞・指示語の指す内容を誤解 | D75: =COUNTIFS($D$10:$D$49,"不正解",$F$10:$F$49,A75) | E75: =IF($D$58=0,"",D75/$D$58) | F75: 語彙・文法理解の問題
A76: 接続詞・ディスコースマーカーの見落とし | D76: =COUNTIFS($D$10:$D$49,"不正解",$F$10:$F$49,A76) | E76: =IF($D$58=0,"",D76/$D$58) | F76: 語彙・文法理解の問題
A77: 該当箇所を見つけられなかった | D77: =COUNTIFS($D$10:$D$49,"不正解",$F$10:$F$49,A77) | E77: =IF($D$58=0,"",D77/$D$58) | F77: 情報検索・スキャニングの問題
A78: キーワードのパラフレーズに気づけず探せなかった | D78: =COUNTIFS($D$10:$D$49,"不正解",$F$10:$F$49,A78) | E78: =IF($D$58=0,"",D78/$D$58) | F78: 情報検索・スキャニングの問題
A79: 似た情報と混同した | D79: =COUNTIFS($D$10:$D$49,"不正解",$F$10:$F$49,A79) | E79: =IF($D$58=0,"",D79/$D$58) | F79: 情報検索・スキャニングの問題
A80: 時間が足りず該当部分まで到達できなかった | D80: =COUNTIFS($D$10:$D$49,"不正解",$F$10:$F$49,A80) | E80: =IF($D$58=0,"",D80/$D$58) | F80: 情報検索・スキャニングの問題
A81: 複数パラグラフにまたがる情報を統合できなかった | D81: =COUNTIFS($D$10:$D$49,"不正解",$F$10:$F$49,A81) | E81: =IF($D$58=0,"",D81/$D$58) | F81: 情報検索・スキャニングの問題
...

Sheet テスト3
A1: IELTSリーディング 間違い分析シート（テスト3）
A2: 使い方：黄色のセルに入力 → 正解/不正解・大カテゴリー・詳細理由はプルダウンで選択。集計と円グラフは自動で更新されます。
A4: テスト名 | F4: 正解数 | G4: =COUNTIF(D10:D49,"正解")&" / 40"
A5: 解いた日 | F5: バンド目安（Academic） | G5: =IF(COUNTA(D10:D49)=0,"",LOOKUP(COUNTIF(D10:D49,"正解"),選択肢マスタ!$E$4:$E$15,選択肢マスタ!$F$4:$F$15))
A6: 分析日 | F6: Passage別 正解数 | G6: ="P1: "&COUNTIFS(B10:B49,1,D10:D49,"正解")&"/13 P2: "&COUNTIFS(B10:B49,2,D10:D49,"正解")&"/13 P3: "&COUNTIFS(B10:B49,3,D10:D49,"正解")&"/14"
A7: 解答時間（分） | F7: 不正解数 | G7: =COUNTIF(D10:D49,"不正解")
A9: 問題番号 | B9: Passage | C9: 設問タイプ | D9: 正解/不正解 | E9: 大カテゴリー | F9: 詳細理由 | G9: 具体的に間違いが起きた箇所 | H9: 同じミスを繰り返さないために
A10: 1 | B10: 1
A11: 2 | B11: 1
A12: 3 | B12: 1
A13: 4 | B13: 1
A14: 5 | B14: 1
A15: 6 | B15: 1
A16: 7 | B16: 1
A17: 8 | B17: 1
A18: 9 | B18: 1
A19: 10 | B19: 1
A20: 11 | B20: 1
A21: 12 | B21: 1
... A49: 40 | B49: 3
A51: ■ 何で間違えたのか（不正解の原因の割合）
A52: 大カテゴリー | D52: 件数 | E52: 割合
A53: 語彙・文法理解の問題 | D53: =COUNTIFS($D$10:$D$49,"不正解",$E$10:$E$49,A53) | E53: =IF($D$58=0,"",D53/$D$58)
A54: 情報検索・スキャニングの問題 | D54: =COUNTIFS($D$10:$D$49,"不正解",$E$10:$E$49,A54) | E54: =IF($D$58=0,"",D54/$D$58)
A55: 論理的思考・推論の問題 | D55: =COUNTIFS($D$10:$D$49,"不正解",$E$10:$E$49,A55) | E55: =IF($D$58=0,"",D55/$D$58)
A56: 注意力・正確性の問題 | D56: =COUNTIFS($D$10:$D$49,"不正解",$E$10:$E$49,A56) | E56: =IF($D$58=0,"",D56/$D$58)
A57: （カテゴリー未入力） | D57: =COUNTIFS($D$10:$D$49,"不正解",$E$10:$E$49,"") | E57: =IF($D$58=0,"",D57/$D$58)
A58: 合計（不正解数） | D58: =SUM(D53:D57) | E58: =IF($D$58=0,"",D58/$D$58)
A70: 詳細理由 | D70: 件数 | E70: 割合 | F70: カテゴリー
A71: 単語の意味が分からなかった | D71: =COUNTIFS($D$10:$D$49,"不正解",$F$10:$F$49,A71) | E71: =IF($D$58=0,"",D71/$D$58) | F71: 語彙・文法理解の問題
A72: 多義語の誤認識 | D72: =COUNTIFS($D$10:$D$49,"不正解",$F$10:$F$49,A72) | E72: =IF($D$58=0,"",D72/$D$58) | F72: 語彙・文法理解の問題
A73: 同義語・言い換え表現に気づけなかった | D73: =COUNTIFS($D$10:$D$49,"不正解",$F$10:$F$49,A73) | E73: =IF($D$58=0,"",D73/$D$58) | F73: 語彙・文法理解の問題
A74: 文法構造が複雑で理解できなかった | D74: =COUNTIFS($D$10:$D$49,"不正解",$F$10:$F$49,A74) | E74: =IF($D$58=0,"",D74/$D$58) | F74: 語彙・文法理解の問題
A75: 代名詞・指示語の指す内容を誤解 | D75: =COUNTIFS($D$10:$D$49,"不正解",$F$10:$F$49,A75) | E75: =IF($D$58=0,"",D75/$D$58) | F75: 語彙・文法理解の問題
A76: 接続詞・ディスコースマーカーの見落とし | D76: =COUNTIFS($D$10:$D$49,"不正解",$F$10:$F$49,A76) | E76: =IF($D$58=0,"",D76/$D$58) | F76: 語彙・文法理解の問題
A77: 該当箇所を見つけられなかった | D77: =COUNTIFS($D$10:$D$49,"不正解",$F$10:$F$49,A77) | E77: =IF($D$58=0,"",D77/$D$58) | F77: 情報検索・スキャニングの問題
A78: キーワードのパラフレーズに気づけず探せなかった | D78: =COUNTIFS($D$10:$D$49,"不正解",$F$10:$F$49,A78) | E78: =IF($D$58=0,"",D78/$D$58) | F78: 情報検索・スキャニングの問題
A79: 似た情報と混同した | D79: =COUNTIFS($D$10:$D$49,"不正解",$F$10:$F$49,A79) | E79: =IF($D$58=0,"",D79/$D$58) | F79: 情報検索・スキャニングの問題
A80: 時間が足りず該当部分まで到達できなかった | D80: =COUNTIFS($D$10:$D$49,"不正解",$F$10:$F$49,A80) | E80: =IF($D$58=0,"",D80/$D$58) | F80: 情報検索・スキャニングの問題
A81: 複数パラグラフにまたがる情報を統合できなかった | D81: =COUNTIFS($D$10:$D$49,"不正解",$F$10:$F$49,A81) | E81: =IF($D$58=0,"",D81/$D$58) | F81: 情報検索・スキャニングの問題
...

Sheet テスト4
A1: IELTSリーディング 間違い分析シート（テスト4）
A2: 使い方：黄色のセルに入力 → 正解/不正解・大カテゴリー・詳細理由はプルダウンで選択。集計と円グラフは自動で更新されます。
A4: テスト名 | F4: 正解数 | G4: =COUNTIF(D10:D49,"正解")&" / 40"
A5: 解いた日 | F5: バンド目安（Academic） | G5: =IF(COUNTA(D10:D49)=0,"",LOOKUP(COUNTIF(D10:D49,"正解"),選択肢マスタ!$E$4:$E$15,選択肢マスタ!$F$4:$F$15))
A6: 分析日 | F6: Passage別 正解数 | G6: ="P1: "&COUNTIFS(B10:B49,1,D10:D49,"正解")&"/13 P2: "&COUNTIFS(B10:B49,2,D10:D49,"正解")&"/13 P3: "&COUNTIFS(B10:B49,3,D10:D49,"正解")&"/14"
A7: 解答時間（分） | F7: 不正解数 | G7: =COUNTIF(D10:D49,"不正解")
A9: 問題番号 | B9: Passage | C9: 設問タイプ | D9: 正解/不正解 | E9: 大カテゴリー | F9: 詳細理由 | G9: 具体的に間違いが起きた箇所 | H9: 同じミスを繰り返さないために
A10: 1 | B10: 1
A11: 2 | B11: 1
A12: 3 | B12: 1
A13: 4 | B13: 1
A14: 5 | B14: 1
A15: 6 | B15: 1
A16: 7 | B16: 1
A17: 8 | B17: 1
A18: 9 | B18: 1
A19: 10 | B19: 1
A20: 11 | B20: 1
A21: 12 | B21: 1
... A49: 40 | B49: 3
A51: ■ 何で間違えたのか（不正解の原因の割合）
A52: 大カテゴリー | D52: 件数 | E52: 割合
A53: 語彙・文法理解の問題 | D53: =COUNTIFS($D$10:$D$49,"不正解",$E$10:$E$49,A53) | E53: =IF($D$58=0,"",D53/$D$58)
A54: 情報検索・スキャニングの問題 | D54: =COUNTIFS($D$10:$D$49,"不正解",$E$10:$E$49,A54) | E54: =IF($D$58=0,"",D54/$D$58)
A55: 論理的思考・推論の問題 | D55: =COUNTIFS($D$10:$D$49,"不正解",$E$10:$E$49,A55) | E55: =IF($D$58=0,"",D55/$D$58)
A56: 注意力・正確性の問題 | D56: =COUNTIFS($D$10:$D$49,"不正解",$E$10:$E$49,A56) | E56: =IF($D$58=0,"",D56/$D$58)
A57: （カテゴリー未入力） | D57: =COUNTIFS($D$10:$D$49,"不正解",$E$10:$E$49,"") | E57: =IF($D$58=0,"",D57/$D$58)
A58: 合計（不正解数） | D58: =SUM(D53:D57) | E58: =IF($D$58=0,"",D58/$D$58)
A70: 詳細理由 | D70: 件数 | E70: 割合 | F70: カテゴリー
A71: 単語の意味が分からなかった | D71: =COUNTIFS($D$10:$D$49,"不正解",$F$10:$F$49,A71) | E71: =IF($D$58=0,"",D71/$D$58) | F71: 語彙・文法理解の問題
A72: 多義語の誤認識 | D72: =COUNTIFS($D$10:$D$49,"不正解",$F$10:$F$49,A72) | E72: =IF($D$58=0,"",D72/$D$58) | F72: 語彙・文法理解の問題
A73: 同義語・言い換え表現に気づけなかった | D73: =COUNTIFS($D$10:$D$49,"不正解",$F$10:$F$49,A73) | E73: =IF($D$58=0,"",D73/$D$58) | F73: 語彙・文法理解の問題
A74: 文法構造が複雑で理解できなかった | D74: =COUNTIFS($D$10:$D$49,"不正解",$F$10:$F$49,A74) | E74: =IF($D$58=0,"",D74/$D$58) | F74: 語彙・文法理解の問題
A75: 代名詞・指示語の指す内容を誤解 | D75: =COUNTIFS($D$10:$D$49,"不正解",$F$10:$F$49,A75) | E75: =IF($D$58=0,"",D75/$D$58) | F75: 語彙・文法理解の問題
A76: 接続詞・ディスコースマーカーの見落とし | D76: =COUNTIFS($D$10:$D$49,"不正解",$F$10:$F$49,A76) | E76: =IF($D$58=0,"",D76/$D$58) | F76: 語彙・文法理解の問題
A77: 該当箇所を見つけられなかった | D77: =COUNTIFS($D$10:$D$49,"不正解",$F$10:$F$49,A77) | E77: =IF($D$58=0,"",D77/$D$58) | F77: 情報検索・スキャニングの問題
A78: キーワードのパラフレーズに気づけず探せなかった | D78: =COUNTIFS($D$10:$D$49,"不正解",$F$10:$F$49,A78) | E78: =IF($D$58=0,"",D78/$D$58) | F78: 情報検索・スキャニングの問題
A79: 似た情報と混同した | D79: =COUNTIFS($D$10:$D$49,"不正解",$F$10:$F$49,A79) | E79: =IF($D$58=0,"",D79/$D$58) | F79: 情報検索・スキャニングの問題
A80: 時間が足りず該当部分まで到達できなかった | D80: =COUNTIFS($D$10:$D$49,"不正解",$F$10:$F$49,A80) | E80: =IF($D$58=0,"",D80/$D$58) | F80: 情報検索・スキャニングの問題
A81: 複数パラグラフにまたがる情報を統合できなかった | D81: =COUNTIFS($D$10:$D$49,"不正解",$F$10:$F$49,A81) | E81: =IF($D$58=0,"",D81/$D$58) | F81: 情報検索・スキャニングの問題
...

Sheet テスト5
A1: IELTSリーディング 間違い分析シート（テスト5）
A2: 使い方：黄色のセルに入力 → 正解/不正解・大カテゴリー・詳細理由はプルダウンで選択。集計と円グラフは自動で更新されます。
A4: テスト名 | F4: 正解数 | G4: =COUNTIF(D10:D49,"正解")&" / 40"
A5: 解いた日 | F5: バンド目安（Academic） | G5: =IF(COUNTA(D10:D49)=0,"",LOOKUP(COUNTIF(D10:D49,"正解"),選択肢マスタ!$E$4:$E$15,選択肢マスタ!$F$4:$F$15))
A6: 分析日 | F6: Passage別 正解数 | G6: ="P1: "&COUNTIFS(B10:B49,1,D10:D49,"正解")&"/13 P2: "&COUNTIFS(B10:B49,2,D10:D49,"正解")&"/13 P3: "&COUNTIFS(B10:B49,3,D10:D49,"正解")&"/14"
A7: 解答時間（分） | F7: 不正解数 | G7: =COUNTIF(D10:D49,"不正解")
A9: 問題番号 | B9: Passage | C9: 設問タイプ | D9: 正解/不正解 | E9: 大カテゴリー | F9: 詳細理由 | G9: 具体的に間違いが起きた箇所 | H9: 同じミスを繰り返さないために
A10: 1 | B10: 1
A11: 2 | B11: 1
A12: 3 | B12: 1
A13: 4 | B13: 1
A14: 5 | B14: 1
A15: 6 | B15: 1
A16: 7 | B16: 1
A17: 8 | B17: 1
A18: 9 | B18: 1
A19: 10 | B19: 1
A20: 11 | B20: 1
A21: 12 | B21: 1
... A49: 40 | B49: 3
A51: ■ 何で間違えたのか（不正解の原因の割合）
A52: 大カテゴリー | D52: 件数 | E52: 割合
A53: 語彙・文法理解の問題 | D53: =COUNTIFS($D$10:$D$49,"不正解",$E$10:$E$49,A53) | E53: =IF($D$58=0,"",D53/$D$58)
A54: 情報検索・スキャニングの問題 | D54: =COUNTIFS($D$10:$D$49,"不正解",$E$10:$E$49,A54) | E54: =IF($D$58=0,"",D54/$D$58)
A55: 論理的思考・推論の問題 | D55: =COUNTIFS($D$10:$D$49,"不正解",$E$10:$E$49,A55) | E55: =IF($D$58=0,"",D55/$D$58)
A56: 注意力・正確性の問題 | D56: =COUNTIFS($D$10:$D$49,"不正解",$E$10:$E$49,A56) | E56: =IF($D$58=0,"",D56/$D$58)
A57: （カテゴリー未入力） | D57: =COUNTIFS($D$10:$D$49,"不正解",$E$10:$E$49,"") | E57: =IF($D$58=0,"",D57/$D$58)
A58: 合計（不正解数） | D58: =SUM(D53:D57) | E58: =IF($D$58=0,"",D58/$D$58)
A70: 詳細理由 | D70: 件数 | E70: 割合 | F70: カテゴリー
A71: 単語の意味が分からなかった | D71: =COUNTIFS($D$10:$D$49,"不正解",$F$10:$F$49,A71) | E71: =IF($D$58=0,"",D71/$D$58) | F71: 語彙・文法理解の問題
A72: 多義語の誤認識 | D72: =COUNTIFS($D$10:$D$49,"不正解",$F$10:$F$49,A72) | E72: =IF($D$58=0,"",D72/$D$58) | F72: 語彙・文法理解の問題
A73: 同義語・言い換え表現に気づけなかった | D73: =COUNTIFS($D$10:$D$49,"不正解",$F$10:$F$49,A73) | E73: =IF($D$58=0,"",D73/$D$58) | F73: 語彙・文法理解の問題
A74: 文法構造が複雑で理解できなかった | D74: =COUNTIFS($D$10:$D$49,"不正解",$F$10:$F$49,A74) | E74: =IF($D$58=0,"",D74/$D$58) | F74: 語彙・文法理解の問題
A75: 代名詞・指示語の指す内容を誤解 | D75: =COUNTIFS($D$10:$D$49,"不正解",$F$10:$F$49,A75) | E75: =IF($D$58=0,"",D75/$D$58) | F75: 語彙・文法理解の問題
A76: 接続詞・ディスコースマーカーの見落とし | D76: =COUNTIFS($D$10:$D$49,"不正解",$F$10:$F$49,A76) | E76: =IF($D$58=0,"",D76/$D$58) | F76: 語彙・文法理解の問題
A77: 該当箇所を見つけられなかった | D77: =COUNTIFS($D$10:$D$49,"不正解",$F$10:$F$49,A77) | E77: =IF($D$58=0,"",D77/$D$58) | F77: 情報検索・スキャニングの問題
A78: キーワードのパラフレーズに気づけず探せなかった | D78: =COUNTIFS($D$10:$D$49,"不正解",$F$10:$F$49,A78) | E78: =IF($D$58=0,"",D78/$D$58) | F78: 情報検索・スキャニングの問題
A79: 似た情報と混同した | D79: =COUNTIFS($D$10:$D$49,"不正解",$F$10:$F$49,A79) | E79: =IF($D$58=0,"",D79/$D$58) | F79: 情報検索・スキャニングの問題
A80: 時間が足りず該当部分まで到達できなかった | D80: =COUNTIFS($D$10:$D$49,"不正解",$F$10:$F$49,A80) | E80: =IF($D$58=0,"",D80/$D$58) | F80: 情報検索・スキャニングの問題
A81: 複数パラグラフにまたがる情報を統合できなかった | D81: =COUNTIFS($D$10:$D$49,"不正解",$F$10:$F$49,A81) | E81: =IF($D$58=0,"",D81/$D$58) | F81: 情報検索・スキャニングの問題
...

Sheet 選択肢マスタ
A1: 選択肢マスタ（プルダウンの元データ。項目を変える時はここを編集）
A3: 大カテゴリー | B3: 詳細理由（全て） | C3: 設問タイプ | D3: 正解/不正解 | E3: 正解数(下限) | F3: バンド目安(Academic) | H3: 詳細理由 | I3: 所属カテゴリー
A4: 語彙・文法理解の問題 | B4: 単語の意味が分からなかった | C4: TRUE / FALSE / NOT GIVEN | D4: 正解 | E4: 0 | F4: 〜3.5 | H4: 単語の意味が分からなかった | I4: 語彙・文法理解の問題
A5: 情報検索・スキャニングの問題 | B5: 多義語の誤認識 | C5: YES / NO / NOT GIVEN | D5: 不正解 | E5: 10 | F5: 4.0 | H5: 多義語の誤認識 | I5: 語彙・文法理解の問題
A6: 論理的思考・推論の問題 | B6: 同義語・言い換え表現に気づけなかった | C6: 見出し選択 (Headings) | E6: 13 | F6: 4.5 | H6: 同義語・言い換え表現に気づけなかった | I6: 語彙・文法理解の問題
A7: 注意力・正確性の問題 | B7: 文法構造が複雑で理解できなかった | C7: 情報の場所 (Matching Information) | E7: 15 | F7: 5.0 | H7: 文法構造が複雑で理解できなかった | I7: 語彙・文法理解の問題
B8: 代名詞・指示語の指す内容を誤解 | C8: 特徴の組み合わせ (Matching Features) | E8: 19 | F8: 5.5 | H8: 代名詞・指示語の指す内容を誤解 | I8: 語彙・文法理解の問題
B9: 接続詞・ディスコースマーカーの見落とし | C9: 文の後半選択 (Sentence Endings) | E9: 23 | F9: 6.0 | H9: 接続詞・ディスコースマーカーの見落とし | I9: 語彙・文法理解の問題
B10: 該当箇所を見つけられなかった | C10: 多肢選択 (Multiple Choice) | E10: 27 | F10: 6.5 | H10: 該当箇所を見つけられなかった | I10: 情報検索・スキャニングの問題
B11: キーワードのパラフレーズに気づけず探せなかった | C11: 文完成 (Sentence Completion) | E11: 30 | F11: 7.0 | H11: キーワードのパラフレーズに気づけず探せなかった | I11: 情報検索・スキャニングの問題
B12: 似た情報と混同した | C12: 要約完成 (Summary Completion) | E12: 33 | F12: 7.5 | H12: 似た情報と混同した | I12: 情報検索・スキャニングの問題
B13: 時間が足りず該当部分まで到達できなかった | C13: 表・ノート・フローチャート完成 | E13: 35 | F13: 8.0 | H13: 時間が足りず該当部分まで到達できなかった | I13: 情報検索・スキャニングの問題
B14: 複数パラグラフにまたがる情報を統合できなかった | C14: 図のラベル (Diagram) | E14: 37 | F14: 8.5 | H14: 複数パラグラフにまたがる情報を統合できなかった | I14: 情報検索・スキャニングの問題
B15: 因果関係の読み取りミス | C15: 短答式 (Short Answer) | E15: 39 | F15: 9.0 | H15: 因果関係の読み取りミス | I15: 論理的思考・推論の問題
B16: 比較表現の理解不足 | H16: 比較表現の理解不足 | I16: 論理的思考・推論の問題
B17: 筆者の主張と例示の区別ができなかった | E17: ※バンド目安はAcademicの一般的な換算表に基づく目安です。回によって多少前後します。 | H17: 筆者の主張と例示の区別ができなかった | I17: 論理的思考・推論の問題
B18: NOT GIVEN判定の誤り | H18: NOT GIVEN判定の誤り | I18: 論理的思考・推論の問題
B19: 否定表現の見落とし | H19: 否定表現の見落とし | I19: 論理的思考・推論の問題
B20: 限定表現の見落とし | H20: 限定表現の見落とし | I20: 論理的思考・推論の問題
B21: 設問の指示を読み間違えた | H21: 設問の指示を読み間違えた | I21: 注意力・正確性の問題
B22: 答えを書き写す際のスペルミス | H22: 答えを書き写す際のスペルミス | I22: 注意力・正確性の問題
B23: 単数形・複数形の間違い | H23: 単数形・複数形の間違い | I23: 注意力・正確性の問題
B24: 大文字・小文字の間違い | H24: 大文字・小文字の間違い | I24: 注意力・正確性の問題
B25: ハイフン・スペースの有無の間違い | H25: ハイフン・スペースの有無の間違い | I25: 注意力・正確性の問題
B26: 解答欄のずれ | H26: 解答欄のずれ | I26: 注意力・正確性の問題
B27: 時間切れで未解答 | H27: 時間切れで未解答 | I27: 注意力・正確性の問題
